Workbook
Name \1: #REF!
Name \q: #REF!
Name \w: #REF!
Name _______us96: #REF!
Name _____us96: #REF!
Name ____BAS1: #REF!
Name ____us96: #REF!
Name ___BAS1: #REF!
Name ___res1: #REF!
Name ___res3: #REF!
Name ___res4: #REF!
Name ___us96: #REF!
Name __BAS1: #REF!
Name __DAT1: #REF!
Name __DAT10: #REF!
Name __DAT11: #REF!
Name __DAT12: #REF!
Name __DAT13: #REF!
Name __DAT14: #REF!
Name __DAT15: #REF!
Name __DAT16: #REF!
Name __DAT17: #REF!
Name __DAT18: #REF!
Name __DAT19: #REF!
Name __DAT2: #REF!
Name __DAT20: #REF!
Name __DAT3: #REF!
Name __DAT4: #REF!
Name __DAT5: #REF!
Name __DAT6: #REF!
Name __DAT7: #REF!
Name __DAT8: #REF!
Name __DAT9: #REF!
Name __res1: #REF!
Name __res2: #REF!
Name __res3: #REF!
Name __res4: #REF!
Name __us96: #REF!
Name _A: #REF!
Name _aa: #REF!
Name _ACT1: #REF!
Name _ACT10: #REF!
Name _ACT11: #REF!
Name _ACT12: #REF!
Name _ACT13: #REF!
Name _ACT14: #REF!
Name _ACT15: #REF!
Name _ACT16: #REF!
Name _ACT17: #REF!
Name _ACT18: #REF!
Name _ACT19: #REF!
Name _ACT2: #REF!
Name _ACT20: #REF!
Name _ACT21: #REF!
Name _ACT22: #REF!
Name _ACT23: #REF!
Name _ACT3: #REF!
Name _ACT4: #REF!
Name _ACT5: #REF!
Name _ACT6: #REF!

Sheet Hoja1
E1: =+SUBTOTAL(9,E3:E89) -> 4.75e+09
A2: NOMBRE SUBGRUPO | B2: CATEGORIA2 | C2: NOMBRE CATEGORIA | D2: INCLUIR | E2: PRESUPUESTO (ORIGINAL) | F2: OBS
A3: Obras Civiles | B3: 11-0102-000G | C3: MAO CD - Civil / Hormigón (G) | D3: NO | E3: 2.4934757e+08
A4: Estructura | B4: 11-0208-000G | C4: MAO CD - Estructura / Montajes (G) | D4: SI | E4: 9107425.3
A5: Mecanica | B5: 11-0308-000G | C5: MAO CD - Mecánica / Montajes (G) | D5: SI | E5: 6.482323e+08
A6: Cañería | B6: 11-0408-000G | C6: MAO CD - Cañería / Montajes (G) | D6: SI | E6: 37872374
A7: Electricidad & Instrumentacion | B7: 11-0508-000G | C7: MAO CD - Electricidad / Montajes (G) | D7: SI | E7: 4909779.4
A8: Andamios | B8: 11-1101-000G | C8: MAO CD - Andamios / Andamios (G) | D8: SI | E8: 40034534
A9: Operador | B9: 11-1201-010G | C9: MAO CD - Equipos / Equipos / Operador (G) | D9: SI | E9: 1.0954463e+08
A10: Rigger | B10: 11-1201-020G | C10: MAO CD - Equipos / Equipos / Rigger (G) | D10: SI | E10: 69826848
A11: Staff Superior | B11: 12-5101-000G | C11: MAO CI - Staff Superior / Staff Superior (G) | D11: SI | E11: 2.6331137e+08
A12: Oficina Técnica | B12: 12-5201-000G | C12: MAO CI - Oficina Técnica / Oficina Técnica (G) | D12: SI | E12: 80469295
A13: Supervisión | B13: 12-5301-000G | C13: MAO CI - Supervisión / Supervisión (G) | D13: SI | E13: 97274459
A14: Administración | B14: 12-5401-000G | C14: MAO CI - Administración / Administración (G) | D14: SI | E14: 55188181
... A89: Utilidades | B89: 72-A060-100G | C89: GAS CI - Of. Central / Utilidades / Todos (G) | D89: SI | E89: 0

Sheet Indice
D2: INDICE | H2: CC: EIMI00398 ARAUCO
C4: INFORME DE COSTOS N° 01
G9: Cliente | H9: : | I9: ARAUCO
G10: Administrador de Proyecto | H10: : | I10: CRISTIAN SEPULVEDA GARAY
G11: Centros de Costos | H11: : | I11: EIMI00398
G12: Periodo | H12: : | I12: 46053
C16: Matriz de Producción
C17: Matriz de Costos
C18: Matriz de Resultado
C19: Matriz de Proyecciones

Sheet Formato General
B1: INFORME DE RESULTADOS
B2: =MID(Indice!H2,1,100) -> CC: EIMI00398 ARAUCO | L2: ="Periodo : " & TEXT(Indice!I12,"Mmmm yyyy") -> Periodo : enero 2026
A4: FORMATO GENERAL | B4: Num | C4: Partida | E4: Presupuesto Original | F4: Aumentos o Dism. de Obras y Reajuste | G4: Presupuesto Corregido | I4: Gastos Reales del Mes | J4: Gastos Reales Acumulados | K4: Avance Según Obra Ejecutada | L4: Proyección de gasto por efectuar | N4: Resultado de la Obra
B5: A. | C5: Costos Directos
B6: A1 | C6: 01 - Obras Civiles | E6: =IF(ISBLANK(A6),"", SUMIF(CATEGORIAS[[#All],[FORMATO GENERAL]], A6, CATEGORIAS[[#All],[PRESUPUESTO (ORIGINAL)]])) | F6: =IF(ISBLANK(A6),"",G6-E6) | G6: =IF(ISBLANK(A6),"",SUMIF(CATEGORIAS[[#All],[FORMATO GENERAL]], A6, CATEGORIAS[[#All],[PRESUPUESTO FINAL PROYECTADO]])) | I6: =IF(ISBLANK(A6),"",J6-SUMIF(CATEGORIAS[[#All],[FORMATO GENERAL]], A6, CATEGORIAS[[#All],[COSTO REAL ANTERIOR]])) | J6: =IF(ISBLANK(A6),"",SUMIF(CATEGORIAS[[#All],[FORMATO GENERAL]], A6, CATEGORIAS[[#All],[COSTO REAL]])) | K6: =IF(ISBLANK(A6),"",SUMIF(CATEGORIAS[[#All],[FORMATO GENERAL]], A6, CATEGORIAS[[#All],[TOTAL PRODUCCION ACTUAL]])) | L6: =IF(ISBLANK(A6),"",SUMIF(CATEGORIAS[[#All],[FORMATO GENERAL]], A6, CATEGORIAS[[#All],[PROYECCION TOTAL DE COSTO]])) | N6: =IF(ISBLANK(A6),"",TRUNC(G6-J6-L6,2))
A7: 0A01 | C7: Mano de Obra | E7: =IF(ISBLANK(A7),"", SUMIF(CATEGORIAS[[#All],[FORMATO GENERAL]], A7, CATEGORIAS[[#All],[PRESUPUESTO (ORIGINAL)]])) -> 2.4934757e+08 | F7: =IF(ISBLANK(A7),"",G7-E7) -> -50544234 | G7: =IF(ISBLANK(A7),"",SUMIF(CATEGORIAS[[#All],[FORMATO GENERAL]], A7, CATEGORIAS[[#All],[PRESUPUESTO FINAL PROYECTADO]])) -> 1.9880333e+08 | I7: =IF(ISBLANK(A7),"",J7-SUMIF(CATEGORIAS[[#All],[FORMATO GENERAL]], A7, CATEGORIAS[[#All],[COSTO REAL ANTERIOR]])) -> 0 | J7: =IF(ISBLANK(A7),"",SUMIF(CATEGORIAS[[#All],[FORMATO GENERAL]], A7, CATEGORIAS[[#All],[COSTO REAL]])) -> 226422941 | K7: =IF(ISBLANK(A7),"",SUMIF(CATEGORIAS[[#All],[FORMATO GENERAL]], A7, CATEGORIAS[[#All],[TOTAL PRODUCCION ACTUAL]])) -> 1.9880333e+08 | L7: =IF(ISBLANK(A7),"",SUMIF(CATEGORIAS[[#All],[FORMATO GENERAL]], A7, CATEGORIAS[[#All],[PROYECCION TOTAL DE COSTO]])) -> 0 | N7: =IF(ISBLANK(A7),"",TRUNC(G7-J7-L7,2)) -> -27619608
A8: 0A02 | C8: Obras Civiles Reembolsable | E8: =IF(ISBLANK(A8),"", SUMIF(CATEGORIAS[[#All],[FORMATO GENERAL]], A8, CATEGORIAS[[#All],[PRESUPUESTO (ORIGINAL)]])) -> 5.0495371e+08 | F8: =IF(ISBLANK(A8),"",G8-E8) -> -52500881 | G8: =IF(ISBLANK(A8),"",SUMIF(CATEGORIAS[[#All],[FORMATO GENERAL]], A8, CATEGORIAS[[#All],[PRESUPUESTO FINAL PROYECTADO]])) -> 4.5245283e+08 | I8: =IF(ISBLANK(A8),"",J8-SUMIF(CATEGORIAS[[#All],[FORMATO GENERAL]], A8, CATEGORIAS[[#All],[COSTO REAL ANTERIOR]])) -> 7053441 | J8: =IF(ISBLANK(A8),"",SUMIF(CATEGORIAS[[#All],[FORMATO GENERAL]], A8, CATEGORIAS[[#All],[COSTO REAL]])) -> 548455838 | K8: =IF(ISBLANK(A8),"",SUMIF(CATEGORIAS[[#All],[FORMATO GENERAL]], A8, CATEGORIAS[[#All],[TOTAL PRODUCCION ACTUAL]])) -> 4.5245283e+08 | L8: =IF(ISBLANK(A8),"",SUMIF(CATEGORIAS[[#All],[FORMATO GENERAL]], A8, CATEGORIAS[[#All],[PROYECCION TOTAL DE COSTO]])) -> 0 | N8: =IF(ISBLANK(A8),"",TRUNC(G8-J8-L8,2)) -> -96003007
B9: A2 | C9: 02 - Estructura | E9: =IF(ISBLANK(A9),"", SUMIF(CATEGORIAS[[#All],[FORMATO GENERAL]], A9, CATEGORIAS[[#All],[PRESUPUESTO (ORIGINAL)]])) | F9: =IF(ISBLANK(A9),"",G9-E9) | G9: =IF(ISBLANK(A9),"",SUMIF(CATEGORIAS[[#All],[FORMATO GENERAL]], A9, CATEGORIAS[[#All],[PRESUPUESTO FINAL PROYECTADO]])) | I9: =IF(ISBLANK(A9),"",J9-SUMIF(CATEGORIAS[[#All],[FORMATO GENERAL]], A9, CATEGORIAS[[#All],[COSTO REAL ANTERIOR]])) | J9: =IF(ISBLANK(A9),"",SUMIF(CATEGORIAS[[#All],[FORMATO GENERAL]], A9, CATEGORIAS[[#All],[COSTO REAL]])) | K9: =IF(ISBLANK(A9),"",SUMIF(CATEGORIAS[[#All],[FORMATO GENERAL]], A9, CATEGORIAS[[#All],[TOTAL PRODUCCION ACTUAL]])) | L9: =IF(ISBLANK(A9),"",SUMIF(CATEGORIAS[[#All],[FORMATO GENERAL]], A9, CATEGORIAS[[#All],[PROYECCION TOTAL DE COSTO]])) | N9: =IF(ISBLANK(A9),"",TRUNC(G9-J9-L9,2))
A10: 0B01 | C10: Mano de Obra | E10: =IF(ISBLANK(A10),"", SUMIF(CATEGORIAS[[#All],[FORMATO GENERAL]], A10, CATEGORIAS[[#All],[PRESUPUESTO (ORIGINAL)]])) -> 9107425.3 | F10: =IF(ISBLANK(A10),"",G10-E10) -> -2901494.2 | G10: =IF(ISBLANK(A10),"",SUMIF(CATEGORIAS[[#All],[FORMATO GENERAL]], A10, CATEGORIAS[[#All],[PRESUPUESTO FINAL PROYECTADO]])) -> 6205931.1 | I10: =IF(ISBLANK(A10),"",J10-SUMIF(CATEGORIAS[[#All],[FORMATO GENERAL]], A10, CATEGORIAS[[#All],[COSTO REAL ANTERIOR]])) -> 0 | J10: =IF(ISBLANK(A10),"",SUMIF(CATEGORIAS[[#All],[FORMATO GENERAL]], A10, CATEGORIAS[[#All],[COSTO REAL]])) -> 0 | K10: =IF(ISBLANK(A10),"",SUMIF(CATEGORIAS[[#All],[FORMATO GENERAL]], A10, CATEGORIAS[[#All],[TOTAL PRODUCCION ACTUAL]])) -> 6205931.1 | L10: =IF(ISBLANK(A10),"",SUMIF(CATEGORIAS[[#All],[FORMATO GENERAL]], A10, CATEGORIAS[[#All],[PROYECCION TOTAL DE COSTO]])) -> 0 | N10: =IF(ISBLANK(A10),"",TRUNC(G10-J10-L10,2)) -> 6205931.1
A11: 0B02 | C11: Estructura Reembolsable | E11: =IF(ISBLANK(A11),"", SUMIF(CATEGORIAS[[#All],[FORMATO GENERAL]], A11, CATEGORIAS[[#All],[PRESUPUESTO (ORIGINAL)]])) -> 0 | F11: =IF(ISBLANK(A11),"",G11-E11) -> 0 | G11: =IF(ISBLANK(A11),"",SUMIF(CATEGORIAS[[#All],[FORMATO GENERAL]], A11, CATEGORIAS[[#All],[PRESUPUESTO FINAL PROYECTADO]])) -> 0 | I11: =IF(ISBLANK(A11),"",J11-SUMIF(CATEGORIAS[[#All],[FORMATO GENERAL]], A11, CATEGORIAS[[#All],[COSTO REAL ANTERIOR]])) -> 0 | J11: =IF(ISBLANK(A11),"",SUMIF(CATEGORIAS[[#All],[FORMATO GENERAL]], A11, CATEGORIAS[[#All],[COSTO REAL]])) -> 0 | K11: =IF(ISBLANK(A11),"",SUMIF(CATEGORIAS[[#All],[FORMATO GENERAL]], A11, CATEGORIAS[[#All],[TOTAL PRODUCCION ACTUAL]])) -> 0 | L11: =IF(ISBLANK(A11),"",SUMIF(CATEGORIAS[[#All],[FORMATO GENERAL]], A11, CATEGORIAS[[#All],[PROYECCION TOTAL DE COSTO]])) -> 0 | N11: =IF(ISBLANK(A11),"",TRUNC(G11-J11-L11,2)) -> 0
B12: A3 | C12: 03 - Mecanica (MO Arquitectura Puentes) | E12: =IF(ISBLANK(A12),"", SUMIF(CATEGORIAS[[#All],[FORMATO GENERAL]], A12, CATEGORIAS[[#All],[PRESUPUESTO (ORIGINAL)]])) | F12: =IF(ISBLANK(A12),"",G12-E12) | G12: =IF(ISBLANK(A12),"",SUMIF(CATEGORIAS[[#All],[FORMATO GENERAL]], A12, CATEGORIAS[[#All],[PRESUPUESTO FINAL PROYECTADO]])) | I12: =IF(ISBLANK(A12),"",J12-SUMIF(CATEGORIAS[[#All],[FORMATO GENERAL]], A12, CATEGORIAS[[#All],[COSTO REAL ANTERIOR]])) | J12: =IF(ISBLANK(A12),"",SUMIF(CATEGORIAS[[#All],[FORMATO GENERAL]], A12, CATEGORIAS[[#All],[COSTO REAL]])) | K12: =IF(ISBLANK(A12),"",SUMIF(CATEGORIAS[[#All],[FORMATO GENERAL]], A12, CATEGORIAS[[#All],[TOTAL PRODUCCION ACTUAL]])) | L12: =IF(ISBLANK(A12),"",SUMIF(CATEGORIAS[[#All],[FORMATO GENERAL]], A12, CATEGORIAS[[#All],[PROYECCION TOTAL DE COSTO]])) | N12: =IF(ISBLANK(A12),"",TRUNC(G12-J12-L12,2))
A13: 0C01 | C13: Mano de Obra | E13: =IF(ISBLANK(A13),"", SUMIF(CATEGORIAS[[#All],[FORMATO GENERAL]], A13, CATEGORIAS[[#All],[PRESUPUESTO (ORIGINAL)]])) -> 6.482323e+08 | F13: =IF(ISBLANK(A13),"",G13-E13) -> 1.9356882e+08 | G13: =IF(ISBLANK(A13),"",SUMIF(CATEGORIAS[[#All],[FORMATO GENERAL]], A13, CATEGORIAS[[#All],[PRESUPUESTO FINAL PROYECTADO]])) -> 8.4180112e+08 | I13: =IF(ISBLANK(A13),"",J13-SUMIF(CATEGORIAS[[#All],[FORMATO GENERAL]], A13, CATEGORIAS[[#All],[COSTO REAL ANTERIOR]])) -> 0 | J13: =IF(ISBLANK(A13),"",SUMIF(CATEGORIAS[[#All],[FORMATO GENERAL]], A13, CATEGORIAS[[#All],[COSTO REAL]])) -> 586461235 | K13: =IF(ISBLANK(A13),"",SUMIF(CATEGORIAS[[#All],[FORMATO GENERAL]], A13, CATEGORIAS[[#All],[TOTAL PRODUCCION ACTUAL]])) -> 8.4180112e+08 | L13: =IF(ISBLANK(A13),"",SUMIF(CATEGORIAS[[#All],[FORMATO GENERAL]], A13, CATEGORIAS[[#All],[PROYECCION TOTAL DE COSTO]])) -> 0 | N13: =IF(ISBLANK(A13),"",TRUNC(G13-J13-L13,2)) -> 2.5533988e+08
A14: 0C02 | C14: Mecanica Reembolsable | E14: =IF(ISBLANK(A14),"", SUMIF(CATEGORIAS[[#All],[FORMATO GENERAL]], A14, CATEGORIAS[[#All],[PRESUPUESTO (ORIGINAL)]])) -> 1.4433078e+08 | F14: =IF(ISBLANK(A14),"",G14-E14) -> 80364044 | G14: =IF(ISBLANK(A14),"",SUMIF(CATEGORIAS[[#All],[FORMATO GENERAL]], A14, CATEGORIAS[[#All],[PRESUPUESTO FINAL PROYECTADO]])) -> 2.2469483e+08 | I14: =IF(ISBLANK(A14),"",J14-SUMIF(CATEGORIAS[[#All],[FORMATO GENERAL]], A14, CATEGORIAS[[#All],[COSTO REAL ANTERIOR]])) -> 18039318 | J14: =IF(ISBLANK(A14),"",SUMIF(CATEGORIAS[[#All],[FORMATO GENERAL]], A14, CATEGORIAS[[#All],[COSTO REAL]])) -> 339509978 | K14: =IF(ISBLANK(A14),"",SUMIF(CATEGORIAS[[#All],[FORMATO GENERAL]], A14, CATEGORIAS[[#All],[TOTAL PRODUCCION ACTUAL]])) -> 2.2469483e+08 | L14: =IF(ISBLANK(A14),"",SUMIF(CATEGORIAS[[#All],[FORMATO GENERAL]], A14, CATEGORIAS[[#All],[PROYECCION TOTAL DE COSTO]])) -> 0 | N14: =IF(ISBLANK(A14),"",TRUNC(G14-J14-L14,2)) -> -1.1481515e+08
B15: A4 | C15: 04 - Cañeria | E15: =IF(ISBLANK(A15),"", SUMIF(CATEGORIAS[[#All],[FORMATO GENERAL]], A15, CATEGORIAS[[#All],[PRESUPUESTO (ORIGINAL)]])) | F15: =IF(ISBLANK(A15),"",G15-E15) | G15: =IF(ISBLANK(A15),"",SUMIF(CATEGORIAS[[#All],[FORMATO GENERAL]], A15, CATEGORIAS[[#All],[PRESUPUESTO FINAL PROYECTADO]])) | I15: =IF(ISBLANK(A15),"",J15-SUMIF(CATEGORIAS[[#All],[FORMATO GENERAL]], A15, CATEGORIAS[[#All],[COSTO REAL ANTERIOR]])) | J15: =IF(ISBLANK(A15),"",SUMIF(CATEGORIAS[[#All],[FORMATO GENERAL]], A15, CATEGORIAS[[#All],[COSTO REAL]])) | K15: =IF(ISBLANK(A15),"",SUMIF(CATEGORIAS[[#All],[FORMATO GENERAL]], A15, CATEGORIAS[[#All],[TOTAL PRODUCCION ACTUAL]])) | L15: =IF(ISBLANK(A15),"",SUMIF(CATEGORIAS[[#All],[FORMATO GENERAL]], A15, CATEGORIAS[[#All],[PROYECCION TOTAL DE COSTO]])) | N15: =IF(ISBLANK(A15),"",TRUNC(G15-J15-L15,2))
A16: 0D01 | C16: Mano de Obra | E16: =IF(ISBLANK(A16),"", SUMIF(CATEGORIAS[[#All],[FORMATO GENERAL]], A16, CATEGORIAS[[#All],[PRESUPUESTO (ORIGINAL)]])) -> 37872374 | F16: =IF(ISBLANK(A16),"",G16-E16) -> -19046384 | G16: =IF(ISBLANK(A16),"",SUMIF(CATEGORIAS[[#All],[FORMATO GENERAL]], A16, CATEGORIAS[[#All],[PRESUPUESTO FINAL PROYECTADO]])) -> 18825990 | I16: =IF(ISBLANK(A16),"",J16-SUMIF(CATEGORIAS[[#All],[FORMATO GENERAL]], A16, CATEGORIAS[[#All],[COSTO REAL ANTERIOR]])) -> 0 | J16: =IF(ISBLANK(A16),"",SUMIF(CATEGORIAS[[#All],[FORMATO GENERAL]], A16, CATEGORIAS[[#All],[COSTO REAL]])) -> 0 | K16: =IF(ISBLANK(A16),"",SUMIF(CATEGORIAS[[#All],[FORMATO GENERAL]], A16, CATEGORIAS[[#All],[TOTAL PRODUCCION ACTUAL]])) -> 18825990 | L16: =IF(ISBLANK(A16),"",SUMIF(CATEGORIAS[[#All],[FORMATO GENERAL]], A16, CATEGORIAS[[#All],[PROYECCION TOTAL DE COSTO]])) -> 0 | N16: =IF(ISBLANK(A16),"",TRUNC(G16-J16-L16,2)) -> 18825990
A17: 0D02 | C17: Cañeria Reembolsable | E17: =IF(ISBLANK(A17),"", SUMIF(CATEGORIAS[[#All],[FORMATO GENERAL]], A17, CATEGORIAS[[#All],[PRESUPUESTO (ORIGINAL)]])) -> 3653812.6 | F17: =IF(ISBLANK(A17),"",G17-E17) -> -2584050.3 | G17: =IF(ISBLANK(A17),"",SUMIF(CATEGORIAS[[#All],[FORMATO GENERAL]], A17, CATEGORIAS[[#All],[PRESUPUESTO FINAL PROYECTADO]])) -> 1069762.3 | I17: =IF(ISBLANK(A17),"",J17-SUMIF(CATEGORIAS[[#All],[FORMATO GENERAL]], A17, CATEGORIAS[[#All],[COSTO REAL ANTERIOR]])) -> 0 | J17: =IF(ISBLANK(A17),"",SUMIF(CATEGORIAS[[#All],[FORMATO GENERAL]], A17, CATEGORIAS[[#All],[COSTO REAL]])) -> 0 | K17: =IF(ISBLANK(A17),"",SUMIF(CATEGORIAS[[#All],[FORMATO GENERAL]], A17, CATEGORIAS[[#All],[TOTAL PRODUCCION ACTUAL]])) -> 1069762.3 | L17: =IF(ISBLANK(A17),"",SUMIF(CATEGORIAS[[#All],[FORMATO GENERAL]], A17, CATEGORIAS[[#All],[PROYECCION TOTAL DE COSTO]])) -> 0 | N17: =IF(ISBLANK(A17),"",TRUNC(G17-J17-L17,2)) -> 1069762.3
B18: A5 | C18: 05- Electricidad & Instrumentacion | E18: =IF(ISBLANK(A18),"", SUMIF(CATEGORIAS[[#All],[FORMATO GENERAL]], A18, CATEGORIAS[[#All],[PRESUPUESTO (ORIGINAL)]])) | F18: =IF(ISBLANK(A18),"",G18-E18) | G18: =IF(ISBLANK(A18),"",SUMIF(CATEGORIAS[[#All],[FORMATO GENERAL]], A18, CATEGORIAS[[#All],[PRESUPUESTO FINAL PROYECTADO]])) | I18: =IF(ISBLANK(A18),"",J18-SUMIF(CATEGORIAS[[#All],[FORMATO GENERAL]], A18, CATEGORIAS[[#All],[COSTO REAL ANTERIOR]])) | J18: =IF(ISBLANK(A18),"",SUMIF(CATEGORIAS[[#All],[FORMATO GENERAL]], A18, CATEGORIAS[[#All],[COSTO REAL]])) | K18: =IF(ISBLANK(A18),"",SUMIF(CATEGORIAS[[#All],[FORMATO GENERAL]], A18, CATEGORIAS[[#All],[TOTAL PRODUCCION ACTUAL]])) | L18: =IF(ISBLANK(A18),"",SUMIF(CATEGORIAS[[#All],[FORMATO GENERAL]], A18, CATEGORIAS[[#All],[PROYECCION TOTAL DE COSTO]])) | N18: =IF(ISBLANK(A18),"",TRUNC(G18-J18-L18,2))
A19: 0F01 | C19: Mano de Obra | E19: =IF(ISBLANK(A19),"", SUMIF(CATEGORIAS[[#All],[FORMATO GENERAL]], A19, CATEGORIAS[[#All],[PRESUPUESTO (ORIGINAL)]])) -> 4909779.4 | F19: =IF(ISBLANK(A19),"",G19-E19) -> 1.1470541e+08 | G19: =IF(ISBLANK(A19),"",SUMIF(CATEGORIAS[[#All],[FORMATO GENERAL]], A19, CATEGORIAS[[#All],[PRESUPUESTO FINAL PROYECTADO]])) -> 1.1961519e+08 | I19: =IF(ISBLANK(A19),"",J19-SUMIF(CATEGORIAS[[#All],[FORMATO GENERAL]], A19, CATEGORIAS[[#All],[COSTO REAL ANTERIOR]])) -> 0 | J19: =IF(ISBLANK(A19),"",SUMIF(CATEGORIAS[[#All],[FORMATO GENERAL]], A19, CATEGORIAS[[#All],[COSTO REAL]])) -> 41920101 | K19: =IF(ISBLANK(A19),"",SUMIF(CATEGORIAS[[#All],[FORMATO GENERAL]], A19, CATEGORIAS[[#All],[TOTAL PRODUCCION ACTUAL]])) -> 1.1961519e+08 | L19: =IF(ISBLANK(A19),"",SUMIF(CATEGORIAS[[#All],[FORMATO GENERAL]], A19, CATEGORIAS[[#All],[PROYECCION TOTAL DE COSTO]])) -> 0 | N19: =IF(ISBLANK(A19),"",TRUNC(G19-J19-L19,2)) -> 77695091
A20: 0F02 | C20: Electricidad Reembolsable | E20: =IF(ISBLANK(A20),"", SUMIF(CATEGORIAS[[#All],[FORMATO GENERAL]], A20, CATEGORIAS[[#All],[PRESUPUESTO (ORIGINAL)]])) -> 1198500 | F20: =IF(ISBLANK(A20),"",G20-E20) -> -232733.36 | G20: =IF(ISBLANK(A20),"",SUMIF(CATEGORIAS[[#All],[FORMATO GENERAL]], A20, CATEGORIAS[[#All],[PRESUPUESTO FINAL PROYECTADO]])) -> 965766.64 | I20: =IF(ISBLANK(A20),"",J20-SUMIF(CATEGORIAS[[#All],[FORMATO GENERAL]], A20, CATEGORIAS[[#All],[COSTO REAL ANTERIOR]])) -> -370962 | J20: =IF(ISBLANK(A20),"",SUMIF(CATEGORIAS[[#All],[FORMATO GENERAL]], A20, CATEGORIAS[[#All],[COSTO REAL]])) -> 3189423 | K20: =IF(ISBLANK(A20),"",SUMIF(CATEGORIAS[[#All],[FORMATO GENERAL]], A20, CATEGORIAS[[#All],[TOTAL PRODUCCION ACTUAL]])) -> 965766.64 | L20: =IF(ISBLANK(A20),"",SUMIF(CATEGORIAS[[#All],[FORMATO GENERAL]], A20, CATEGORIAS[[#All],[PROYECCION TOTAL DE COSTO]])) -> 0 | N20: =IF(ISBLANK(A20),"",TRUNC(G20-J20-L20,2)) -> -2223656.4
B21: A6 | C21: 06 - Andamios | E21: =IF(ISBLANK(A21),"", SUMIF(CATEGORIAS[[#All],[FORMATO GENERAL]], A21, CATEGORIAS[[#All],[PRESUPUESTO (ORIGINAL)]])) | F21: =IF(ISBLANK(A21),"",G21-E21) | G21: =IF(ISBLANK(A21),"",SUMIF(CATEGORIAS[[#All],[FORMATO GENERAL]], A21, CATEGORIAS[[#All],[PRESUPUESTO FINAL PROYECTADO]])) | I21: =IF(ISBLANK(A21),"",J21-SUMIF(CATEGORIAS[[#All],[FORMATO GENERAL]], A21, CATEGORIAS[[#All],[COSTO REAL ANTERIOR]])) | J21: =IF(ISBLANK(A21),"",SUMIF(CATEGORIAS[[#All],[FORMATO GENERAL]], A21, CATEGORIAS[[#All],[COSTO REAL]])) | K21: =IF(ISBLANK(A21),"",SUMIF(CATEGORIAS[[#All],[FORMATO GENERAL]], A21, CATEGORIAS[[#All],[TOTAL PRODUCCION ACTUAL]])) | L21: =IF(ISBLANK(A21),"",SUMIF(CATEGORIAS[[#All],[FORMATO GENERAL]], A21, CATEGORIAS[[#All],[PROYECCION TOTAL DE COSTO]])) | N21: =IF(ISBLANK(A21),"",TRUNC(G21-J21-L21,2))
A22: 0N01 | C22: Mano de Obra | E22: =IF(ISBLANK(A22),"", SUMIF(CATEGORIAS[[#All],[FORMATO GENERAL]], A22, CATEGORIAS[[#All],[PRESUPUESTO (ORIGINAL)]])) -> 40034534 | F22: =IF(ISBLANK(A22),"",G22-E22) -> 14598476 | G22: =IF(ISBLANK(A22),"",SUMIF(CATEGORIAS[[#All],[FORMATO GENERAL]], A22, CATEGORIAS[[#All],[PRESUPUESTO FINAL PROYECTADO]])) -> 54633010 | I22: =IF(ISBLANK(A22),"",J22-SUMIF(CATEGORIAS[[#All],[FORMATO GENERAL]], A22, CATEGORIAS[[#All],[COSTO REAL ANTERIOR]])) -> 0 | J22: =IF(ISBLANK(A22),"",SUMIF(CATEGORIAS[[#All],[FORMATO GENERAL]], A22, CATEGORIAS[[#All],[COSTO REAL]])) -> 166683412 | K22: =IF(ISBLANK(A22),"",SUMIF(CATEGORIAS[[#All],[FORMATO GENERAL]], A22, CATEGORIAS[[#All],[TOTAL PRODUCCION ACTUAL]])) -> 54633010 | L22: =IF(ISBLANK(A22),"",SUMIF(CATEGORIAS[[#All],[FORMATO GENERAL]], A22, CATEGORIAS[[#All],[PROYECCION TOTAL DE COSTO]])) -> 0 | N22: =IF(ISBLANK(A22),"",TRUNC(G22-J22-L22,2)) -> -1.120504e+08
B23: A7 | C23: 07 - Aislación | E23: =IF(ISBLANK(A23),"", SUMIF(CATEGORIAS[[#All],[FORMATO GENERAL]], A23, CATEGORIAS[[#All],[PRESUPUESTO (ORIGINAL)]])) | F23: =IF(ISBLANK(A23),"",G23-E23) | G23: =IF(ISBLANK(A23),"",SUMIF(CATEGORIAS[[#All],[FORMATO GENERAL]], A23, CATEGORIAS[[#All],[PRESUPUESTO FINAL PROYECTADO]])) | I23: =IF(ISBLANK(A23),"",J23-SUMIF(CATEGORIAS[[#All],[FORMATO GENERAL]], A23, CATEGORIAS[[#All],[COSTO REAL ANTERIOR]])) | J23: =IF(ISBLANK(A23),"",SUMIF(CATEGORIAS[[#All],[FORMATO GENERAL]], A23, CATEGORIAS[[#All],[COSTO REAL]])) | K23: =IF(ISBLANK(A23),"",SUMIF(CATEGORIAS[[#All],[FORMATO GENERAL]], A23, CATEGORIAS[[#All],[TOTAL PRODUCCION ACTUAL]])) | L23: =IF(ISBLANK(A23),"",SUMIF(CATEGORIAS[[#All],[FORMATO GENERAL]], A23, CATEGORIAS[[#All],[PROYECCION TOTAL DE COSTO]])) | N23: =IF(ISBLANK(A23),"",TRUNC(G23-J23-L23,2))
A24: 0H01 | C24: Mano de Obra | E24: =IF(ISBLANK(A24),"", SUMIF(CATEGORIAS[[#All],[FORMATO GENERAL]], A24, CATEGORIAS[[#All],[PRESUPUESTO (ORIGINAL)]])) -> 0 | F24: =IF(ISBLANK(A24),"",G24-E24) -> 0 | G24: =IF(ISBLANK(A24),"",SUMIF(CATEGORIAS[[#All],[FORMATO GENERAL]], A24, CATEGORIAS[[#All],[PRESUPUESTO FINAL PROYECTADO]])) -> 0 | I24: =IF(ISBLANK(A24),"",J24-SUMIF(CATEGORIAS[[#All],[FORMATO GENERAL]], A24, CATEGORIAS[[#All],[COSTO REAL ANTERIOR]])) -> 0 | J24: =IF(ISBLANK(A24),"",SUMIF(CATEGORIAS[[#All],[FORMATO GENERAL]], A24, CATEGORIAS[[#All],[COSTO REAL]])) -> 0 | K24: =IF(ISBLANK(A24),"",SUMIF(CATEGORIAS[[#All],[FORMATO GENERAL]], A24, CATEGORIAS[[#All],[TOTAL PRODUCCION ACTUAL]])) -> 0 | L24: =IF(ISBLANK(A24),"",SUMIF(CATEGORIAS[[#All],[FORMATO GENERAL]], A24, CATEGORIAS[[#All],[PROYECCION TOTAL DE COSTO]])) -> 0 | N24: =IF(ISBLANK(A24),"",TRUNC(G24-J24-L24,2)) -> 0
A25: 0H02 | C25: Aislación Reembolsable | E25: =IF(ISBLANK(A25),"", SUMIF(CATEGORIAS[[#All],[FORMATO GENERAL]], A25, CATEGORIAS[[#All],[PRESUPUESTO (ORIGINAL)]])) -> 0 | F25: =IF(ISBLANK(A25),"",G25-E25) -> 0 | G25: =IF(ISBLANK(A25),"",SUMIF(CATEGORIAS[[#All],[FORMATO GENERAL]], A25, CATEGORIAS[[#All],[PRESUPUESTO FINAL PROYECTADO]])) -> 0 | I25: =IF(ISBLANK(A25),"",J25-SUMIF(CATEGORIAS[[#All],[FORMATO GENERAL]], A25, CATEGORIAS[[#All],[COSTO REAL ANTERIOR]])) -> 0 | J25: =IF(ISBLANK(A25),"",SUMIF(CATEGORIAS[[#All],[FORMATO GENERAL]], A25, CATEGORIAS[[#All],[COSTO REAL]])) -> 0 | K25: =IF(ISBLANK(A25),"",SUMIF(CATEGORIAS[[#All],[FORMATO GENERAL]], A25, CATEGORIAS[[#All],[TOTAL PRODUCCION ACTUAL]])) -> 0 | L25: =IF(ISBLANK(A25),"",SUMIF(CATEGORIAS[[#All],[FORMATO GENERAL]], A25, CATEGORIAS[[#All],[PROYECCION TOTAL DE COSTO]])) -> 0 | N25: =IF(ISBLANK(A25),"",TRUNC(G25-J25-L25,2)) -> 0
B26: A8 | C26: 08 - Caldera | E26: =IF(ISBLANK(A26),"", SUMIF(CATEGORIAS[[#All],[FORMATO GENERAL]], A26, CATEGORIAS[[#All],[PRESUPUESTO (ORIGINAL)]])) | F26: =IF(ISBLANK(A26),"",G26-E26) | G26: =IF(ISBLANK(A26),"",SUMIF(CATEGORIAS[[#All],[FORMATO GENERAL]], A26, CATEGORIAS[[#All],[PRESUPUESTO FINAL PROYECTADO]])) | I26: =IF(ISBLANK(A26),"",J26-SUMIF(CATEGORIAS[[#All],[FORMATO GENERAL]], A26, CATEGORIAS[[#All],[COSTO REAL ANTERIOR]])) | J26: =IF(ISBLANK(A26),"",SUMIF(CATEGORIAS[[#All],[FORMATO GENERAL]], A26, CATEGORIAS[[#All],[COSTO REAL]])) | K26: =IF(ISBLANK(A26),"",SUMIF(CATEGORIAS[[#All],[FORMATO GENERAL]], A26, CATEGORIAS[[#All],[TOTAL PRODUCCION ACTUAL]])) | L26: =IF(ISBLANK(A26),"",SUMIF(CATEGORIAS[[#All],[FORMATO GENERAL]], A26, CATEGORIAS[[#All],[PROYECCION TOTAL DE COSTO]])) | N26: =IF(ISBLANK(A26),"",TRUNC(G26-J26-L26,2))
A27: 0I01 | C27: Mano de Obra | E27: =IF(ISBLANK(A27),"", SUMIF(CATEGORIAS[[#All],[FORMATO GENERAL]], A27, CATEGORIAS[[#All],[PRESUPUESTO (ORIGINAL)]])) -> 0 | F27: =IF(ISBLANK(A27),"",G27-E27) -> 0 | G27: =IF(ISBLANK(A27),"",SUMIF(CATEGORIAS[[#All],[FORMATO GENERAL]], A27, CATEGORIAS[[#All],[PRESUPUESTO FINAL PROYECTADO]])) -> 0 | I27: =IF(ISBLANK(A27),"",J27-SUMIF(CATEGORIAS[[#All],[FORMATO GENERAL]], A27, CATEGORIAS[[#All],[COSTO REAL ANTERIOR]])) -> 0 | J27: =IF(ISBLANK(A27),"",SUMIF(CATEGORIAS[[#All],[FORMATO GENERAL]], A27, CATEGORIAS[[#All],[COSTO REAL]])) -> 0 | K27: =IF(ISBLANK(A27),"",SUMIF(CATEGORIAS[[#All],[FORMATO GENERAL]], A27, CATEGORIAS[[#All],[TOTAL PRODUCCION ACTUAL]])) -> 0 | L27: =IF(ISBLANK(A27),"",SUMIF(CATEGORIAS[[#All],[FORMATO GENERAL]], A27, CATEGORIAS[[#All],[PROYECCION TOTAL DE COSTO]])) -> 0 | N27: =IF(ISBLANK(A27),"",TRUNC(G27-J27-L27,2)) -> 0
A28: 0I02 | C28: Caldera Reembolsable | E28: =IF(ISBLANK(A28),"", SUMIF(CATEGORIAS[[#All],[FORMATO GENERAL]], A28, CATEGORIAS[[#All],[PRESUPUESTO (ORIGINAL)]])) -> 0 | F28: =IF(ISBLANK(A28),"",G28-E28) -> 0 | G28: =IF(ISBLANK(A28),"",SUMIF(CATEGORIAS[[#All],[FORMATO GENERAL]], A28, CATEGORIAS[[#All],[PRESUPUESTO FINAL PROYECTADO]])) -> 0 | I28: =IF(ISBLANK(A28),"",J28-SUMIF(CATEGORIAS[[#All],[FORMATO GENERAL]], A28, CATEGORIAS[[#All],[COSTO REAL ANTERIOR]])) -> 0 | J28: =IF(ISBLANK(A28),"",SUMIF(CATEGORIAS[[#All],[FORMATO GENERAL]], A28, CATEGORIAS[[#All],[COSTO REAL]])) -> 0 | K28: =IF(ISBLANK(A28),"",SUMIF(CATEGORIAS[[#All],[FORMATO GENERAL]], A28, CATEGORIAS[[#All],[TOTAL PRODUCCION ACTUAL]])) -> 0 | L28: =IF(ISBLANK(A28),"",SUMIF(CATEGORIAS[[#All],[FORMATO GENERAL]], A28, CATEGORIAS[[#All],[PROYECCION TOTAL DE COSTO]])) -> 0 | N28: =IF(ISBLANK(A28),"",TRUNC(G28-J28-L28,2)) -> 0
B29: A9 | C29: 09 - Ducto | E29: =IF(ISBLANK(A29),"", SUMIF(CATEGORIAS[[#All],[FORMATO GENERAL]], A29, CATEGORIAS[[#All],[PRESUPUESTO (ORIGINAL)]])) | F29: =IF(ISBLANK(A29),"",G29-E29) | G29: =IF(ISBLANK(A29),"",SUMIF(CATEGORIAS[[#All],[FORMATO GENERAL]], A29, CATEGORIAS[[#All],[PRESUPUESTO FINAL PROYECTADO]])) | I29: =IF(ISBLANK(A29),"",J29-SUMIF(CATEGORIAS[[#All],[FORMATO GENERAL]], A29, CATEGORIAS[[#All],[COSTO REAL ANTERIOR]])) | J29: =IF(ISBLANK(A29),"",SUMIF(CATEGORIAS[[#All],[FORMATO GENERAL]], A29, CATEGORIAS[[#All],[COSTO REAL]])) | K29: =IF(ISBLANK(A29),"",SUMIF(CATEGORIAS[[#All],[FORMATO GENERAL]], A29, CATEGORIAS[[#All],[TOTAL PRODUCCION ACTUAL]])) | L29: =IF(ISBLANK(A29),"",SUMIF(CATEGORIAS[[#All],[FORMATO GENERAL]], A29, CATEGORIAS[[#All],[PROYECCION TOTAL DE COSTO]])) | N29: =IF(ISBLANK(A29),"",TRUNC(G29-J29-L29,2))
A30: 0J01 | C30: Mano de Obra | E30: =IF(ISBLANK(A30),"", SUMIF(CATEGORIAS[[#All],[FORMATO GENERAL]], A30, CATEGORIAS[[#All],[PRESUPUESTO (ORIGINAL)]])) -> 0 | F30: =IF(ISBLANK(A30),"",G30-E30) -> 0 | G30: =IF(ISBLANK(A30),"",SUMIF(CATEGORIAS[[#All],[FORMATO GENERAL]], A30, CATEGORIAS[[#All],[PRESUPUESTO FINAL PROYECTADO]])) -> 0 | I30: =IF(ISBLANK(A30),"",J30-SUMIF(CATEGORIAS[[#All],[FORMATO GENERAL]], A30, CATEGORIAS[[#All],[COSTO REAL ANTERIOR]])) -> 0 | J30: =IF(ISBLANK(A30),"",SUMIF(CATEGORIAS[[#All],[FORMATO GENERAL]], A30, CATEGORIAS[[#All],[COSTO REAL]])) -> 0 | K30: =IF(ISBLANK(A30),"",SUMIF(CATEGORIAS[[#All],[FORMATO GENERAL]], A30, CATEGORIAS[[#All],[TOTAL PRODUCCION ACTUAL]])) -> 0 | L30: =IF(ISBLANK(A30),"",SUMIF(CATEGORIAS[[#All],[FORMATO GENERAL]], A30, CATEGORIAS[[#All],[PROYECCION TOTAL DE COSTO]])) -> 0 | N30: =IF(ISBLANK(A30),"",TRUNC(G30-J30-L30,2)) -> 0
A31: 0J02 | C31: Ducto Reembolsable | E31: =IF(ISBLANK(A31),"", SUMIF(CATEGORIAS[[#All],[FORMATO GENERAL]], A31, CATEGORIAS[[#All],[PRESUPUESTO (ORIGINAL)]])) -> 0 | F31: =IF(ISBLANK(A31),"",G31-E31) -> 0 | G31: =IF(ISBLANK(A31),"",SUMIF(CATEGORIAS[[#All],[FORMATO GENERAL]], A31, CATEGORIAS[[#All],[PRESUPUESTO FINAL PROYECTADO]])) -> 0 | I31: =IF(ISBLANK(A31),"",J31-SUMIF(CATEGORIAS[[#All],[FORMATO GENERAL]], A31, CATEGORIAS[[#All],[COSTO REAL ANTERIOR]])) -> 0 | J31: =IF(ISBLANK(A31),"",SUMIF(CATEGORIAS[[#All],[FORMATO GENERAL]], A31, CATEGORIAS[[#All],[COSTO REAL]])) -> 0 | K31: =IF(ISBLANK(A31),"",SUMIF(CATEGORIAS[[#All],[FORMATO GENERAL]], A31, CATEGORIAS[[#All],[TOTAL PRODUCCION ACTUAL]])) -> 0 | L31: =IF(ISBLANK(A31),"",SUMIF(CATEGORIAS[[#All],[FORMATO GENERAL]], A31, CATEGORIAS[[#All],[PROYECCION TOTAL DE COSTO]])) -> 0 | N31: =IF(ISBLANK(A31),"",TRUNC(G31-J31-L31,2)) -> 0
B32: A10 | C32: 10 - Comisionamiento - PEM | E32: =IF(ISBLANK(A32),"", SUMIF(CATEGORIAS[[#All],[FORMATO GENERAL]], A32, CATEGORIAS[[#All],[PRESUPUESTO (ORIGINAL)]])) | F32: =IF(ISBLANK(A32),"",G32-E32) | G32: =IF(ISBLANK(A32),"",SUMIF(CATEGORIAS[[#All],[FORMATO GENERAL]], A32, CATEGORIAS[[#All],[PRESUPUESTO FINAL PROYECTADO]])) | I32: =IF(ISBLANK(A32),"",J32-SUMIF(CATEGORIAS[[#All],[FORMATO GENERAL]], A32, CATEGORIAS[[#All],[COSTO REAL ANTERIOR]])) | J32: =IF(ISBLANK(A32),"",SUMIF(CATEGORIAS[[#All],[FORMATO GENERAL]], A32, CATEGORIAS[[#All],[COSTO REAL]])) | K32: =IF(ISBLANK(A32),"",SUMIF(CATEGORIAS[[#All],[FORMATO GENERAL]], A32, CATEGORIAS[[#All],[TOTAL PRODUCCION ACTUAL]])) | L32: =IF(ISBLANK(A32),"",SUMIF(CATEGORIAS[[#All],[FORMATO GENERAL]], A32, CATEGORIAS[[#All],[PROYECCION TOTAL DE COSTO]])) | N32: =IF(ISBLANK(A32),"",TRUNC(G32-J32-L32,2))
A33: 0G01 | C33: Mano de Obra | E33: =IF(ISBLANK(A33),"", SUMIF(CATEGORIAS[[#All],[FORMATO GENERAL]], A33, CATEGORIAS[[#All],[PRESUPUESTO (ORIGINAL)]])) -> 0 | F33: =IF(ISBLANK(A33),"",G33-E33) -> 0 | G33: =IF(ISBLANK(A33),"",SUMIF(CATEGORIAS[[#All],[FORMATO GENERAL]], A33, CATEGORIAS[[#All],[PRESUPUESTO FINAL PROYECTADO]])) -> 0 | I33: =IF(ISBLANK(A33),"",J33-SUMIF(CATEGORIAS[[#All],[FORMATO GENERAL]], A33, CATEGORIAS[[#All],[COSTO REAL ANTERIOR]])) -> 0 | J33: =IF(ISBLANK(A33),"",SUMIF(CATEGORIAS[[#All],[FORMATO GENERAL]], A33, CATEGORIAS[[#All],[COSTO REAL]])) -> 0 | K33: =IF(ISBLANK(A33),"",SUMIF(CATEGORIAS[[#All],[FORMATO GENERAL]], A33, CATEGORIAS[[#All],[TOTAL PRODUCCION ACTUAL]])) -> 0 | L33: =IF(ISBLANK(A33),"",SUMIF(CATEGORIAS[[#All],[FORMATO GENERAL]], A33, CATEGORIAS[[#All],[PROYECCION TOTAL DE COSTO]])) -> 0 | N33: =IF(ISBLANK(A33),"",TRUNC(G33-J33-L33,2)) -> 0
B34: A11 | C34: 11 - Arquitectura | E34: =IF(ISBLANK(A34),"", SUMIF(CATEGORIAS[[#All],[FORMATO GENERAL]], A34, CATEGORIAS[[#All],[PRESUPUESTO (ORIGINAL)]])) | F34: =IF(ISBLANK(A34),"",G34-E34) | G34: =IF(ISBLANK(A34),"",SUMIF(CATEGORIAS[[#All],[FORMATO GENERAL]], A34, CATEGORIAS[[#All],[PRESUPUESTO FINAL PROYECTADO]])) | I34: =IF(ISBLANK(A34),"",J34-SUMIF(CATEGORIAS[[#All],[FORMATO GENERAL]], A34, CATEGORIAS[[#All],[COSTO REAL ANTERIOR]])) | J34: =IF(ISBLANK(A34),"",SUMIF(CATEGORIAS[[#All],[FORMATO GENERAL]], A34, CATEGORIAS[[#All],[COSTO REAL]])) | K34: =IF(ISBLANK(A34),"",SUMIF(CATEGORIAS[[#All],[FORMATO GENERAL]], A34, CATEGORIAS[[#All],[TOTAL PRODUCCION ACTUAL]])) | L34: =IF(ISBLANK(A34),"",SUMIF(CATEGORIAS[[#All],[FORMATO GENERAL]], A34, CATEGORIAS[[#All],[PROYECCION TOTAL DE COSTO]])) | N34: =IF(ISBLANK(A34),"",TRUNC(G34-J34-L34,2))
A35: 0K01 | C35: Mano de Obra | E35: =IF(ISBLANK(A35),"", SUMIF(CATEGORIAS[[#All],[FORMATO GENERAL]], A35, CATEGORIAS[[#All],[PRESUPUESTO (ORIGINAL)]])) -> 0 | F35: =IF(ISBLANK(A35),"",G35-E35) -> 0 | G35: =IF(ISBLANK(A35),"",SUMIF(CATEGORIAS[[#All],[FORMATO GENERAL]], A35, CATEGORIAS[[#All],[PRESUPUESTO FINAL PROYECTADO]])) -> 0 | I35: =IF(ISBLANK(A35),"",J35-SUMIF(CATEGORIAS[[#All],[FORMATO GENERAL]], A35, CATEGORIAS[[#All],[COSTO REAL ANTERIOR]])) -> 0 | J35: =IF(ISBLANK(A35),"",SUMIF(CATEGORIAS[[#All],[FORMATO GENERAL]], A35, CATEGORIAS[[#All],[COSTO REAL]])) -> 0 | K35: =IF(ISBLANK(A35),"",SUMIF(CATEGORIAS[[#All],[FORMATO GENERAL]], A35, CATEGORIAS[[#All],[TOTAL PRODUCCION ACTUAL]])) -> 0 | L35: =IF(ISBLANK(A35),"",SUMIF(CATEGORIAS[[#All],[FORMATO GENERAL]], A35, CATEGORIAS[[#All],[PROYECCION TOTAL DE COSTO]])) -> 0 | N35: =IF(ISBLANK(A35),"",TRUNC(G35-J35-L35,2)) -> 0
A36: 0K02 | C36: Arquitectura Reembolsable | E36: =IF(ISBLANK(A36),"", SUMIF(CATEGORIAS[[#All],[FORMATO GENERAL]], A36, CATEGORIAS[[#All],[PRESUPUESTO (ORIGINAL)]])) -> 0 | F36: =IF(ISBLANK(A36),"",G36-E36) -> 0 | G36: =IF(ISBLANK(A36),"",SUMIF(CATEGORIAS[[#All],[FORMATO GENERAL]], A36, CATEGORIAS[[#All],[PRESUPUESTO FINAL PROYECTADO]])) -> 0 | I36: =IF(ISBLANK(A36),"",J36-SUMIF(CATEGORIAS[[#All],[FORMATO GENERAL]], A36, CATEGORIAS[[#All],[COSTO REAL ANTERIOR]])) -> 0 | J36: =IF(ISBLANK(A36),"",SUMIF(CATEGORIAS[[#All],[FORMATO GENERAL]], A36, CATEGORIAS[[#All],[COSTO REAL]])) -> 0 | K36: =IF(ISBLANK(A36),"",SUMIF(CATEGORIAS[[#All],[FORMATO GENERAL]], A36, CATEGORIAS[[#All],[TOTAL PRODUCCION ACTUAL]])) -> 0 | L36: =IF(ISBLANK(A36),"",SUMIF(CATEGORIAS[[#All],[FORMATO GENERAL]], A36, CATEGORIAS[[#All],[PROYECCION TOTAL DE COSTO]])) -> 0 | N36: =IF(ISBLANK(A36),"",TRUNC(G36-J36-L36,2)) -> 0
B37: A12 | C37: 12 - Estanque | E37: =IF(ISBLANK(A37),"", SUMIF(CATEGORIAS[[#All],[FORMATO GENERAL]], A37, CATEGORIAS[[#All],[PRESUPUESTO (ORIGINAL)]])) | F37: =IF(ISBLANK(A37),"",G37-E37) | G37: =IF(ISBLANK(A37),"",SUMIF(CATEGORIAS[[#All],[FORMATO GENERAL]], A37, CATEGORIAS[[#All],[PRESUPUESTO FINAL PROYECTADO]])) | I37: =IF(ISBLANK(A37),"",J37-SUMIF(CATEGORIAS[[#All],[FORMATO GENERAL]], A37, CATEGORIAS[[#All],[COSTO REAL ANTERIOR]])) | J37: =IF(ISBLANK(A37),"",SUMIF(CATEGORIAS[[#All],[FORMATO GENERAL]], A37, CATEGORIAS[[#All],[COSTO REAL]])) | K37: =IF(ISBLANK(A37),"",SUMIF(CATEGORIAS[[#All],[FORMATO GENERAL]], A37, CATEGORIAS[[#All],[TOTAL PRODUCCION ACTUAL]])) | L37: =IF(ISBLANK(A37),"",SUMIF(CATEGORIAS[[#All],[FORMATO GENERAL]], A37, CATEGORIAS[[#All],[PROYECCION TOTAL DE COSTO]])) | N37: =IF(ISBLANK(A37),"",TRUNC(G37-J37-L37,2))
A38: 0M01 | C38: Mano de Obra | E38: =IF(ISBLANK(A38),"", SUMIF(CATEGORIAS[[#All],[FORMATO GENERAL]], A38, CATEGORIAS[[#All],[PRESUPUESTO (ORIGINAL)]])) -> 0 | F38: =IF(ISBLANK(A38),"",G38-E38) -> 0 | G38: =IF(ISBLANK(A38),"",SUMIF(CATEGORIAS[[#All],[FORMATO GENERAL]], A38, CATEGORIAS[[#All],[PRESUPUESTO FINAL PROYECTADO]])) -> 0 | I38: =IF(ISBLANK(A38),"",J38-SUMIF(CATEGORIAS[[#All],[FORMATO GENERAL]], A38, CATEGORIAS[[#All],[COSTO REAL ANTERIOR]])) -> 0 | J38: =IF(ISBLANK(A38),"",SUMIF(CATEGORIAS[[#All],[FORMATO GENERAL]], A38, CATEGORIAS[[#All],[COSTO REAL]])) -> 0 | K38: =IF(ISBLANK(A38),"",SUMIF(CATEGORIAS[[#All],[FORMATO GENERAL]], A38, CATEGORIAS[[#All],[TOTAL PRODUCCION ACTUAL]])) -> 0 | L38: =IF(ISBLANK(A38),"",SUMIF(CATEGORIAS[[#All],[FORMATO GENERAL]], A38, CATEGORIAS[[#All],[PROYECCION TOTAL DE COSTO]])) -> 0 | N38: =IF(ISBLANK(A38),"",TRUNC(G38-J38-L38,2)) -> 0
A39: 0M02 | C39: Estanque Reembolsable | E39: =IF(ISBLANK(A39),"", SUMIF(CATEGORIAS[[#All],[FORMATO GENERAL]], A39, CATEGORIAS[[#All],[PRESUPUESTO (ORIGINAL)]])) -> 0 | F39: =IF(ISBLANK(A39),"",G39-E39) -> 0 | G39: =IF(ISBLANK(A39),"",SUMIF(CATEGORIAS[[#All],[FORMATO GENERAL]], A39, CATEGORIAS[[#All],[PRESUPUESTO FINAL PROYECTADO]])) -> 0 | I39: =IF(ISBLANK(A39),"",J39-SUMIF(CATEGORIAS[[#All],[FORMATO GENERAL]], A39, CATEGORIAS[[#All],[COSTO REAL ANTERIOR]])) -> 0 | J39: =IF(ISBLANK(A39),"",SUMIF(CATEGORIAS[[#All],[FORMATO GENERAL]], A39, CATEGORIAS[[#All],[COSTO REAL]])) -> 0 | K39: =IF(ISBLANK(A39),"",SUMIF(CATEGORIAS[[#All],[FORMATO GENERAL]], A39, CATEGORIAS[[#All],[TOTAL PRODUCCION ACTUAL]])) -> 0 | L39: =IF(ISBLANK(A39),"",SUMIF(CATEGORIAS[[#All],[FORMATO GENERAL]], A39, CATEGORIAS[[#All],[PROYECCION TOTAL DE COSTO]])) -> 0 | N39: =IF(ISBLANK(A39),"",TRUNC(G39-J39-L39,2)) -> 0
B40: A13 | C40: Costo Proporcional HH | E40: =IF(ISBLANK(A40),"", SUMIF(CATEGORIAS[[#All],[FORMATO GENERAL]], A40, CATEGORIAS[[#All],[PRESUPUESTO (ORIGINAL)]])) | F40: =IF(ISBLANK(A40),"",G40-E40) | G40: =IF(ISBLANK(A40),"",SUMIF(CATEGORIAS[[#All],[FORMATO GENERAL]], A40, CATEGORIAS[[#All],[PRESUPUESTO FINAL PROYECTADO]])) | I40: =IF(ISBLANK(A40),"",J40-SUMIF(CATEGORIAS[[#All],[FORMATO GENERAL]], A40, CATEGORIAS[[#All],[COSTO REAL ANTERIOR]])) | J40: =IF(ISBLANK(A40),"",SUMIF(CATEGORIAS[[#All],[FORMATO GENERAL]], A40, CATEGORIAS[[#All],[COSTO REAL]])) | K40: =IF(ISBLANK(A40),"",SUMIF(CATEGORIAS[[#All],[FORMATO GENERAL]], A40, CATEGORIAS[[#All],[TOTAL PRODUCCION ACTUAL]])) | L40: =IF(ISBLANK(A40),"",SUMIF(CATEGORIAS[[#All],[FORMATO GENERAL]], A40, CATEGORIAS[[#All],[PROYECCION TOTAL DE COSTO]])) | N40: =IF(ISBLANK(A40),"",TRUNC(G40-J40-L40,2))
A41: 0Y01 | C41: Movilización | E41: =IF(ISBLANK(A41),"", SUMIF(CATEGORIAS[[#All],[FORMATO GENERAL]], A41, CATEGORIAS[[#All],[PRESUPUESTO (ORIGINAL)]])) -> 1.3325478e+08 | F41: =IF(ISBLANK(A41),"",G41-E41) -> 5084246.4 | G41: =IF(ISBLANK(A41),"",SUMIF(CATEGORIAS[[#All],[FORMATO GENERAL]], A41, CATEGORIAS[[#All],[PRESUPUESTO FINAL PROYECTADO]])) -> 1.3833903e+08 | I41: =IF(ISBLANK(A41),"",J41-SUMIF(CATEGORIAS[[#All],[FORMATO GENERAL]], A41, CATEGORIAS[[#All],[COSTO REAL ANTERIOR]])) -> 0 | J41: =IF(ISBLANK(A41),"",SUMIF(CATEGORIAS[[#All],[FORMATO GENERAL]], A41, CATEGORIAS[[#All],[COSTO REAL]])) -> 1.9913927e+08 | K41: =IF(ISBLANK(A41),"",SUMIF(CATEGORIAS[[#All],[FORMATO GENERAL]], A41, CATEGORIAS[[#All],[TOTAL PRODUCCION ACTUAL]])) -> 1.3833903e+08 | L41: =IF(ISBLANK(A41),"",SUMIF(CATEGORIAS[[#All],[FORMATO GENERAL]], A41, CATEGORIAS[[#All],[PROYECCION TOTAL DE COSTO]])) -> 0 | N41: =IF(ISBLANK(A41),"",TRUNC(G41-J41-L41,2)) -> -60800244
...

Sheet Analisis por Categorias
E1: ERROR DE PRODUCCION - ADICIONALES | G1: 4 | H1: 5 | I1: 6 | L1: 7 | M1: 8 | O1: =+L2-O2 -> -0.0018701553 | P1: 11 | Q1: 12 | R1: 13 | S1: 14 | T1: 15 | U1: 16 | V1: 17 | W1: 18 | X1: 19 | Y1: 20 | Z1: 21 | AA1: 22 | AB1: 23 | AC1: 24 | AD1: 25 | AE1: 26
E2: ERROR DE PRODUCCION - ADICIONALES | G2: =SUBTOTAL(9,CATEGORIAS[PRESUPUESTO (ORIGINAL)]) -> 4.75e+09 | H2: =SUBTOTAL(9,CATEGORIAS[POM]) -> 4.3139404e+09 | I2: =SUBTOTAL(9,CATEGORIAS[ADICIONALES]) -> 1.5613215e+09 | J2: =+SUBTOTAL(9,CATEGORIAS[REAJUSTE PAGADO]) -> 1.3870427e+08 | K2: =+SUBTOTAL(9,CATEGORIAS[REAJUSTE PROYECTADO]) -> 0 | L2: =SUBTOTAL(9,CATEGORIAS[PRESUPUESTO FINAL PROYECTADO]) -> 6.0139661e+09 | M2: =SUBTOTAL(9,CATEGORIAS[PRODUCCION PARTIDAS ORIGINALES ACTUAL]) -> 4.4518842e+09 | N2: =SUBTOTAL(9,CATEGORIAS[PRODUCCION ADICIONALES ACTUAL]) -> 1.5620819e+09 | O2: =SUBTOTAL(9,CATEGORIAS[TOTAL PRODUCCION ACTUAL]) -> 6.0139661e+09 | P2: =SUBTOTAL(9,CATEGORIAS[PRODUCCION ANTERIOR]) -> 4.4518724e+09 | Q2: =SUBTOTAL(9,CATEGORIAS[PRODUCCION ADICIONALES ANTERIOR]) -> 1.5413014e+09 | R2: =SUBTOTAL(9,CATEGORIAS[TOTAL PRODUCCION ANTERIOR]) -> 5.9931738e+09 | S2: =SUBTOTAL(9,CATEGORIAS[COSTO ACUMULADO AX]) -> 5.5981128e+09 | T2: =SUM(CATEGORIAS[CAMBIO DE CATEGORIA]) -> 3.7252903e-09 | U2: =SUBTOTAL(9,CATEGORIAS[PROVISIONES]) -> 25727542 | V2: =SUBTOTAL(9,CATEGORIAS[COSTO REAL]) -> 5.6238403e+09 | W2: =SUBTOTAL(9,CATEGORIAS[COSTO ACUMULADO ANTERIOR]) -> 5.4162668e+09 | X2: =SUBTOTAL(9,CATEGORIAS[CAMBIO DE CATEGORIA ANTERIOR]) -> 3.7252903e-09 | Y2: =SUBTOTAL(9,CATEGORIAS[PROVISIONES ANTERIOR]) -> 1.659176e+08 | Z2: =SUBTOTAL(9,CATEGORIAS[COSTO REAL ANTERIOR]) -> 5.5821844e+09 | AA2: =SUBTOTAL(9,CATEGORIAS[PROYECCION DE INGRESO DEL SALDO]) -> 0.0051058717 | AB2: =SUBTOTAL(9,CATEGORIAS[INVENTARIO]) -> 0 | AC2: =SUBTOTAL(9,CATEGORIAS[PEDIDOS DE COMPRA NO RECIBIDOS]) -> 0 | AD2: =SUBTOTAL(9,CATEGORIAS[PROYECCION DE COSTO DEL SALDO]) -> 4384841 | AE2: =SUBTOTAL(9,CATEGORIAS[PROYECCION TOTAL DE COSTO]) -> 4384841
E3: ERROR DE COSTO - CAMBIO CATEGORIA - PROVISION | H3: 3931246334 | L3: 5.9931738e+09 | M3: PRODUCCION | S3: COSTOS | AA3: PROYECCION
E4: ERROR DE PROYECCION - INVENTARIO | H4: =+H2-H3 -> 3.8269406e+08 | J4: 1.3860928e+08 | M4: ACUMULADA | P4: ACUMULADA ANTERIOR | S4: ACUMULADO | W4: ACUMULADO ANTERIOR | AA4: PRODUCCION | AB4: COSTOS
G5: CARGA MANUAL | H5: CARGA MANUAL | I5: CARGA MANUAL | L5: FORMULA | M5: CARGA MANUAL | N5: CARGA MANUAL | O5: FORMULA | P5: CARGA MANUAL | Q5: CARGA MANUAL | R5: FORMULA | S5: DESDE AX | T5: CARGA MANUAL | U5: CARGA MANUAL | V5: FORMULA | W5: CARGA MANUAL | X5: CARGA MANUAL | Y5: CARGA MANUAL | Z5: FORMULA | AA5: FORMULA | AB5: DESDE AX | AC5: DESDE AX | AD5: CARGA MANUAL | AE5: FORMULA
A6: FORMATO GENERAL | B6: SUBGRUPO | C6: NOMBRE SUBGRUPO | D6: CATEGORIA2 | E6: NOMBRE CATEGORIA | F6: INCLUIR | G6: PRESUPUESTO (ORIGINAL) | H6: POM | I6: ADICIONALES | J6: REAJUSTE PAGADO | K6: REAJUSTE PROYECTADO | L6: PRESUPUESTO FINAL PROYECTADO | M6: PRODUCCION PARTIDAS ORIGINALES ACTUAL | N6: PRODUCCION ADICIONALES ACTUAL | O6: TOTAL PRODUCCION ACTUAL | P6: PRODUCCION ANTERIOR | Q6: PRODUCCION ADICIONALES ANTERIOR | R6: TOTAL PRODUCCION ANTERIOR | S6: COSTO ACUMULADO AX | T6: CAMBIO DE CATEGORIA | U6: PROVISIONES | V6: COSTO REAL | W6: COSTO ACUMULADO ANTERIOR | X6: CAMBIO DE CATEGORIA ANTERIOR | Y6: PROVISIONES ANTERIOR | Z6: COSTO REAL ANTERIOR | AA6: PROYECCION DE INGRESO DEL SALDO | AB6: INVENTARIO | AC6: PEDIDOS DE COMPRA NO RECIBIDOS | AD6: PROYECCION DE COSTO DEL SALDO | AE6: PROYECCION TOTAL DE COSTO | AF6: ITEM | AG6: Columna1
D7: 10-0000-000G | E7: MAO / Por Distribuir (G) | F7: NO | G7: 0 | H7: 0 | I7: 0 | J7: 0 | K7: 0 | L7: =CATEGORIAS[[#This Row],[ADICIONALES]]+CATEGORIAS[[#This Row],[POM]]+CATEGORIAS[[#This Row],[REAJUSTE PAGADO]]+CATEGORIAS[[#This Row],[REAJUSTE PROYECTADO]] -> 0 | M7: 0 | N7: 0 | O7: =+CATEGORIAS[[#This Row],[PRODUCCION PARTIDAS ORIGINALES ACTUAL]]+CATEGORIAS[[#This Row],[PRODUCCION ADICIONALES ACTUAL]] -> 0 | P7: 0 | Q7: 0 | R7: =+CATEGORIAS[[#This Row],[PRODUCCION ANTERIOR]]+CATEGORIAS[[#This Row],[PRODUCCION ADICIONALES ANTERIOR]] -> 0 | S7: 0 | U7: 0 | V7: =SUM(CATEGORIAS[[#This Row],[COSTO ACUMULADO AX]:[PROVISIONES]]) -> 0 | W7: 0 | Y7: 0 | Z7: =SUM(CATEGORIAS[[#This Row],[COSTO ACUMULADO ANTERIOR]:[PROVISIONES ANTERIOR]]) -> 0 | AA7: =ABS(+CATEGORIAS[[#This Row],[PRESUPUESTO FINAL PROYECTADO]]-CATEGORIAS[[#This Row],[TOTAL PRODUCCION ACTUAL]]) -> 0 | AD7: 0 | AE7: =SUM(CATEGORIAS[[#This Row],[INVENTARIO]:[PROYECCION DE COSTO DEL SALDO]]) -> 0 | AG7: =+CATEGORIAS[[#This Row],[PRESUPUESTO FINAL PROYECTADO]]-CATEGORIAS[[#This Row],[COSTO REAL]]-CATEGORIAS[[#This Row],[PROYECCION TOTAL DE COSTO]] -> 0
D8: 11-0101-000G | E8: MAO CD - Civil / Movimiento de tierra (G) | F8: NO | G8: 0 | H8: 0 | I8: 0 | J8: 0 | K8: 0 | L8: =CATEGORIAS[[#This Row],[ADICIONALES]]+CATEGORIAS[[#This Row],[POM]]+CATEGORIAS[[#This Row],[REAJUSTE PAGADO]]+CATEGORIAS[[#This Row],[REAJUSTE PROYECTADO]] -> 0 | M8: 0 | N8: 0 | O8: =+CATEGORIAS[[#This Row],[PRODUCCION PARTIDAS ORIGINALES ACTUAL]]+CATEGORIAS[[#This Row],[PRODUCCION ADICIONALES ACTUAL]] -> 0 | P8: 0 | Q8: 0 | R8: =+CATEGORIAS[[#This Row],[PRODUCCION ANTERIOR]]+CATEGORIAS[[#This Row],[PRODUCCION ADICIONALES ANTERIOR]] -> 0 | S8: 0 | U8: 0 | V8: =SUM(CATEGORIAS[[#This Row],[COSTO ACUMULADO AX]:[PROVISIONES]]) -> 0 | W8: 0 | Y8: 0 | Z8: =SUM(CATEGORIAS[[#This Row],[COSTO ACUMULADO ANTERIOR]:[PROVISIONES ANTERIOR]]) -> 0 | AA8: =ABS(+CATEGORIAS[[#This Row],[PRESUPUESTO FINAL PROYECTADO]]-CATEGORIAS[[#This Row],[TOTAL PRODUCCION ACTUAL]]) -> 0 | AD8: 0 | AE8: =SUM(CATEGORIAS[[#This Row],[INVENTARIO]:[PROYECCION DE COSTO DEL SALDO]]) -> 0 | AG8: =+CATEGORIAS[[#This Row],[PRESUPUESTO FINAL PROYECTADO]]-CATEGORIAS[[#This Row],[COSTO REAL]]-CATEGORIAS[[#This Row],[PROYECCION TOTAL DE COSTO]] -> 0
A9: 0A01 | B9: 0A01 | C9: Obras Civiles | D9: 11-0102-000G | E9: MAO CD - Civil / Hormigón (G) | F9: NO | G9: 2.4934757e+08 | H9: 1.4836277e+08 | I9: 45209537 | J9: 5231027.1 | K9: 0 | L9: =CATEGORIAS[[#This Row],[ADICIONALES]]+CATEGORIAS[[#This Row],[POM]]+CATEGORIAS[[#This Row],[REAJUSTE PAGADO]]+CATEGORIAS[[#This Row],[REAJUSTE PROYECTADO]] -> 1.9880333e+08 | M9: 1.5356467e+08 | N9: 45238661 | O9: =+CATEGORIAS[[#This Row],[PRODUCCION PARTIDAS ORIGINALES ACTUAL]]+CATEGORIAS[[#This Row],[PRODUCCION ADICIONALES ACTUAL]] -> 1.9880333e+08 | P9: 1.5356467e+08 | Q9: 45209537 | R9: =+CATEGORIAS[[#This Row],[PRODUCCION ANTERIOR]]+CATEGORIAS[[#This Row],[PRODUCCION ADICIONALES ANTERIOR]] -> 1.9877421e+08 | S9: 242028406 | T9: -15605465 | U9: 0 | V9: =SUM(CATEGORIAS[[#This Row],[COSTO ACUMULADO AX]:[PROVISIONES]]) -> 226422941 | W9: 242028406 | X9: -15605465 | Y9: 0 | Z9: =SUM(CATEGORIAS[[#This Row],[COSTO ACUMULADO ANTERIOR]:[PROVISIONES ANTERIOR]]) -> 226422941 | AA9: =ABS(+CATEGORIAS[[#This Row],[PRESUPUESTO FINAL PROYECTADO]]-CATEGORIAS[[#This Row],[TOTAL PRODUCCION ACTUAL]]) -> 0 | AD9: 0 | AE9: =SUM(CATEGORIAS[[#This Row],[INVENTARIO]:[PROYECCION DE COSTO DEL SALDO]]) -> 0 | AG9: =+CATEGORIAS[[#This Row],[PRESUPUESTO FINAL PROYECTADO]]-CATEGORIAS[[#This Row],[COSTO REAL]]-CATEGORIAS[[#This Row],[PROYECCION TOTAL DE COSTO]] -> -27619608
D10: 11-0103-000G | E10: MAO CD - Civil / Moldaje (G) | F10: NO | G10: 0 | H10: 0 | I10: 0 | J10: 0 | K10: 0 | L10: =CATEGORIAS[[#This Row],[ADICIONALES]]+CATEGORIAS[[#This Row],[POM]]+CATEGORIAS[[#This Row],[REAJUSTE PAGADO]]+CATEGORIAS[[#This Row],[REAJUSTE PROYECTADO]] -> 0 | M10: 0 | N10: 0 | O10: =+CATEGORIAS[[#This Row],[PRODUCCION PARTIDAS ORIGINALES ACTUAL]]+CATEGORIAS[[#This Row],[PRODUCCION ADICIONALES ACTUAL]] -> 0 | P10: 0 | Q10: 0 | R10: =+CATEGORIAS[[#This Row],[PRODUCCION ANTERIOR]]+CATEGORIAS[[#This Row],[PRODUCCION ADICIONALES ANTERIOR]] -> 0 | S10: 0 | U10: 0 | V10: =SUM(CATEGORIAS[[#This Row],[COSTO ACUMULADO AX]:[PROVISIONES]]) -> 0 | W10: 0 | Y10: 0 | Z10: =SUM(CATEGORIAS[[#This Row],[COSTO ACUMULADO ANTERIOR]:[PROVISIONES ANTERIOR]]) -> 0 | AA10: =ABS(+CATEGORIAS[[#This Row],[PRESUPUESTO FINAL PROYECTADO]]-CATEGORIAS[[#This Row],[TOTAL PRODUCCION ACTUAL]]) -> 0 | AD10: 0 | AE10: =SUM(CATEGORIAS[[#This Row],[INVENTARIO]:[PROYECCION DE COSTO DEL SALDO]]) -> 0 | AG10: =+CATEGORIAS[[#This Row],[PRESUPUESTO FINAL PROYECTADO]]-CATEGORIAS[[#This Row],[COSTO REAL]]-CATEGORIAS[[#This Row],[PROYECCION TOTAL DE COSTO]] -> 0
D11: 11-0104-000G | E11: MAO CD - Civil / Enfierradura (G) | F11: NO | G11: 0 | H11: 0 | I11: 0 | J11: 0 | K11: 0 | L11: =CATEGORIAS[[#This Row],[ADICIONALES]]+CATEGORIAS[[#This Row],[POM]]+CATEGORIAS[[#This Row],[REAJUSTE PAGADO]]+CATEGORIAS[[#This Row],[REAJUSTE PROYECTADO]] -> 0 | M11: 0 | N11: 0 | O11: =+CATEGORIAS[[#This Row],[PRODUCCION PARTIDAS ORIGINALES ACTUAL]]+CATEGORIAS[[#This Row],[PRODUCCION ADICIONALES ACTUAL]] -> 0 | P11: 0 | Q11: 0 | R11: =+CATEGORIAS[[#This Row],[PRODUCCION ANTERIOR]]+CATEGORIAS[[#This Row],[PRODUCCION ADICIONALES ANTERIOR]] -> 0 | S11: 0 | U11: 0 | V11: =SUM(CATEGORIAS[[#This Row],[COSTO ACUMULADO AX]:[PROVISIONES]]) -> 0 | W11: 0 | Y11: 0 | Z11: =SUM(CATEGORIAS[[#This Row],[COSTO ACUMULADO ANTERIOR]:[PROVISIONES ANTERIOR]]) -> 0 | AA11: =ABS(+CATEGORIAS[[#This Row],[PRESUPUESTO FINAL PROYECTADO]]-CATEGORIAS[[#This Row],[TOTAL PRODUCCION ACTUAL]]) -> 0 | AD11: 0 | AE11: =SUM(CATEGORIAS[[#This Row],[INVENTARIO]:[PROYECCION DE COSTO DEL SALDO]]) -> 0 | AG11: =+CATEGORIAS[[#This Row],[PRESUPUESTO FINAL PROYECTADO]]-CATEGORIAS[[#This Row],[COSTO REAL]]-CATEGORIAS[[#This Row],[PROYECCION TOTAL DE COSTO]] -> 0
D12: 11-0105-000G | E12: MAO CD - Civil / Arquitectura (G) | F12: NO | G12: 0 | H12: 0 | I12: 0 | J12: 0 | K12: 0 | L12: =CATEGORIAS[[#This Row],[ADICIONALES]]+CATEGORIAS[[#This Row],[POM]]+CATEGORIAS[[#This Row],[REAJUSTE PAGADO]]+CATEGORIAS[[#This Row],[REAJUSTE PROYECTADO]] -> 0 | M12: 0 | N12: 0 | O12: =+CATEGORIAS[[#This Row],[PRODUCCION PARTIDAS ORIGINALES ACTUAL]]+CATEGORIAS[[#This Row],[PRODUCCION ADICIONALES ACTUAL]] -> 0 | P12: 0 | Q12: 0 | R12: =+CATEGORIAS[[#This Row],[PRODUCCION ANTERIOR]]+CATEGORIAS[[#This Row],[PRODUCCION ADICIONALES ANTERIOR]] -> 0 | S12: 0 | U12: 0 | V12: =SUM(CATEGORIAS[[#This Row],[COSTO ACUMULADO AX]:[PROVISIONES]]) -> 0 | W12: 0 | Y12: 0 | Z12: =SUM(CATEGORIAS[[#This Row],[COSTO ACUMULADO ANTERIOR]:[PROVISIONES ANTERIOR]]) -> 0 | AA12: =ABS(+CATEGORIAS[[#This Row],[PRESUPUESTO FINAL PROYECTADO]]-CATEGORIAS[[#This Row],[TOTAL PRODUCCION ACTUAL]]) -> 0 | AD12: 0 | AE12: =SUM(CATEGORIAS[[#This Row],[INVENTARIO]:[PROYECCION DE COSTO DEL SALDO]]) -> 0 | AG12: =+CATEGORIAS[[#This Row],[PRESUPUESTO FINAL PROYECTADO]]-CATEGORIAS[[#This Row],[COSTO REAL]]-CATEGORIAS[[#This Row],[PROYECCION TOTAL DE COSTO]] -> 0
D13: 11-0199-000G | E13: MAO CD - Civil / Otros (G) | F13: SI | G13: 0 | H13: 0 | I13: 0 | J13: 0 | K13: 0 | L13: =CATEGORIAS[[#This Row],[ADICIONALES]]+CATEGORIAS[[#This Row],[POM]]+CATEGORIAS[[#This Row],[REAJUSTE PAGADO]]+CATEGORIAS[[#This Row],[REAJUSTE PROYECTADO]] -> 0 | M13: 0 | N13: 0 | O13: =+CATEGORIAS[[#This Row],[PRODUCCION PARTIDAS ORIGINALES ACTUAL]]+CATEGORIAS[[#This Row],[PRODUCCION ADICIONALES ACTUAL]] -> 0 | P13: 0 | Q13: 0 | R13: =+CATEGORIAS[[#This Row],[PRODUCCION ANTERIOR]]+CATEGORIAS[[#This Row],[PRODUCCION ADICIONALES ANTERIOR]] -> 0 | S13: 0 | U13: 0 | V13: =SUM(CATEGORIAS[[#This Row],[COSTO ACUMULADO AX]:[PROVISIONES]]) -> 0 | W13: 0 | Y13: 0 | Z13: =SUM(CATEGORIAS[[#This Row],[COSTO ACUMULADO ANTERIOR]:[PROVISIONES ANTERIOR]]) -> 0 | AA13: =ABS(+CATEGORIAS[[#This Row],[PRESUPUESTO FINAL PROYECTADO]]-CATEGORIAS[[#This Row],[TOTAL PRODUCCION ACTUAL]]) -> 0 | AD13: 0 | AE13: =SUM(CATEGORIAS[[#This Row],[INVENTARIO]:[PROYECCION DE COSTO DEL SALDO]]) -> 0 | AG13: =+CATEGORIAS[[#This Row],[PRESUPUESTO FINAL PROYECTADO]]-CATEGORIAS[[#This Row],[COSTO REAL]]-CATEGORIAS[[#This Row],[PROYECCION TOTAL DE COSTO]] -> 0
D14: 11-0207-000G | E14: MAO CD - Estructura / Soldadura (G) | F14: NO | G14: 0 | H14: 0 | I14: 0 | J14: 0 | K14: 0 | L14: =CATEGORIAS[[#This Row],[ADICIONALES]]+CATEGORIAS[[#This Row],[POM]]+CATEGORIAS[[#This Row],[REAJUSTE PAGADO]]+CATEGORIAS[[#This Row],[REAJUSTE PROYECTADO]] -> 0 | M14: 0 | N14: 0 | O14: =+CATEGORIAS[[#This Row],[PRODUCCION PARTIDAS ORIGINALES ACTUAL]]+CATEGORIAS[[#This Row],[PRODUCCION ADICIONALES ACTUAL]] -> 0 | P14: 0 | Q14: 0 | R14: =+CATEGORIAS[[#This Row],[PRODUCCION ANTERIOR]]+CATEGORIAS[[#This Row],[PRODUCCION ADICIONALES ANTERIOR]] -> 0 | S14: 0 | U14: 0 | V14: =SUM(CATEGORIAS[[#This Row],[COSTO ACUMULADO AX]:[PROVISIONES]]) -> 0 | W14: 0 | Y14: 0 | Z14: =SUM(CATEGORIAS[[#This Row],[COSTO ACUMULADO ANTERIOR]:[PROVISIONES ANTERIOR]]) -> 0 | AA14: =ABS(+CATEGORIAS[[#This Row],[PRESUPUESTO FINAL PROYECTADO]]-CATEGORIAS[[#This Row],[TOTAL PRODUCCION ACTUAL]]) -> 0 | AD14: 0 | AE14: =SUM(CATEGORIAS[[#This Row],[INVENTARIO]:[PROYECCION DE COSTO DEL SALDO]]) -> 0 | AG14: =+CATEGORIAS[[#This Row],[PRESUPUESTO FINAL PROYECTADO]]-CATEGORIAS[[#This Row],[COSTO REAL]]-CATEGORIAS[[#This Row],[PROYECCION TOTAL DE COSTO]] -> 0
A15: 0B01 | B15: 0A02 | C15: Estructura | D15: 11-0208-000G | E15: MAO CD - Estructura / Montajes (G) | F15: SI | G15: 9107425.3 | H15: 5994572.4 | I15: 0 | J15: 211358.76 | K15: 0 | L15: =CATEGORIAS[[#This Row],[ADICIONALES]]+CATEGORIAS[[#This Row],[POM]]+CATEGORIAS[[#This Row],[REAJUSTE PAGADO]]+CATEGORIAS[[#This Row],[REAJUSTE PROYECTADO]] -> 6205931.1 | M15: 6204754.4 | N15: 1176.7382 | O15: =+CATEGORIAS[[#This Row],[PRODUCCION PARTIDAS ORIGINALES ACTUAL]]+CATEGORIAS[[#This Row],[PRODUCCION ADICIONALES ACTUAL]] -> 6205931.1 | P15: 6204754.4 | Q15: 0 | R15: =+CATEGORIAS[[#This Row],[PRODUCCION ANTERIOR]]+CATEGORIAS[[#This Row],[PRODUCCION ADICIONALES ANTERIOR]] -> 6204754.4 | S15: 0 | U15: 0 | V15: =SUM(CATEGORIAS[[#This Row],[COSTO ACUMULADO AX]:[PROVISIONES]]) -> 0 | W15: 0 | Y15: 0 | Z15: =SUM(CATEGORIAS[[#This Row],[COSTO ACUMULADO ANTERIOR]:[PROVISIONES ANTERIOR]]) -> 0 | AA15: =ABS(+CATEGORIAS[[#This Row],[PRESUPUESTO FINAL PROYECTADO]]-CATEGORIAS[[#This Row],[TOTAL PRODUCCION ACTUAL]]) -> 0 | AD15: 0 | AE15: =SUM(CATEGORIAS[[#This Row],[INVENTARIO]:[PROYECCION DE COSTO DEL SALDO]]) -> 0 | AG15: =+CATEGORIAS[[#This Row],[PRESUPUESTO FINAL PROYECTADO]]-CATEGORIAS[[#This Row],[COSTO REAL]]-CATEGORIAS[[#This Row],[PROYECCION TOTAL DE COSTO]] -> 6205931.1
D16: 11-0231-201G | E16: Remuneraciones / Otros Gastos / Prov. Vacaciones | F16: NO | G16: 0 | H16: 0 | I16: 0 | J16: 0 | K16: 0 | L16: =CATEGORIAS[[#This Row],[ADICIONALES]]+CATEGORIAS[[#This Row],[POM]]+CATEGORIAS[[#This Row],[REAJUSTE PAGADO]]+CATEGORIAS[[#This Row],[REAJUSTE PROYECTADO]] -> 0 | M16: 0 | N16: 0 | O16: =+CATEGORIAS[[#This Row],[PRODUCCION PARTIDAS ORIGINALES ACTUAL]]+CATEGORIAS[[#This Row],[PRODUCCION ADICIONALES ACTUAL]] -> 0 | P16: 0 | Q16: 0 | R16: =+CATEGORIAS[[#This Row],[PRODUCCION ANTERIOR]]+CATEGORIAS[[#This Row],[PRODUCCION ADICIONALES ANTERIOR]] -> 0 | S16: 0 | U16: 0 | V16: =SUM(CATEGORIAS[[#This Row],[COSTO ACUMULADO AX]:[PROVISIONES]]) -> 0 | W16: 0 | Y16: 0 | Z16: =SUM(CATEGORIAS[[#This Row],[COSTO ACUMULADO ANTERIOR]:[PROVISIONES ANTERIOR]]) -> 0 | AA16: =ABS(+CATEGORIAS[[#This Row],[PRESUPUESTO FINAL PROYECTADO]]-CATEGORIAS[[#This Row],[TOTAL PRODUCCION ACTUAL]]) -> 0 | AD16: 0 | AE16: =SUM(CATEGORIAS[[#This Row],[INVENTARIO]:[PROYECCION DE COSTO DEL SALDO]]) -> 0 | AG16: =+CATEGORIAS[[#This Row],[PRESUPUESTO FINAL PROYECTADO]]-CATEGORIAS[[#This Row],[COSTO REAL]]-CATEGORIAS[[#This Row],[PROYECCION TOTAL DE COSTO]] -> 0
D17: 11-0307-000G | E17: MAO CD - Mecánica / Soldadura (G) | F17: NO | G17: 0 | H17: 0 | I17: 0 | J17: 0 | K17: 0 | L17: =CATEGORIAS[[#This Row],[ADICIONALES]]+CATEGORIAS[[#This Row],[POM]]+CATEGORIAS[[#This Row],[REAJUSTE PAGADO]]+CATEGORIAS[[#This Row],[REAJUSTE PROYECTADO]] -> 0 | M17: 0 | N17: 0 | O17: =+CATEGORIAS[[#This Row],[PRODUCCION PARTIDAS ORIGINALES ACTUAL]]+CATEGORIAS[[#This Row],[PRODUCCION ADICIONALES ACTUAL]] -> 0 | P17: 0 | Q17: 0 | R17: =+CATEGORIAS[[#This Row],[PRODUCCION ANTERIOR]]+CATEGORIAS[[#This Row],[PRODUCCION ADICIONALES ANTERIOR]] -> 0 | S17: 0 | U17: 0 | V17: =SUM(CATEGORIAS[[#This Row],[COSTO ACUMULADO AX]:[PROVISIONES]]) -> 0 | W17: 0 | Y17: 0 | Z17: =SUM(CATEGORIAS[[#This Row],[COSTO ACUMULADO ANTERIOR]:[PROVISIONES ANTERIOR]]) -> 0 | AA17: =ABS(+CATEGORIAS[[#This Row],[PRESUPUESTO FINAL PROYECTADO]]-CATEGORIAS[[#This Row],[TOTAL PRODUCCION ACTUAL]]) -> 0 | AD17: 0 | AE17: =SUM(CATEGORIAS[[#This Row],[INVENTARIO]:[PROYECCION DE COSTO DEL SALDO]]) -> 0 | AG17: =+CATEGORIAS[[#This Row],[PRESUPUESTO FINAL PROYECTADO]]-CATEGORIAS[[#This Row],[COSTO REAL]]-CATEGORIAS[[#This Row],[PROYECCION TOTAL DE COSTO]] -> 0
A18: 0C01 | B18: 0A03 | C18: Mecanica | D18: 11-0308-000G | E18: MAO CD - Mecánica / Montajes (G) | F18: SI | G18: 6.482323e+08 | H18: 6.6364583e+08 | I18: 1.5475623e+08 | J18: 23399060 | K18: 0 | L18: =CATEGORIAS[[#This Row],[ADICIONALES]]+CATEGORIAS[[#This Row],[POM]]+CATEGORIAS[[#This Row],[REAJUSTE PAGADO]]+CATEGORIAS[[#This Row],[REAJUSTE PROYECTADO]] -> 8.4180112e+08 | M18: 6.8691462e+08 | N18: 1.548865e+08 | O18: =+CATEGORIAS[[#This Row],[PRODUCCION PARTIDAS ORIGINALES ACTUAL]]+CATEGORIAS[[#This Row],[PRODUCCION ADICIONALES ACTUAL]] -> 8.4180112e+08 | P18: 6.8691462e+08 | Q18: 1.5687251e+08 | R18: =+CATEGORIAS[[#This Row],[PRODUCCION ANTERIOR]]+CATEGORIAS[[#This Row],[PRODUCCION ADICIONALES ANTERIOR]] -> 8.4378713e+08 | S18: 590365191 | T18: -3903956 | U18: 0 | V18: =SUM(CATEGORIAS[[#This Row],[COSTO ACUMULADO AX]:[PROVISIONES]]) -> 586461235 | W18: 590365191 | X18: -3903956 | Y18: 0 | Z18: =SUM(CATEGORIAS[[#This Row],[COSTO ACUMULADO ANTERIOR]:[PROVISIONES ANTERIOR]]) -> 586461235 | AA18: =ABS(+CATEGORIAS[[#This Row],[PRESUPUESTO FINAL PROYECTADO]]-CATEGORIAS[[#This Row],[TOTAL PRODUCCION ACTUAL]]) -> 4.7683716e-07 | AD18: 0 | AE18: =SUM(CATEGORIAS[[#This Row],[INVENTARIO]:[PROYECCION DE COSTO DEL SALDO]]) -> 0 | AG18: =+CATEGORIAS[[#This Row],[PRESUPUESTO FINAL PROYECTADO]]-CATEGORIAS[[#This Row],[COSTO REAL]]-CATEGORIAS[[#This Row],[PROYECCION TOTAL DE COSTO]] -> 2.5533988e+08
D19: 11-0321-619A | E19: Remuneraciones / Remuneraciones / Otros Dsctos. al Personal | F19: NO | G19: 0 | H19: 0 | I19: 0 | J19: 0 | K19: 0 | L19: =CATEGORIAS[[#This Row],[ADICIONALES]]+CATEGORIAS[[#This Row],[POM]]+CATEGORIAS[[#This Row],[REAJUSTE PAGADO]]+CATEGORIAS[[#This Row],[REAJUSTE PROYECTADO]] -> 0 | M19: 0 | N19: 0 | O19: =+CATEGORIAS[[#This Row],[PRODUCCION PARTIDAS ORIGINALES ACTUAL]]+CATEGORIAS[[#This Row],[PRODUCCION ADICIONALES ACTUAL]] -> 0 | P19: 0 | Q19: 0 | R19: =+CATEGORIAS[[#This Row],[PRODUCCION ANTERIOR]]+CATEGORIAS[[#This Row],[PRODUCCION ADICIONALES ANTERIOR]] -> 0 | S19: 0 | U19: 0 | V19: =SUM(CATEGORIAS[[#This Row],[COSTO ACUMULADO AX]:[PROVISIONES]]) -> 0 | W19: 0 | Y19: 0 | Z19: =SUM(CATEGORIAS[[#This Row],[COSTO ACUMULADO ANTERIOR]:[PROVISIONES ANTERIOR]]) -> 0 | AA19: =ABS(+CATEGORIAS[[#This Row],[PRESUPUESTO FINAL PROYECTADO]]-CATEGORIAS[[#This Row],[TOTAL PRODUCCION ACTUAL]]) -> 0 | AD19: 0 | AE19: =SUM(CATEGORIAS[[#This Row],[INVENTARIO]:[PROYECCION DE COSTO DEL SALDO]]) -> 0 | AG19: =+CATEGORIAS[[#This Row],[PRESUPUESTO FINAL PROYECTADO]]-CATEGORIAS[[#This Row],[COSTO REAL]]-CATEGORIAS[[#This Row],[PROYECCION TOTAL DE COSTO]] -> 0
D20: 11-0321-619G | E20: Remuneraciones / Remuneraciones / Otros Dsctos. al Personal | F20: NO | G20: 0 | H20: 0 | I20: 0 | J20: 0 | K20: 0 | L20: =CATEGORIAS[[#This Row],[ADICIONALES]]+CATEGORIAS[[#This Row],[POM]]+CATEGORIAS[[#This Row],[REAJUSTE PAGADO]]+CATEGORIAS[[#This Row],[REAJUSTE PROYECTADO]] -> 0 | M20: 0 | N20: 0 | O20: =+CATEGORIAS[[#This Row],[PRODUCCION PARTIDAS ORIGINALES ACTUAL]]+CATEGORIAS[[#This Row],[PRODUCCION ADICIONALES ACTUAL]] -> 0 | P20: 0 | Q20: 0 | R20: =+CATEGORIAS[[#This Row],[PRODUCCION ANTERIOR]]+CATEGORIAS[[#This Row],[PRODUCCION ADICIONALES ANTERIOR]] -> 0 | S20: 0 | U20: 0 | V20: =SUM(CATEGORIAS[[#This Row],[COSTO ACUMULADO AX]:[PROVISIONES]]) -> 0 | W20: 0 | Y20: 0 | Z20: =SUM(CATEGORIAS[[#This Row],[COSTO ACUMULADO ANTERIOR]:[PROVISIONES ANTERIOR]]) -> 0 | AA20: =ABS(+CATEGORIAS[[#This Row],[PRESUPUESTO FINAL PROYECTADO]]-CATEGORIAS[[#This Row],[TOTAL PRODUCCION ACTUAL]]) -> 0 | AD20: 0 | AE20: =SUM(CATEGORIAS[[#This Row],[INVENTARIO]:[PROYECCION DE COSTO DEL SALDO]]) -> 0 | AG20: =+CATEGORIAS[[#This Row],[PRESUPUESTO FINAL PROYECTADO]]-CATEGORIAS[[#This Row],[COSTO REAL]]-CATEGORIAS[[#This Row],[PROYECCION TOTAL DE COSTO]] -> 0
D21: 11-0331-201G | E21: Remuneraciones / Remuneraciones / Remuneraciones | F21: NO | G21: 0 | H21: 0 | I21: 0 | J21: 0 | K21: 0 | L21: =CATEGORIAS[[#This Row],[ADICIONALES]]+CATEGORIAS[[#This Row],[POM]]+CATEGORIAS[[#This Row],[REAJUSTE PAGADO]]+CATEGORIAS[[#This Row],[REAJUSTE PROYECTADO]] -> 0 | M21: 0 | N21: 0 | O21: =+CATEGORIAS[[#This Row],[PRODUCCION PARTIDAS ORIGINALES ACTUAL]]+CATEGORIAS[[#This Row],[PRODUCCION ADICIONALES ACTUAL]] -> 0 | P21: 0 | Q21: 0 | R21: =+CATEGORIAS[[#This Row],[PRODUCCION ANTERIOR]]+CATEGORIAS[[#This Row],[PRODUCCION ADICIONALES ANTERIOR]] -> 0 | S21: 0 | U21: 0 | V21: =SUM(CATEGORIAS[[#This Row],[COSTO ACUMULADO AX]:[PROVISIONES]]) -> 0 | W21: 0 | Y21: 0 | Z21: =SUM(CATEGORIAS[[#This Row],[COSTO ACUMULADO ANTERIOR]:[PROVISIONES ANTERIOR]]) -> 0 | AA21: =ABS(+CATEGORIAS[[#This Row],[PRESUPUESTO FINAL PROYECTADO]]-CATEGORIAS[[#This Row],[TOTAL PRODUCCION ACTUAL]]) -> 0 | AD21: 0 | AE21: =SUM(CATEGORIAS[[#This Row],[INVENTARIO]:[PROYECCION DE COSTO DEL SALDO]]) -> 0 | AG21: =+CATEGORIAS[[#This Row],[PRESUPUESTO FINAL PROYECTADO]]-CATEGORIAS[[#This Row],[COSTO REAL]]-CATEGORIAS[[#This Row],[PROYECCION TOTAL DE COSTO]] -> 0
D22: 11-0407-000G | E22: MAO CD - Cañería / Soldadura (G) | F22: NO | G22: 0 | H22: 0 | I22: 0 | J22: 0 | K22: 0 | L22: =CATEGORIAS[[#This Row],[ADICIONALES]]+CATEGORIAS[[#This Row],[POM]]+CATEGORIAS[[#This Row],[REAJUSTE PAGADO]]+CATEGORIAS[[#This Row],[REAJUSTE PROYECTADO]] -> 0 | M22: 0 | N22: 0 | O22: =+CATEGORIAS[[#This Row],[PRODUCCION PARTIDAS ORIGINALES ACTUAL]]+CATEGORIAS[[#This Row],[PRODUCCION ADICIONALES ACTUAL]] -> 0 | P22: 0 | Q22: 0 | R22: =+CATEGORIAS[[#This Row],[PRODUCCION ANTERIOR]]+CATEGORIAS[[#This Row],[PRODUCCION ADICIONALES ANTERIOR]] -> 0 | S22: 0 | U22: 0 | V22: =SUM(CATEGORIAS[[#This Row],[COSTO ACUMULADO AX]:[PROVISIONES]]) -> 0 | W22: 0 | Y22: 0 | Z22: =SUM(CATEGORIAS[[#This Row],[COSTO ACUMULADO ANTERIOR]:[PROVISIONES ANTERIOR]]) -> 0 | AA22: =ABS(+CATEGORIAS[[#This Row],[PRESUPUESTO FINAL PROYECTADO]]-CATEGORIAS[[#This Row],[TOTAL PRODUCCION ACTUAL]]) -> 0 | AD22: 0 | AE22: =SUM(CATEGORIAS[[#This Row],[INVENTARIO]:[PROYECCION DE COSTO DEL SALDO]]) -> 0 | AG22: =+CATEGORIAS[[#This Row],[PRESUPUESTO FINAL PROYECTADO]]-CATEGORIAS[[#This Row],[COSTO REAL]]-CATEGORIAS[[#This Row],[PROYECCION TOTAL DE COSTO]] -> 0
A23: 0D01 | B23: 0A04 | C23: Cañería | D23: 11-0408-000G | E23: MAO CD - Cañería / Montajes (G) | F23: SI | G23: 37872374 | H23: 9336138.6 | I23: 9160674.7 | J23: 329176.89 | K23: 0 | L23: =CATEGORIAS[[#This Row],[ADICIONALES]]+CATEGORIAS[[#This Row],[POM]]+CATEGORIAS[[#This Row],[REAJUSTE PAGADO]]+CATEGORIAS[[#This Row],[REAJUSTE PROYECTADO]] -> 18825990 | M23: 9663482.8 | N23: 9162507.4 | O23: =+CATEGORIAS[[#This Row],[PRODUCCION PARTIDAS ORIGINALES ACTUAL]]+CATEGORIAS[[#This Row],[PRODUCCION ADICIONALES ACTUAL]] -> 18825990 | P23: 9663482.8 | Q23: 9160674.7 | R23: =+CATEGORIAS[[#This Row],[PRODUCCION ANTERIOR]]+CATEGORIAS[[#This Row],[PRODUCCION ADICIONALES ANTERIOR]] -> 18824158 | S23: 0 | U23: 0 | V23: =SUM(CATEGORIAS[[#This Row],[COSTO ACUMULADO AX]:[PROVISIONES]]) -> 0 | W23: 0 | Y23: 0 | Z23: =SUM(CATEGORIAS[[#This Row],[COSTO ACUMULADO ANTERIOR]:[PROVISIONES ANTERIOR]]) -> 0 | AA23: =ABS(+CATEGORIAS[[#This Row],[PRESUPUESTO FINAL PROYECTADO]]-CATEGORIAS[[#This Row],[TOTAL PRODUCCION ACTUAL]]) -> 0 | AE23: =SUM(CATEGORIAS[[#This Row],[INVENTARIO]:[PROYECCION DE COSTO DEL SALDO]]) -> 0 | AG23: =+CATEGORIAS[[#This Row],[PRESUPUESTO FINAL PROYECTADO]]-CATEGORIAS[[#This Row],[COSTO REAL]]-CATEGORIAS[[#This Row],[PROYECCION TOTAL DE COSTO]] -> 18825990
