Workbook
Name \1: #REF!
Name \q: #REF!
Name \w: #REF!
Name _______us96: #REF!
Name _____us96: #REF!
Name ____BAS1: #REF!
Name ____us96: #REF!
Name ___BAS1: #REF!
Name ___res1: #REF!
Name ___res3: #REF!
Name ___res4: #REF!
Name ___us96: #REF!
Name __BAS1: #REF!
Name __DAT1: #REF!
Name __DAT10: #REF!
Name __DAT11: #REF!
Name __DAT12: #REF!
Name __DAT13: #REF!
Name __DAT14: #REF!
Name __DAT15: #REF!
Name __DAT16: #REF!
Name __DAT17: #REF!
Name __DAT18: #REF!
Name __DAT19: #REF!
Name __DAT2: #REF!
Name __DAT20: #REF!
Name __DAT3: #REF!
Name __DAT4: #REF!
Name __DAT5: #REF!
Name __DAT6: #REF!
Name __DAT7: #REF!
Name __DAT8: #REF!
Name __DAT9: #REF!
Name __res1: #REF!
Name __res2: #REF!
Name __res3: #REF!
Name __res4: #REF!
Name __us96: #REF!
Name _A: #REF!
Name _aa: #REF!
Name _ACT1: #REF!
Name _ACT10: #REF!
Name _ACT11: #REF!
Name _ACT12: #REF!
Name _ACT13: #REF!
Name _ACT14: #REF!
Name _ACT15: #REF!
Name _ACT16: #REF!
Name _ACT17: #REF!
Name _ACT18: #REF!
Name _ACT19: #REF!
Name _ACT2: #REF!
Name _ACT20: #REF!
Name _ACT21: #REF!
Name _ACT22: #REF!
Name _ACT23: #REF!
Name _ACT3: #REF!
Name _ACT4: #REF!
Name _ACT5: #REF!
Name _ACT6: #REF!

Sheet Indice
D2: INDICE | H2: CC: EIMI00412 MONTAJE ELECTROMECÁNICO " PROYECTO NUEVAS PRENSAS DE LODOS"
C4: INFORME DE COSTOS N° 3
G9: Cliente : | H9: CMPC
G10: Administrador de Proyecto : | H10: Jose Petersen
G11: Centros de Costos : | H11: EIMI00412
G12: Periodo | H12: : | I12: 45992
C16: Matriz de Producción
C17: Matriz de Costos
C18: Matriz de Resultado
C19: Matriz de Proyecciones

Sheet Formato General
B1: INFORME DE RESULTADOS
B2: =MID(Indice!H2,1,100) -> CC: EIMI00412 MONTAJE ELECTROMECÁNICO " PROYECTO NUEVAS PRENSAS DE LODOS" | X2: ="Periodo : " & TEXT(Indice!I12,"Mmmm yyyy") -> Periodo : diciembre 2025
A4: FORMATO GENERAL | B4: Num | C4: Partida | E4: Presupuesto Original | F4: PBI | G4: DIFERENCIA | H4: Aumentos o Dism. de Obras y Reajuste | I4: PBI | J4: DIFERENCIA | K4: Presupuesto Corregido | L4: PBI | M4: DIFERENCIA | O4: Gastos Reales del Mes | P4: PBI | Q4: DIFERENCIA | R4: Gastos Reales Acumulados | S4: PBI | T4: DIFERENCIA | U4: Avance Según Obra Ejecutada | V4: PBI | W4: DIFERENCIA | X4: Proyección de gasto por efectuar | Y4: PBI | Z4: DIFERENCIA | AB4: Resultado de la Obra | AC4: PBI | AD4: DIFERENCIA
B5: A. | C5: Costos Directos
B6: A1 | C6: 01 - Obras Civiles | E6: =IF(ISBLANK(A6),"", SUMIF(CATEGORIAS[[#All],[FORMATO GENERAL]], A6, CATEGORIAS[[#All],[PRESUPUESTO (ORIGINAL)]])) | H6: =IF(ISBLANK(A6),"",K6-E6) | K6: =IF(ISBLANK(A6),"",SUMIF(CATEGORIAS[[#All],[FORMATO GENERAL]], A6, CATEGORIAS[[#All],[PRESUPUESTO FINAL PROYECTADO]])) | O6: =IF(ISBLANK(A6),"",R6-SUMIF(CATEGORIAS[[#All],[FORMATO GENERAL]], A6, CATEGORIAS[[#All],[COSTO REAL ANTERIOR]])) | R6: =IF(ISBLANK(A6),"",SUMIF(CATEGORIAS[[#All],[FORMATO GENERAL]], A6, CATEGORIAS[[#All],[COSTO REAL]])) | U6: =IF(ISBLANK(A6),"",SUMIF(CATEGORIAS[[#All],[FORMATO GENERAL]], A6, CATEGORIAS[[#All],[TOTAL PRODUCCION ACTUAL]])) | X6: =IF(ISBLANK(A6),"",SUMIF(CATEGORIAS[[#All],[FORMATO GENERAL]], A6, CATEGORIAS[[#All],[PROYECCION TOTAL DE COSTO]])) | AB6: =IF(ISBLANK(A6),"",TRUNC(K6-R6-X6,2))
A7: 0A01 | C7: Mano de Obra | E7: =IF(ISBLANK(A7),"", SUMIF(CATEGORIAS[[#All],[FORMATO GENERAL]], A7, CATEGORIAS[[#All],[PRESUPUESTO (ORIGINAL)]])) -> 1.4597251e+08 | F7: 145972510 | G7: =+E7-F7 -> 0.11940765 | H7: =IF(ISBLANK(A7),"",K7-E7) -> 14606632 | I7: 14606632 | J7: =+H7-I7 -> -0.11194655 | K7: =IF(ISBLANK(A7),"",SUMIF(CATEGORIAS[[#All],[FORMATO GENERAL]], A7, CATEGORIAS[[#All],[PRESUPUESTO FINAL PROYECTADO]])) -> 1.6057914e+08 | L7: 160579142 | M7: =+K7-L7 -> 0.0074611008 | O7: =IF(ISBLANK(A7),"",R7-SUMIF(CATEGORIAS[[#All],[FORMATO GENERAL]], A7, CATEGORIAS[[#All],[COSTO REAL ANTERIOR]])) -> 48030488 | P7: 48030488 | Q7: =+O7-P7 -> 0.087633081 | R7: =IF(ISBLANK(A7),"",SUMIF(CATEGORIAS[[#All],[FORMATO GENERAL]], A7, CATEGORIAS[[#All],[COSTO REAL]])) -> 1.0783158e+08 | S7: 107831578 | T7: =+R7-S7 -> -0.074529082 | U7: =IF(ISBLANK(A7),"",SUMIF(CATEGORIAS[[#All],[FORMATO GENERAL]], A7, CATEGORIAS[[#All],[TOTAL PRODUCCION ACTUAL]])) -> 1.1662961e+08 | V7: 116629607 | W7: =+U7-V7 -> 0.26106611 | X7: =IF(ISBLANK(A7),"",SUMIF(CATEGORIAS[[#All],[FORMATO GENERAL]], A7, CATEGORIAS[[#All],[PROYECCION TOTAL DE COSTO]])) -> 52747564 | Y7: 52747564 | Z7: =+X7-Y7 -> 0.081990182 | AB7: =IF(ISBLANK(A7),"",TRUNC(K7-R7-X7,2)) -> 0 | AD7: =+AB7-AC7 -> 0
A8: 0A02 | C8: Obras Civiles Reembolsable | E8: =IF(ISBLANK(A8),"", SUMIF(CATEGORIAS[[#All],[FORMATO GENERAL]], A8, CATEGORIAS[[#All],[PRESUPUESTO (ORIGINAL)]])) -> 64602232 | F8: 64602232 | G8: =+E8-F8 -> -0.1283 | H8: =IF(ISBLANK(A8),"",K8-E8) -> 15412760 | I8: 15412760 | J8: =+H8-I8 -> 0.050430097 | K8: =IF(ISBLANK(A8),"",SUMIF(CATEGORIAS[[#All],[FORMATO GENERAL]], A8, CATEGORIAS[[#All],[PRESUPUESTO FINAL PROYECTADO]])) -> 80014992 | L8: 80014992 | M8: =+K8-L8 -> -0.077869907 | O8: =IF(ISBLANK(A8),"",R8-SUMIF(CATEGORIAS[[#All],[FORMATO GENERAL]], A8, CATEGORIAS[[#All],[COSTO REAL ANTERIOR]])) -> 6141908 | P8: 6141908 | Q8: =+O8-P8 -> 0 | R8: =IF(ISBLANK(A8),"",SUMIF(CATEGORIAS[[#All],[FORMATO GENERAL]], A8, CATEGORIAS[[#All],[COSTO REAL]])) -> 21679270 | S8: 21679270 | T8: =+R8-S8 -> 0 | U8: =IF(ISBLANK(A8),"",SUMIF(CATEGORIAS[[#All],[FORMATO GENERAL]], A8, CATEGORIAS[[#All],[TOTAL PRODUCCION ACTUAL]])) -> 26331435 | V8: 26331435 | W8: =+U8-V8 -> 0.4492 | X8: =IF(ISBLANK(A8),"",SUMIF(CATEGORIAS[[#All],[FORMATO GENERAL]], A8, CATEGORIAS[[#All],[PROYECCION TOTAL DE COSTO]])) -> 58335715 | Y8: 58335715 | Z8: =+X8-Y8 -> -0.077869907 | AB8: =IF(ISBLANK(A8),"",TRUNC(K8-R8-X8,2)) -> 7 | AD8: =+AB8-AC8 -> 7
B9: A2 | C9: 02 - Estructura | E9: =IF(ISBLANK(A9),"", SUMIF(CATEGORIAS[[#All],[FORMATO GENERAL]], A9, CATEGORIAS[[#All],[PRESUPUESTO (ORIGINAL)]])) | G9: =+E9-F9 -> #VALUE! | H9: =IF(ISBLANK(A9),"",K9-E9) | J9: =+H9-I9 -> #VALUE! | K9: =IF(ISBLANK(A9),"",SUMIF(CATEGORIAS[[#All],[FORMATO GENERAL]], A9, CATEGORIAS[[#All],[PRESUPUESTO FINAL PROYECTADO]])) | M9: =+K9-L9 -> #VALUE! | O9: =IF(ISBLANK(A9),"",R9-SUMIF(CATEGORIAS[[#All],[FORMATO GENERAL]], A9, CATEGORIAS[[#All],[COSTO REAL ANTERIOR]])) | Q9: =+O9-P9 -> #VALUE! | R9: =IF(ISBLANK(A9),"",SUMIF(CATEGORIAS[[#All],[FORMATO GENERAL]], A9, CATEGORIAS[[#All],[COSTO REAL]])) | T9: =+R9-S9 -> #VALUE! | U9: =IF(ISBLANK(A9),"",SUMIF(CATEGORIAS[[#All],[FORMATO GENERAL]], A9, CATEGORIAS[[#All],[TOTAL PRODUCCION ACTUAL]])) | W9: =+U9-V9 -> #VALUE! | X9: =IF(ISBLANK(A9),"",SUMIF(CATEGORIAS[[#All],[FORMATO GENERAL]], A9, CATEGORIAS[[#All],[PROYECCION TOTAL DE COSTO]])) | Z9: =+X9-Y9 -> #VALUE! | AB9: =IF(ISBLANK(A9),"",TRUNC(K9-R9-X9,2)) | AD9: =+AB9-AC9 -> #VALUE!
A10: 0B01 | C10: Mano de Obra | E10: =IF(ISBLANK(A10),"", SUMIF(CATEGORIAS[[#All],[FORMATO GENERAL]], A10, CATEGORIAS[[#All],[PRESUPUESTO (ORIGINAL)]])) -> 1.7987561e+08 | F10: 179875615 | G10: =+E10-F10 -> -0.11864346 | H10: =IF(ISBLANK(A10),"",K10-E10) -> 612034.1 | I10: 612034 | J10: =+H10-I10 -> 0.098096818 | K10: =IF(ISBLANK(A10),"",SUMIF(CATEGORIAS[[#All],[FORMATO GENERAL]], A10, CATEGORIAS[[#All],[PRESUPUESTO FINAL PROYECTADO]])) -> 1.8048765e+08 | L10: 180487649 | M10: =+K10-L10 -> -0.020546645 | O10: =IF(ISBLANK(A10),"",R10-SUMIF(CATEGORIAS[[#All],[FORMATO GENERAL]], A10, CATEGORIAS[[#All],[COSTO REAL ANTERIOR]])) -> 61673899 | P10: 61673899 | Q10: =+O10-P10 -> 0.13677312 | R10: =IF(ISBLANK(A10),"",SUMIF(CATEGORIAS[[#All],[FORMATO GENERAL]], A10, CATEGORIAS[[#All],[COSTO REAL]])) -> 1.5135843e+08 | S10: 151358428 | T10: =+R10-S10 -> 0.37592137 | U10: =IF(ISBLANK(A10),"",SUMIF(CATEGORIAS[[#All],[FORMATO GENERAL]], A10, CATEGORIAS[[#All],[TOTAL PRODUCCION ACTUAL]])) -> 70290747 | V10: 70290747 | W10: =+U10-V10 -> 0.35645182 | X10: =IF(ISBLANK(A10),"",SUMIF(CATEGORIAS[[#All],[FORMATO GENERAL]], A10, CATEGORIAS[[#All],[PROYECCION TOTAL DE COSTO]])) -> 29129221 | Y10: 29129221 | Z10: =+X10-Y10 -> -0.39646801 | AB10: =IF(ISBLANK(A10),"",TRUNC(K10-R10-X10,2)) -> 0 | AD10: =+AB10-AC10 -> 0
A11: 0B02 | C11: Estructura Reembolsable | E11: =IF(ISBLANK(A11),"", SUMIF(CATEGORIAS[[#All],[FORMATO GENERAL]], A11, CATEGORIAS[[#All],[PRESUPUESTO (ORIGINAL)]])) -> 53940891 | F11: 53940891 | G11: =+E11-F11 -> -0.047499999 | H11: =IF(ISBLANK(A11),"",K11-E11) -> 31204.186 | I11: 31204 | J11: =+H11-I11 -> 0.18552163 | K11: =IF(ISBLANK(A11),"",SUMIF(CATEGORIAS[[#All],[FORMATO GENERAL]], A11, CATEGORIAS[[#All],[PRESUPUESTO FINAL PROYECTADO]])) -> 53972095 | L11: 53972095 | M11: =+K11-L11 -> 0.13802163 | O11: =IF(ISBLANK(A11),"",R11-SUMIF(CATEGORIAS[[#All],[FORMATO GENERAL]], A11, CATEGORIAS[[#All],[COSTO REAL ANTERIOR]])) -> 1917454 | P11: 1917454 | Q11: =+O11-P11 -> 0 | R11: =IF(ISBLANK(A11),"",SUMIF(CATEGORIAS[[#All],[FORMATO GENERAL]], A11, CATEGORIAS[[#All],[COSTO REAL]])) -> 2601319 | S11: 2601319 | T11: =+R11-S11 -> 0 | U11: =IF(ISBLANK(A11),"",SUMIF(CATEGORIAS[[#All],[FORMATO GENERAL]], A11, CATEGORIAS[[#All],[TOTAL PRODUCCION ACTUAL]])) -> 23564053 | V11: 23564053 | W11: =+U11-V11 -> -0.17937837 | X11: =IF(ISBLANK(A11),"",SUMIF(CATEGORIAS[[#All],[FORMATO GENERAL]], A11, CATEGORIAS[[#All],[PROYECCION TOTAL DE COSTO]])) -> 51370776 | Y11: 51370776 | Z11: =+X11-Y11 -> 0.13802163 | AB11: =IF(ISBLANK(A11),"",TRUNC(K11-R11-X11,2)) -> 0 | AD11: =+AB11-AC11 -> 0
B12: A3 | C12: 03 - Mecanica (MO Arquitectura Puentes) | E12: =IF(ISBLANK(A12),"", SUMIF(CATEGORIAS[[#All],[FORMATO GENERAL]], A12, CATEGORIAS[[#All],[PRESUPUESTO (ORIGINAL)]])) | G12: =+E12-F12 -> #VALUE! | H12: =IF(ISBLANK(A12),"",K12-E12) | J12: =+H12-I12 -> #VALUE! | K12: =IF(ISBLANK(A12),"",SUMIF(CATEGORIAS[[#All],[FORMATO GENERAL]], A12, CATEGORIAS[[#All],[PRESUPUESTO FINAL PROYECTADO]])) | M12: =+K12-L12 -> #VALUE! | O12: =IF(ISBLANK(A12),"",R12-SUMIF(CATEGORIAS[[#All],[FORMATO GENERAL]], A12, CATEGORIAS[[#All],[COSTO REAL ANTERIOR]])) | Q12: =+O12-P12 -> #VALUE! | R12: =IF(ISBLANK(A12),"",SUMIF(CATEGORIAS[[#All],[FORMATO GENERAL]], A12, CATEGORIAS[[#All],[COSTO REAL]])) | T12: =+R12-S12 -> #VALUE! | U12: =IF(ISBLANK(A12),"",SUMIF(CATEGORIAS[[#All],[FORMATO GENERAL]], A12, CATEGORIAS[[#All],[TOTAL PRODUCCION ACTUAL]])) | W12: =+U12-V12 -> #VALUE! | X12: =IF(ISBLANK(A12),"",SUMIF(CATEGORIAS[[#All],[FORMATO GENERAL]], A12, CATEGORIAS[[#All],[PROYECCION TOTAL DE COSTO]])) | Z12: =+X12-Y12 -> #VALUE! | AB12: =IF(ISBLANK(A12),"",TRUNC(K12-R12-X12,2)) | AD12: =+AB12-AC12 -> #VALUE!
A13: 0C01 | C13: Mano de Obra | E13: =IF(ISBLANK(A13),"", SUMIF(CATEGORIAS[[#All],[FORMATO GENERAL]], A13, CATEGORIAS[[#All],[PRESUPUESTO (ORIGINAL)]])) -> 1.332508e+08 | F13: 133250804 | G13: =+E13-F13 -> 0.19788337 | H13: =IF(ISBLANK(A13),"",K13-E13) -> 8661404.9 | I13: 8661405 | J13: =+H13-I13 -> -0.065739036 | K13: =IF(ISBLANK(A13),"",SUMIF(CATEGORIAS[[#All],[FORMATO GENERAL]], A13, CATEGORIAS[[#All],[PRESUPUESTO FINAL PROYECTADO]])) -> 1.4191221e+08 | L13: 141912209 | M13: =+K13-L13 -> 0.13214433 | O13: =IF(ISBLANK(A13),"",R13-SUMIF(CATEGORIAS[[#All],[FORMATO GENERAL]], A13, CATEGORIAS[[#All],[COSTO REAL ANTERIOR]])) -> 47992218 | P13: 47992218 | Q13: =+O13-P13 -> -0.25307125 | R13: =IF(ISBLANK(A13),"",SUMIF(CATEGORIAS[[#All],[FORMATO GENERAL]], A13, CATEGORIAS[[#All],[COSTO REAL]])) -> 1.4843688e+08 | S13: 148436879 | T13: =+R13-S13 -> -0.13267812 | U13: =IF(ISBLANK(A13),"",SUMIF(CATEGORIAS[[#All],[FORMATO GENERAL]], A13, CATEGORIAS[[#All],[TOTAL PRODUCCION ACTUAL]])) -> 57846587 | V13: 57846587 | W13: =+U13-V13 -> -0.42201257 | X13: =IF(ISBLANK(A13),"",SUMIF(CATEGORIAS[[#All],[FORMATO GENERAL]], A13, CATEGORIAS[[#All],[PROYECCION TOTAL DE COSTO]])) -> -6524669.7 | Y13: -6524670 | Z13: =+X13-Y13 -> 0.26482245 | AB13: =IF(ISBLANK(A13),"",TRUNC(K13-R13-X13,2)) -> 0 | AD13: =+AB13-AC13 -> 0
A14: 0C02 | C14: Mecanica Reembolsable | E14: =IF(ISBLANK(A14),"", SUMIF(CATEGORIAS[[#All],[FORMATO GENERAL]], A14, CATEGORIAS[[#All],[PRESUPUESTO (ORIGINAL)]])) -> 65364961 | F14: 65364961 | G14: =+E14-F14 -> -0.069499999 | H14: =IF(ISBLANK(A14),"",K14-E14) -> 2398036.9 | I14: 2398037 | J14: =+H14-I14 -> -0.069623649 | K14: =IF(ISBLANK(A14),"",SUMIF(CATEGORIAS[[#All],[FORMATO GENERAL]], A14, CATEGORIAS[[#All],[PRESUPUESTO FINAL PROYECTADO]])) -> 67762998 | L14: 67762998 | M14: =+K14-L14 -> -0.13912365 | O14: =IF(ISBLANK(A14),"",R14-SUMIF(CATEGORIAS[[#All],[FORMATO GENERAL]], A14, CATEGORIAS[[#All],[COSTO REAL ANTERIOR]])) -> 6395578 | P14: 6395578 | Q14: =+O14-P14 -> 0 | R14: =IF(ISBLANK(A14),"",SUMIF(CATEGORIAS[[#All],[FORMATO GENERAL]], A14, CATEGORIAS[[#All],[COSTO REAL]])) -> 15218949 | S14: 15218949 | T14: =+R14-S14 -> 0 | U14: =IF(ISBLANK(A14),"",SUMIF(CATEGORIAS[[#All],[FORMATO GENERAL]], A14, CATEGORIAS[[#All],[TOTAL PRODUCCION ACTUAL]])) -> 21505782 | V14: 21505782 | W14: =+U14-V14 -> 0.40672635 | X14: =IF(ISBLANK(A14),"",SUMIF(CATEGORIAS[[#All],[FORMATO GENERAL]], A14, CATEGORIAS[[#All],[PROYECCION TOTAL DE COSTO]])) -> 52544049 | Y14: 52544049 | Z14: =+X14-Y14 -> -0.13912365 | AB14: =IF(ISBLANK(A14),"",TRUNC(K14-R14-X14,2)) -> 0 | AD14: =+AB14-AC14 -> 0
B15: A4 | C15: 04 - Cañeria | E15: =IF(ISBLANK(A15),"", SUMIF(CATEGORIAS[[#All],[FORMATO GENERAL]], A15, CATEGORIAS[[#All],[PRESUPUESTO (ORIGINAL)]])) | G15: =+E15-F15 -> #VALUE! | H15: =IF(ISBLANK(A15),"",K15-E15) | J15: =+H15-I15 -> #VALUE! | K15: =IF(ISBLANK(A15),"",SUMIF(CATEGORIAS[[#All],[FORMATO GENERAL]], A15, CATEGORIAS[[#All],[PRESUPUESTO FINAL PROYECTADO]])) | M15: =+K15-L15 -> #VALUE! | O15: =IF(ISBLANK(A15),"",R15-SUMIF(CATEGORIAS[[#All],[FORMATO GENERAL]], A15, CATEGORIAS[[#All],[COSTO REAL ANTERIOR]])) | Q15: =+O15-P15 -> #VALUE! | R15: =IF(ISBLANK(A15),"",SUMIF(CATEGORIAS[[#All],[FORMATO GENERAL]], A15, CATEGORIAS[[#All],[COSTO REAL]])) | T15: =+R15-S15 -> #VALUE! | U15: =IF(ISBLANK(A15),"",SUMIF(CATEGORIAS[[#All],[FORMATO GENERAL]], A15, CATEGORIAS[[#All],[TOTAL PRODUCCION ACTUAL]])) | W15: =+U15-V15 -> #VALUE! | X15: =IF(ISBLANK(A15),"",SUMIF(CATEGORIAS[[#All],[FORMATO GENERAL]], A15, CATEGORIAS[[#All],[PROYECCION TOTAL DE COSTO]])) | Z15: =+X15-Y15 -> #VALUE! | AB15: =IF(ISBLANK(A15),"",TRUNC(K15-R15-X15,2)) | AD15: =+AB15-AC15 -> #VALUE!
A16: 0D01 | C16: Mano de Obra | E16: =IF(ISBLANK(A16),"", SUMIF(CATEGORIAS[[#All],[FORMATO GENERAL]], A16, CATEGORIAS[[#All],[PRESUPUESTO (ORIGINAL)]])) -> 4.7397038e+08 | F16: 473970383 | G16: =+E16-F16 -> -0.36377794 | H16: =IF(ISBLANK(A16),"",K16-E16) -> 17687642 | I16: 17687642 | J16: =+H16-I16 -> 0.15925747 | K16: =IF(ISBLANK(A16),"",SUMIF(CATEGORIAS[[#All],[FORMATO GENERAL]], A16, CATEGORIAS[[#All],[PRESUPUESTO FINAL PROYECTADO]])) -> 4.9165802e+08 | L16: 491658025 | M16: =+K16-L16 -> -0.20452046 | O16: =IF(ISBLANK(A16),"",R16-SUMIF(CATEGORIAS[[#All],[FORMATO GENERAL]], A16, CATEGORIAS[[#All],[COSTO REAL ANTERIOR]])) -> 97545747 | P16: 97545748 | Q16: =+O16-P16 -> -0.80016381 | R16: =IF(ISBLANK(A16),"",SUMIF(CATEGORIAS[[#All],[FORMATO GENERAL]], A16, CATEGORIAS[[#All],[COSTO REAL]])) -> 2.4410529e+08 | S16: 244105286 | T16: =+R16-S16 -> -0.39066339 | U16: =IF(ISBLANK(A16),"",SUMIF(CATEGORIAS[[#All],[FORMATO GENERAL]], A16, CATEGORIAS[[#All],[TOTAL PRODUCCION ACTUAL]])) -> 2.0089425e+08 | V16: 200894250 | W16: =+U16-V16 -> -0.026842386 | X16: =IF(ISBLANK(A16),"",SUMIF(CATEGORIAS[[#All],[FORMATO GENERAL]], A16, CATEGORIAS[[#All],[PROYECCION TOTAL DE COSTO]])) -> 2.4755274e+08 | Y16: 247552739 | Z16: =+X16-Y16 -> 0.18614292 | AB16: =IF(ISBLANK(A16),"",TRUNC(K16-R16-X16,2)) -> 0 | AD16: =+AB16-AC16 -> 0
A17: 0D02 | C17: Cañeria Reembolsable | E17: =IF(ISBLANK(A17),"", SUMIF(CATEGORIAS[[#All],[FORMATO GENERAL]], A17, CATEGORIAS[[#All],[PRESUPUESTO (ORIGINAL)]])) -> 1.3799808e+08 | F17: 137998078 | G17: =+E17-F17 -> 0.26400003 | H17: =IF(ISBLANK(A17),"",K17-E17) -> 3121699.7 | I17: 3121700 | J17: =+H17-I17 -> -0.2527684 | K17: =IF(ISBLANK(A17),"",SUMIF(CATEGORIAS[[#All],[FORMATO GENERAL]], A17, CATEGORIAS[[#All],[PRESUPUESTO FINAL PROYECTADO]])) -> 1.4111978e+08 | L17: 141119778 | M17: =+K17-L17 -> 0.011231631 | O17: =IF(ISBLANK(A17),"",R17-SUMIF(CATEGORIAS[[#All],[FORMATO GENERAL]], A17, CATEGORIAS[[#All],[COSTO REAL ANTERIOR]])) -> 21866710 | P17: 21866710 | Q17: =+O17-P17 -> 0 | R17: =IF(ISBLANK(A17),"",SUMIF(CATEGORIAS[[#All],[FORMATO GENERAL]], A17, CATEGORIAS[[#All],[COSTO REAL]])) -> 120804123 | S17: 120804123 | T17: =+R17-S17 -> 0 | U17: =IF(ISBLANK(A17),"",SUMIF(CATEGORIAS[[#All],[FORMATO GENERAL]], A17, CATEGORIAS[[#All],[TOTAL PRODUCCION ACTUAL]])) -> 66472512 | V17: 66472512 | W17: =+U17-V17 -> -0.47079682 | X17: =IF(ISBLANK(A17),"",SUMIF(CATEGORIAS[[#All],[FORMATO GENERAL]], A17, CATEGORIAS[[#All],[PROYECCION TOTAL DE COSTO]])) -> 20315655 | Y17: 20315655 | Z17: =+X17-Y17 -> 0.011231627 | AB17: =IF(ISBLANK(A17),"",TRUNC(K17-R17-X17,2)) -> 0 | AD17: =+AB17-AC17 -> 0
B18: A5 | C18: 05- Electricidad & Instrumentacion | E18: =IF(ISBLANK(A18),"", SUMIF(CATEGORIAS[[#All],[FORMATO GENERAL]], A18, CATEGORIAS[[#All],[PRESUPUESTO (ORIGINAL)]])) | G18: =+E18-F18 -> #VALUE! | H18: =IF(ISBLANK(A18),"",K18-E18) | J18: =+H18-I18 -> #VALUE! | K18: =IF(ISBLANK(A18),"",SUMIF(CATEGORIAS[[#All],[FORMATO GENERAL]], A18, CATEGORIAS[[#All],[PRESUPUESTO FINAL PROYECTADO]])) | M18: =+K18-L18 -> #VALUE! | O18: =IF(ISBLANK(A18),"",R18-SUMIF(CATEGORIAS[[#All],[FORMATO GENERAL]], A18, CATEGORIAS[[#All],[COSTO REAL ANTERIOR]])) | Q18: =+O18-P18 -> #VALUE! | R18: =IF(ISBLANK(A18),"",SUMIF(CATEGORIAS[[#All],[FORMATO GENERAL]], A18, CATEGORIAS[[#All],[COSTO REAL]])) | T18: =+R18-S18 -> #VALUE! | U18: =IF(ISBLANK(A18),"",SUMIF(CATEGORIAS[[#All],[FORMATO GENERAL]], A18, CATEGORIAS[[#All],[TOTAL PRODUCCION ACTUAL]])) | W18: =+U18-V18 -> #VALUE! | X18: =IF(ISBLANK(A18),"",SUMIF(CATEGORIAS[[#All],[FORMATO GENERAL]], A18, CATEGORIAS[[#All],[PROYECCION TOTAL DE COSTO]])) | Z18: =+X18-Y18 -> #VALUE! | AB18: =IF(ISBLANK(A18),"",TRUNC(K18-R18-X18,2)) | AD18: =+AB18-AC18 -> #VALUE!
A19: 0F01 | C19: Mano de Obra | E19: =IF(ISBLANK(A19),"", SUMIF(CATEGORIAS[[#All],[FORMATO GENERAL]], A19, CATEGORIAS[[#All],[PRESUPUESTO (ORIGINAL)]])) -> 3.8799498e+08 | F19: 387994981 | G19: =+E19-F19 -> -0.0095154643 | H19: =IF(ISBLANK(A19),"",K19-E19) -> 11735815 | I19: 11735815 | J19: =+H19-I19 -> 0.31848192 | K19: =IF(ISBLANK(A19),"",SUMIF(CATEGORIAS[[#All],[FORMATO GENERAL]], A19, CATEGORIAS[[#All],[PRESUPUESTO FINAL PROYECTADO]])) -> 3.997308e+08 | L19: 399730796 | M19: =+K19-L19 -> 0.30896646 | O19: =IF(ISBLANK(A19),"",R19-SUMIF(CATEGORIAS[[#All],[FORMATO GENERAL]], A19, CATEGORIAS[[#All],[COSTO REAL ANTERIOR]])) -> 48101003 | P19: 48101003 | Q19: =+O19-P19 -> 0.41932841 | R19: =IF(ISBLANK(A19),"",SUMIF(CATEGORIAS[[#All],[FORMATO GENERAL]], A19, CATEGORIAS[[#All],[COSTO REAL]])) -> 94638932 | S19: 94638932 | T19: =+R19-S19 -> 0.37510237 | U19: =IF(ISBLANK(A19),"",SUMIF(CATEGORIAS[[#All],[FORMATO GENERAL]], A19, CATEGORIAS[[#All],[TOTAL PRODUCCION ACTUAL]])) -> 50124938 | V19: 50124938 | W19: =+U19-V19 -> -0.29480966 | X19: =IF(ISBLANK(A19),"",SUMIF(CATEGORIAS[[#All],[FORMATO GENERAL]], A19, CATEGORIAS[[#All],[PROYECCION TOTAL DE COSTO]])) -> 3.0509186e+08 | Y19: 305091864 | Z19: =+X19-Y19 -> -0.066135883 | AB19: =IF(ISBLANK(A19),"",TRUNC(K19-R19-X19,2)) -> 0 | AD19: =+AB19-AC19 -> 0
A20: 0F02 | C20: Electricidad Reembolsable | E20: =IF(ISBLANK(A20),"", SUMIF(CATEGORIAS[[#All],[FORMATO GENERAL]], A20, CATEGORIAS[[#All],[PRESUPUESTO (ORIGINAL)]])) -> 1.1524467e+08 | F20: 115244667 | G20: =+E20-F20 -> -0.017499998 | H20: =IF(ISBLANK(A20),"",K20-E20) -> 7814199.6 | I20: 7814200 | J20: =+H20-I20 -> -0.39764924 | K20: =IF(ISBLANK(A20),"",SUMIF(CATEGORIAS[[#All],[FORMATO GENERAL]], A20, CATEGORIAS[[#All],[PRESUPUESTO FINAL PROYECTADO]])) -> 1.2305887e+08 | L20: 123058867 | M20: =+K20-L20 -> -0.41514924 | O20: =IF(ISBLANK(A20),"",R20-SUMIF(CATEGORIAS[[#All],[FORMATO GENERAL]], A20, CATEGORIAS[[#All],[COSTO REAL ANTERIOR]])) -> 20231798 | P20: 20231798 | Q20: =+O20-P20 -> 0 | R20: =IF(ISBLANK(A20),"",SUMIF(CATEGORIAS[[#All],[FORMATO GENERAL]], A20, CATEGORIAS[[#All],[COSTO REAL]])) -> 41128877 | S20: 41128877 | T20: =+R20-S20 -> 0 | U20: =IF(ISBLANK(A20),"",SUMIF(CATEGORIAS[[#All],[FORMATO GENERAL]], A20, CATEGORIAS[[#All],[TOTAL PRODUCCION ACTUAL]])) -> 25860927 | V20: 25860927 | W20: =+U20-V20 -> 0.068724085 | X20: =IF(ISBLANK(A20),"",SUMIF(CATEGORIAS[[#All],[FORMATO GENERAL]], A20, CATEGORIAS[[#All],[PROYECCION TOTAL DE COSTO]])) -> 81929990 | Y20: 81929990 | Z20: =+X20-Y20 -> -0.41514924 | AB20: =IF(ISBLANK(A20),"",TRUNC(K20-R20-X20,2)) -> 0 | AD20: =+AB20-AC20 -> 0
B21: A6 | C21: 06 - Andamios | E21: =IF(ISBLANK(A21),"", SUMIF(CATEGORIAS[[#All],[FORMATO GENERAL]], A21, CATEGORIAS[[#All],[PRESUPUESTO (ORIGINAL)]])) | G21: =+E21-F21 -> #VALUE! | H21: =IF(ISBLANK(A21),"",K21-E21) | J21: =+H21-I21 -> #VALUE! | K21: =IF(ISBLANK(A21),"",SUMIF(CATEGORIAS[[#All],[FORMATO GENERAL]], A21, CATEGORIAS[[#All],[PRESUPUESTO FINAL PROYECTADO]])) | M21: =+K21-L21 -> #VALUE! | O21: =IF(ISBLANK(A21),"",R21-SUMIF(CATEGORIAS[[#All],[FORMATO GENERAL]], A21, CATEGORIAS[[#All],[COSTO REAL ANTERIOR]])) | Q21: =+O21-P21 -> #VALUE! | R21: =IF(ISBLANK(A21),"",SUMIF(CATEGORIAS[[#All],[FORMATO GENERAL]], A21, CATEGORIAS[[#All],[COSTO REAL]])) | T21: =+R21-S21 -> #VALUE! | U21: =IF(ISBLANK(A21),"",SUMIF(CATEGORIAS[[#All],[FORMATO GENERAL]], A21, CATEGORIAS[[#All],[TOTAL PRODUCCION ACTUAL]])) | W21: =+U21-V21 -> #VALUE! | X21: =IF(ISBLANK(A21),"",SUMIF(CATEGORIAS[[#All],[FORMATO GENERAL]], A21, CATEGORIAS[[#All],[PROYECCION TOTAL DE COSTO]])) | Z21: =+X21-Y21 -> #VALUE! | AB21: =IF(ISBLANK(A21),"",TRUNC(K21-R21-X21,2)) | AD21: =+AB21-AC21 -> #VALUE!
A22: 0G01 | C22: Mano de Obra | E22: =IF(ISBLANK(A22),"", SUMIF(CATEGORIAS[[#All],[FORMATO GENERAL]], A22, CATEGORIAS[[#All],[PRESUPUESTO (ORIGINAL)]])) -> 79797653 | F22: 79797653 | G22: =+E22-F22 -> -0.18236393 | H22: =IF(ISBLANK(A22),"",K22-E22) -> 2031426.5 | I22: 2031427 | J22: =+H22-I22 -> -0.4911463 | K22: =IF(ISBLANK(A22),"",SUMIF(CATEGORIAS[[#All],[FORMATO GENERAL]], A22, CATEGORIAS[[#All],[PRESUPUESTO FINAL PROYECTADO]])) -> 81829079 | L22: 81829079 | M22: =+K22-L22 -> 0.32648978 | O22: =IF(ISBLANK(A22),"",R22-SUMIF(CATEGORIAS[[#All],[FORMATO GENERAL]], A22, CATEGORIAS[[#All],[COSTO REAL ANTERIOR]])) -> 43427321 | P22: 43427321 | Q22: =+O22-P22 -> -0.37264537 | R22: =IF(ISBLANK(A22),"",SUMIF(CATEGORIAS[[#All],[FORMATO GENERAL]], A22, CATEGORIAS[[#All],[COSTO REAL]])) -> 88410801 | S22: 88410801 | T22: =+R22-S22 -> 0.12121212 | U22: =IF(ISBLANK(A22),"",SUMIF(CATEGORIAS[[#All],[FORMATO GENERAL]], A22, CATEGORIAS[[#All],[TOTAL PRODUCCION ACTUAL]])) -> 32123966 | V22: 32123966 | W22: =+U22-V22 -> -0.21972494 | X22: =IF(ISBLANK(A22),"",SUMIF(CATEGORIAS[[#All],[FORMATO GENERAL]], A22, CATEGORIAS[[#All],[PROYECCION TOTAL DE COSTO]])) -> -6581721.8 | Y22: -6581722 | Z22: =+X22-Y22 -> 0.20527765 | AB22: =IF(ISBLANK(A22),"",TRUNC(K22-R22-X22,2)) -> 0 | AD22: =+AB22-AC22 -> 0
B23: A7 | C23: 07 - Aislación | E23: =IF(ISBLANK(A23),"", SUMIF(CATEGORIAS[[#All],[FORMATO GENERAL]], A23, CATEGORIAS[[#All],[PRESUPUESTO (ORIGINAL)]])) | G23: =+E23-F23 -> #VALUE! | H23: =IF(ISBLANK(A23),"",K23-E23) | J23: =+H23-I23 -> #VALUE! | K23: =IF(ISBLANK(A23),"",SUMIF(CATEGORIAS[[#All],[FORMATO GENERAL]], A23, CATEGORIAS[[#All],[PRESUPUESTO FINAL PROYECTADO]])) | M23: =+K23-L23 -> #VALUE! | O23: =IF(ISBLANK(A23),"",R23-SUMIF(CATEGORIAS[[#All],[FORMATO GENERAL]], A23, CATEGORIAS[[#All],[COSTO REAL ANTERIOR]])) | Q23: =+O23-P23 -> #VALUE! | R23: =IF(ISBLANK(A23),"",SUMIF(CATEGORIAS[[#All],[FORMATO GENERAL]], A23, CATEGORIAS[[#All],[COSTO REAL]])) | T23: =+R23-S23 -> #VALUE! | U23: =IF(ISBLANK(A23),"",SUMIF(CATEGORIAS[[#All],[FORMATO GENERAL]], A23, CATEGORIAS[[#All],[TOTAL PRODUCCION ACTUAL]])) | W23: =+U23-V23 -> #VALUE! | X23: =IF(ISBLANK(A23),"",SUMIF(CATEGORIAS[[#All],[FORMATO GENERAL]], A23, CATEGORIAS[[#All],[PROYECCION TOTAL DE COSTO]])) | Z23: =+X23-Y23 -> #VALUE! | AB23: =IF(ISBLANK(A23),"",TRUNC(K23-R23-X23,2)) | AD23: =+AB23-AC23 -> #VALUE!
A24: 0H01 | C24: Mano de Obra | E24: =IF(ISBLANK(A24),"", SUMIF(CATEGORIAS[[#All],[FORMATO GENERAL]], A24, CATEGORIAS[[#All],[PRESUPUESTO (ORIGINAL)]])) -> 25004643 | F24: 25004643 | G24: =+E24-F24 -> -0.37450741 | H24: =IF(ISBLANK(A24),"",K24-E24) -> 0 | J24: =+H24-I24 -> 0 | K24: =IF(ISBLANK(A24),"",SUMIF(CATEGORIAS[[#All],[FORMATO GENERAL]], A24, CATEGORIAS[[#All],[PRESUPUESTO FINAL PROYECTADO]])) -> 25004643 | L24: 25004643 | M24: =+K24-L24 -> -0.37450741 | O24: =IF(ISBLANK(A24),"",R24-SUMIF(CATEGORIAS[[#All],[FORMATO GENERAL]], A24, CATEGORIAS[[#All],[COSTO REAL ANTERIOR]])) -> 0 | Q24: =+O24-P24 -> 0 | R24: =IF(ISBLANK(A24),"",SUMIF(CATEGORIAS[[#All],[FORMATO GENERAL]], A24, CATEGORIAS[[#All],[COSTO REAL]])) -> 0 | T24: =+R24-S24 -> 0 | U24: =IF(ISBLANK(A24),"",SUMIF(CATEGORIAS[[#All],[FORMATO GENERAL]], A24, CATEGORIAS[[#All],[TOTAL PRODUCCION ACTUAL]])) -> 0 | W24: =+U24-V24 -> 0 | X24: =IF(ISBLANK(A24),"",SUMIF(CATEGORIAS[[#All],[FORMATO GENERAL]], A24, CATEGORIAS[[#All],[PROYECCION TOTAL DE COSTO]])) -> 25004643 | Y24: 25004643 | Z24: =+X24-Y24 -> -0.37450741 | AB24: =IF(ISBLANK(A24),"",TRUNC(K24-R24-X24,2)) -> 0 | AD24: =+AB24-AC24 -> 0
A25: 0H02 | C25: Aislación Reembolsable | E25: =IF(ISBLANK(A25),"", SUMIF(CATEGORIAS[[#All],[FORMATO GENERAL]], A25, CATEGORIAS[[#All],[PRESUPUESTO (ORIGINAL)]])) -> 18524724 | F25: 18524724 | G25: =+E25-F25 -> 0.39 | H25: =IF(ISBLANK(A25),"",K25-E25) -> 0 | J25: =+H25-I25 -> 0 | K25: =IF(ISBLANK(A25),"",SUMIF(CATEGORIAS[[#All],[FORMATO GENERAL]], A25, CATEGORIAS[[#All],[PRESUPUESTO FINAL PROYECTADO]])) -> 18524724 | L25: 18524724 | M25: =+K25-L25 -> 0.39 | O25: =IF(ISBLANK(A25),"",R25-SUMIF(CATEGORIAS[[#All],[FORMATO GENERAL]], A25, CATEGORIAS[[#All],[COSTO REAL ANTERIOR]])) -> 0 | Q25: =+O25-P25 -> 0 | R25: =IF(ISBLANK(A25),"",SUMIF(CATEGORIAS[[#All],[FORMATO GENERAL]], A25, CATEGORIAS[[#All],[COSTO REAL]])) -> 0 | T25: =+R25-S25 -> 0 | U25: =IF(ISBLANK(A25),"",SUMIF(CATEGORIAS[[#All],[FORMATO GENERAL]], A25, CATEGORIAS[[#All],[TOTAL PRODUCCION ACTUAL]])) -> 15433050 | V25: 15433050 | W25: =+U25-V25 -> 0 | X25: =IF(ISBLANK(A25),"",SUMIF(CATEGORIAS[[#All],[FORMATO GENERAL]], A25, CATEGORIAS[[#All],[PROYECCION TOTAL DE COSTO]])) -> 18524724 | Y25: 18524724 | Z25: =+X25-Y25 -> 0.39 | AB25: =IF(ISBLANK(A25),"",TRUNC(K25-R25-X25,2)) -> 0 | AD25: =+AB25-AC25 -> 0
B26: A8 | C26: 08 - Caldera | E26: =IF(ISBLANK(A26),"", SUMIF(CATEGORIAS[[#All],[FORMATO GENERAL]], A26, CATEGORIAS[[#All],[PRESUPUESTO (ORIGINAL)]])) | G26: =+E26-F26 -> #VALUE! | H26: =IF(ISBLANK(A26),"",K26-E26) | J26: =+H26-I26 -> #VALUE! | K26: =IF(ISBLANK(A26),"",SUMIF(CATEGORIAS[[#All],[FORMATO GENERAL]], A26, CATEGORIAS[[#All],[PRESUPUESTO FINAL PROYECTADO]])) | M26: =+K26-L26 -> #VALUE! | O26: =IF(ISBLANK(A26),"",R26-SUMIF(CATEGORIAS[[#All],[FORMATO GENERAL]], A26, CATEGORIAS[[#All],[COSTO REAL ANTERIOR]])) | Q26: =+O26-P26 -> #VALUE! | R26: =IF(ISBLANK(A26),"",SUMIF(CATEGORIAS[[#All],[FORMATO GENERAL]], A26, CATEGORIAS[[#All],[COSTO REAL]])) | T26: =+R26-S26 -> #VALUE! | U26: =IF(ISBLANK(A26),"",SUMIF(CATEGORIAS[[#All],[FORMATO GENERAL]], A26, CATEGORIAS[[#All],[TOTAL PRODUCCION ACTUAL]])) | W26: =+U26-V26 -> #VALUE! | X26: =IF(ISBLANK(A26),"",SUMIF(CATEGORIAS[[#All],[FORMATO GENERAL]], A26, CATEGORIAS[[#All],[PROYECCION TOTAL DE COSTO]])) | Z26: =+X26-Y26 -> #VALUE! | AB26: =IF(ISBLANK(A26),"",TRUNC(K26-R26-X26,2)) | AD26: =+AB26-AC26 -> #VALUE!
A27: 0I01 | C27: Mano de Obra | E27: =IF(ISBLANK(A27),"", SUMIF(CATEGORIAS[[#All],[FORMATO GENERAL]], A27, CATEGORIAS[[#All],[PRESUPUESTO (ORIGINAL)]])) -> 0 | G27: =+E27-F27 -> 0 | H27: =IF(ISBLANK(A27),"",K27-E27) -> 0 | J27: =+H27-I27 -> 0 | K27: =IF(ISBLANK(A27),"",SUMIF(CATEGORIAS[[#All],[FORMATO GENERAL]], A27, CATEGORIAS[[#All],[PRESUPUESTO FINAL PROYECTADO]])) -> 0 | M27: =+K27-L27 -> 0 | O27: =IF(ISBLANK(A27),"",R27-SUMIF(CATEGORIAS[[#All],[FORMATO GENERAL]], A27, CATEGORIAS[[#All],[COSTO REAL ANTERIOR]])) -> 0 | Q27: =+O27-P27 -> 0 | R27: =IF(ISBLANK(A27),"",SUMIF(CATEGORIAS[[#All],[FORMATO GENERAL]], A27, CATEGORIAS[[#All],[COSTO REAL]])) -> 0 | T27: =+R27-S27 -> 0 | U27: =IF(ISBLANK(A27),"",SUMIF(CATEGORIAS[[#All],[FORMATO GENERAL]], A27, CATEGORIAS[[#All],[TOTAL PRODUCCION ACTUAL]])) -> 0 | W27: =+U27-V27 -> 0 | X27: =IF(ISBLANK(A27),"",SUMIF(CATEGORIAS[[#All],[FORMATO GENERAL]], A27, CATEGORIAS[[#All],[PROYECCION TOTAL DE COSTO]])) -> 0 | Z27: =+X27-Y27 -> 0 | AB27: =IF(ISBLANK(A27),"",TRUNC(K27-R27-X27,2)) -> 0 | AD27: =+AB27-AC27 -> 0
A28: 0I02 | C28: Caldera Reembolsable | E28: =IF(ISBLANK(A28),"", SUMIF(CATEGORIAS[[#All],[FORMATO GENERAL]], A28, CATEGORIAS[[#All],[PRESUPUESTO (ORIGINAL)]])) -> 0 | G28: =+E28-F28 -> 0 | H28: =IF(ISBLANK(A28),"",K28-E28) -> 0 | J28: =+H28-I28 -> 0 | K28: =IF(ISBLANK(A28),"",SUMIF(CATEGORIAS[[#All],[FORMATO GENERAL]], A28, CATEGORIAS[[#All],[PRESUPUESTO FINAL PROYECTADO]])) -> 0 | M28: =+K28-L28 -> 0 | O28: =IF(ISBLANK(A28),"",R28-SUMIF(CATEGORIAS[[#All],[FORMATO GENERAL]], A28, CATEGORIAS[[#All],[COSTO REAL ANTERIOR]])) -> 0 | Q28: =+O28-P28 -> 0 | R28: =IF(ISBLANK(A28),"",SUMIF(CATEGORIAS[[#All],[FORMATO GENERAL]], A28, CATEGORIAS[[#All],[COSTO REAL]])) -> 0 | T28: =+R28-S28 -> 0 | U28: =IF(ISBLANK(A28),"",SUMIF(CATEGORIAS[[#All],[FORMATO GENERAL]], A28, CATEGORIAS[[#All],[TOTAL PRODUCCION ACTUAL]])) -> 0 | W28: =+U28-V28 -> 0 | X28: =IF(ISBLANK(A28),"",SUMIF(CATEGORIAS[[#All],[FORMATO GENERAL]], A28, CATEGORIAS[[#All],[PROYECCION TOTAL DE COSTO]])) -> 0 | Z28: =+X28-Y28 -> 0 | AB28: =IF(ISBLANK(A28),"",TRUNC(K28-R28-X28,2)) -> 0 | AD28: =+AB28-AC28 -> 0
B29: A9 | C29: 09 - Ducto | E29: =IF(ISBLANK(A29),"", SUMIF(CATEGORIAS[[#All],[FORMATO GENERAL]], A29, CATEGORIAS[[#All],[PRESUPUESTO (ORIGINAL)]])) | G29: =+E29-F29 -> #VALUE! | H29: =IF(ISBLANK(A29),"",K29-E29) | J29: =+H29-I29 -> #VALUE! | K29: =IF(ISBLANK(A29),"",SUMIF(CATEGORIAS[[#All],[FORMATO GENERAL]], A29, CATEGORIAS[[#All],[PRESUPUESTO FINAL PROYECTADO]])) | M29: =+K29-L29 -> #VALUE! | O29: =IF(ISBLANK(A29),"",R29-SUMIF(CATEGORIAS[[#All],[FORMATO GENERAL]], A29, CATEGORIAS[[#All],[COSTO REAL ANTERIOR]])) | Q29: =+O29-P29 -> #VALUE! | R29: =IF(ISBLANK(A29),"",SUMIF(CATEGORIAS[[#All],[FORMATO GENERAL]], A29, CATEGORIAS[[#All],[COSTO REAL]])) | T29: =+R29-S29 -> #VALUE! | U29: =IF(ISBLANK(A29),"",SUMIF(CATEGORIAS[[#All],[FORMATO GENERAL]], A29, CATEGORIAS[[#All],[TOTAL PRODUCCION ACTUAL]])) | W29: =+U29-V29 -> #VALUE! | X29: =IF(ISBLANK(A29),"",SUMIF(CATEGORIAS[[#All],[FORMATO GENERAL]], A29, CATEGORIAS[[#All],[PROYECCION TOTAL DE COSTO]])) | Z29: =+X29-Y29 -> #VALUE! | AB29: =IF(ISBLANK(A29),"",TRUNC(K29-R29-X29,2)) | AD29: =+AB29-AC29 -> #VALUE!
A30: 0J01 | C30: Mano de Obra | E30: =IF(ISBLANK(A30),"", SUMIF(CATEGORIAS[[#All],[FORMATO GENERAL]], A30, CATEGORIAS[[#All],[PRESUPUESTO (ORIGINAL)]])) -> 0 | G30: =+E30-F30 -> 0 | H30: =IF(ISBLANK(A30),"",K30-E30) -> 0 | J30: =+H30-I30 -> 0 | K30: =IF(ISBLANK(A30),"",SUMIF(CATEGORIAS[[#All],[FORMATO GENERAL]], A30, CATEGORIAS[[#All],[PRESUPUESTO FINAL PROYECTADO]])) -> 0 | M30: =+K30-L30 -> 0 | O30: =IF(ISBLANK(A30),"",R30-SUMIF(CATEGORIAS[[#All],[FORMATO GENERAL]], A30, CATEGORIAS[[#All],[COSTO REAL ANTERIOR]])) -> 0 | Q30: =+O30-P30 -> 0 | R30: =IF(ISBLANK(A30),"",SUMIF(CATEGORIAS[[#All],[FORMATO GENERAL]], A30, CATEGORIAS[[#All],[COSTO REAL]])) -> 0 | T30: =+R30-S30 -> 0 | U30: =IF(ISBLANK(A30),"",SUMIF(CATEGORIAS[[#All],[FORMATO GENERAL]], A30, CATEGORIAS[[#All],[TOTAL PRODUCCION ACTUAL]])) -> 0 | W30: =+U30-V30 -> 0 | X30: =IF(ISBLANK(A30),"",SUMIF(CATEGORIAS[[#All],[FORMATO GENERAL]], A30, CATEGORIAS[[#All],[PROYECCION TOTAL DE COSTO]])) -> 0 | Z30: =+X30-Y30 -> 0 | AB30: =IF(ISBLANK(A30),"",TRUNC(K30-R30-X30,2)) -> 0 | AD30: =+AB30-AC30 -> 0
A31: 0J02 | C31: Ducto Reembolsable | E31: =IF(ISBLANK(A31),"", SUMIF(CATEGORIAS[[#All],[FORMATO GENERAL]], A31, CATEGORIAS[[#All],[PRESUPUESTO (ORIGINAL)]])) -> 0 | G31: =+E31-F31 -> 0 | H31: =IF(ISBLANK(A31),"",K31-E31) -> 0 | J31: =+H31-I31 -> 0 | K31: =IF(ISBLANK(A31),"",SUMIF(CATEGORIAS[[#All],[FORMATO GENERAL]], A31, CATEGORIAS[[#All],[PRESUPUESTO FINAL PROYECTADO]])) -> 0 | M31: =+K31-L31 -> 0 | O31: =IF(ISBLANK(A31),"",R31-SUMIF(CATEGORIAS[[#All],[FORMATO GENERAL]], A31, CATEGORIAS[[#All],[COSTO REAL ANTERIOR]])) -> 0 | Q31: =+O31-P31 -> 0 | R31: =IF(ISBLANK(A31),"",SUMIF(CATEGORIAS[[#All],[FORMATO GENERAL]], A31, CATEGORIAS[[#All],[COSTO REAL]])) -> 0 | T31: =+R31-S31 -> 0 | U31: =IF(ISBLANK(A31),"",SUMIF(CATEGORIAS[[#All],[FORMATO GENERAL]], A31, CATEGORIAS[[#All],[TOTAL PRODUCCION ACTUAL]])) -> 0 | W31: =+U31-V31 -> 0 | X31: =IF(ISBLANK(A31),"",SUMIF(CATEGORIAS[[#All],[FORMATO GENERAL]], A31, CATEGORIAS[[#All],[PROYECCION TOTAL DE COSTO]])) -> 0 | Z31: =+X31-Y31 -> 0 | AB31: =IF(ISBLANK(A31),"",TRUNC(K31-R31-X31,2)) -> 0 | AD31: =+AB31-AC31 -> 0
B32: A10 | C32: 10 - Comisionamiento - PEM | E32: =IF(ISBLANK(A32),"", SUMIF(CATEGORIAS[[#All],[FORMATO GENERAL]], A32, CATEGORIAS[[#All],[PRESUPUESTO (ORIGINAL)]])) | G32: =+E32-F32 -> #VALUE! | H32: =IF(ISBLANK(A32),"",K32-E32) | J32: =+H32-I32 -> #VALUE! | K32: =IF(ISBLANK(A32),"",SUMIF(CATEGORIAS[[#All],[FORMATO GENERAL]], A32, CATEGORIAS[[#All],[PRESUPUESTO FINAL PROYECTADO]])) | M32: =+K32-L32 -> #VALUE! | O32: =IF(ISBLANK(A32),"",R32-SUMIF(CATEGORIAS[[#All],[FORMATO GENERAL]], A32, CATEGORIAS[[#All],[COSTO REAL ANTERIOR]])) | Q32: =+O32-P32 -> #VALUE! | R32: =IF(ISBLANK(A32),"",SUMIF(CATEGORIAS[[#All],[FORMATO GENERAL]], A32, CATEGORIAS[[#All],[COSTO REAL]])) | T32: =+R32-S32 -> #VALUE! | U32: =IF(ISBLANK(A32),"",SUMIF(CATEGORIAS[[#All],[FORMATO GENERAL]], A32, CATEGORIAS[[#All],[TOTAL PRODUCCION ACTUAL]])) | W32: =+U32-V32 -> #VALUE! | X32: =IF(ISBLANK(A32),"",SUMIF(CATEGORIAS[[#All],[FORMATO GENERAL]], A32, CATEGORIAS[[#All],[PROYECCION TOTAL DE COSTO]])) | Z32: =+X32-Y32 -> #VALUE! | AB32: =IF(ISBLANK(A32),"",TRUNC(K32-R32-X32,2)) | AD32: =+AB32-AC32 -> #VALUE!
A33: 0L01 | C33: Mano de Obra | E33: =IF(ISBLANK(A33),"", SUMIF(CATEGORIAS[[#All],[FORMATO GENERAL]], A33, CATEGORIAS[[#All],[PRESUPUESTO (ORIGINAL)]])) -> 0 | G33: =+E33-F33 -> 0 | H33: =IF(ISBLANK(A33),"",K33-E33) -> 0 | J33: =+H33-I33 -> 0 | K33: =IF(ISBLANK(A33),"",SUMIF(CATEGORIAS[[#All],[FORMATO GENERAL]], A33, CATEGORIAS[[#All],[PRESUPUESTO FINAL PROYECTADO]])) -> 0 | M33: =+K33-L33 -> 0 | O33: =IF(ISBLANK(A33),"",R33-SUMIF(CATEGORIAS[[#All],[FORMATO GENERAL]], A33, CATEGORIAS[[#All],[COSTO REAL ANTERIOR]])) -> 0 | Q33: =+O33-P33 -> 0 | R33: =IF(ISBLANK(A33),"",SUMIF(CATEGORIAS[[#All],[FORMATO GENERAL]], A33, CATEGORIAS[[#All],[COSTO REAL]])) -> 0 | T33: =+R33-S33 -> 0 | U33: =IF(ISBLANK(A33),"",SUMIF(CATEGORIAS[[#All],[FORMATO GENERAL]], A33, CATEGORIAS[[#All],[TOTAL PRODUCCION ACTUAL]])) -> 0 | W33: =+U33-V33 -> 0 | X33: =IF(ISBLANK(A33),"",SUMIF(CATEGORIAS[[#All],[FORMATO GENERAL]], A33, CATEGORIAS[[#All],[PROYECCION TOTAL DE COSTO]])) -> 0 | Z33: =+X33-Y33 -> 0 | AB33: =IF(ISBLANK(A33),"",TRUNC(K33-R33-X33,2)) -> 0 | AD33: =+AB33-AC33 -> 0
B34: A11 | C34: 11 - Arquitectura | E34: =IF(ISBLANK(A34),"", SUMIF(CATEGORIAS[[#All],[FORMATO GENERAL]], A34, CATEGORIAS[[#All],[PRESUPUESTO (ORIGINAL)]])) | G34: =+E34-F34 -> #VALUE! | H34: =IF(ISBLANK(A34),"",K34-E34) | J34: =+H34-I34 -> #VALUE! | K34: =IF(ISBLANK(A34),"",SUMIF(CATEGORIAS[[#All],[FORMATO GENERAL]], A34, CATEGORIAS[[#All],[PRESUPUESTO FINAL PROYECTADO]])) | M34: =+K34-L34 -> #VALUE! | O34: =IF(ISBLANK(A34),"",R34-SUMIF(CATEGORIAS[[#All],[FORMATO GENERAL]], A34, CATEGORIAS[[#All],[COSTO REAL ANTERIOR]])) | Q34: =+O34-P34 -> #VALUE! | R34: =IF(ISBLANK(A34),"",SUMIF(CATEGORIAS[[#All],[FORMATO GENERAL]], A34, CATEGORIAS[[#All],[COSTO REAL]])) | T34: =+R34-S34 -> #VALUE! | U34: =IF(ISBLANK(A34),"",SUMIF(CATEGORIAS[[#All],[FORMATO GENERAL]], A34, CATEGORIAS[[#All],[TOTAL PRODUCCION ACTUAL]])) | W34: =+U34-V34 -> #VALUE! | X34: =IF(ISBLANK(A34),"",SUMIF(CATEGORIAS[[#All],[FORMATO GENERAL]], A34, CATEGORIAS[[#All],[PROYECCION TOTAL DE COSTO]])) | Z34: =+X34-Y34 -> #VALUE! | AB34: =IF(ISBLANK(A34),"",TRUNC(K34-R34-X34,2)) | AD34: =+AB34-AC34 -> #VALUE!
A35: 0M01 | C35: Mano de Obra | E35: =IF(ISBLANK(A35),"", SUMIF(CATEGORIAS[[#All],[FORMATO GENERAL]], A35, CATEGORIAS[[#All],[PRESUPUESTO (ORIGINAL)]])) -> 0 | G35: =+E35-F35 -> 0 | H35: =IF(ISBLANK(A35),"",K35-E35) -> 0 | J35: =+H35-I35 -> 0 | K35: =IF(ISBLANK(A35),"",SUMIF(CATEGORIAS[[#All],[FORMATO GENERAL]], A35, CATEGORIAS[[#All],[PRESUPUESTO FINAL PROYECTADO]])) -> 0 | M35: =+K35-L35 -> 0 | O35: =IF(ISBLANK(A35),"",R35-SUMIF(CATEGORIAS[[#All],[FORMATO GENERAL]], A35, CATEGORIAS[[#All],[COSTO REAL ANTERIOR]])) -> 2325389 | P35: 2325389 | Q35: =+O35-P35 -> 0.025389026 | R35: =IF(ISBLANK(A35),"",SUMIF(CATEGORIAS[[#All],[FORMATO GENERAL]], A35, CATEGORIAS[[#All],[COSTO REAL]])) -> 2325389 | S35: 2325389 | T35: =+R35-S35 -> 0.025389026 | U35: =IF(ISBLANK(A35),"",SUMIF(CATEGORIAS[[#All],[FORMATO GENERAL]], A35, CATEGORIAS[[#All],[TOTAL PRODUCCION ACTUAL]])) -> 0 | W35: =+U35-V35 -> 0 | X35: =IF(ISBLANK(A35),"",SUMIF(CATEGORIAS[[#All],[FORMATO GENERAL]], A35, CATEGORIAS[[#All],[PROYECCION TOTAL DE COSTO]])) -> 0 | Z35: =+X35-Y35 -> 0 | AB35: =IF(ISBLANK(A35),"",TRUNC(K35-R35-X35,2)) -> -2325389 | AC35: -2325389 | AD35: =+AB35-AC35 -> -0.02
A36: 0M02 | C36: Arquitectura Reembolsable | E36: =IF(ISBLANK(A36),"", SUMIF(CATEGORIAS[[#All],[FORMATO GENERAL]], A36, CATEGORIAS[[#All],[PRESUPUESTO (ORIGINAL)]])) -> 0 | G36: =+E36-F36 -> 0 | H36: =IF(ISBLANK(A36),"",K36-E36) -> 0 | J36: =+H36-I36 -> 0 | K36: =IF(ISBLANK(A36),"",SUMIF(CATEGORIAS[[#All],[FORMATO GENERAL]], A36, CATEGORIAS[[#All],[PRESUPUESTO FINAL PROYECTADO]])) -> 0 | M36: =+K36-L36 -> 0 | O36: =IF(ISBLANK(A36),"",R36-SUMIF(CATEGORIAS[[#All],[FORMATO GENERAL]], A36, CATEGORIAS[[#All],[COSTO REAL ANTERIOR]])) -> 0 | Q36: =+O36-P36 -> 0 | R36: =IF(ISBLANK(A36),"",SUMIF(CATEGORIAS[[#All],[FORMATO GENERAL]], A36, CATEGORIAS[[#All],[COSTO REAL]])) -> 0 | T36: =+R36-S36 -> 0 | U36: =IF(ISBLANK(A36),"",SUMIF(CATEGORIAS[[#All],[FORMATO GENERAL]], A36, CATEGORIAS[[#All],[TOTAL PRODUCCION ACTUAL]])) -> 0 | W36: =+U36-V36 -> 0 | X36: =IF(ISBLANK(A36),"",SUMIF(CATEGORIAS[[#All],[FORMATO GENERAL]], A36, CATEGORIAS[[#All],[PROYECCION TOTAL DE COSTO]])) -> 0 | Z36: =+X36-Y36 -> 0 | AB36: =IF(ISBLANK(A36),"",TRUNC(K36-R36-X36,2)) -> 0 | AD36: =+AB36-AC36 -> 0
B37: A12 | C37: 12 - Estanque | E37: =IF(ISBLANK(A37),"", SUMIF(CATEGORIAS[[#All],[FORMATO GENERAL]], A37, CATEGORIAS[[#All],[PRESUPUESTO (ORIGINAL)]])) | G37: =+E37-F37 -> #VALUE! | H37: =IF(ISBLANK(A37),"",K37-E37) | J37: =+H37-I37 -> #VALUE! | K37: =IF(ISBLANK(A37),"",SUMIF(CATEGORIAS[[#All],[FORMATO GENERAL]], A37, CATEGORIAS[[#All],[PRESUPUESTO FINAL PROYECTADO]])) | M37: =+K37-L37 -> #VALUE! | O37: =IF(ISBLANK(A37),"",R37-SUMIF(CATEGORIAS[[#All],[FORMATO GENERAL]], A37, CATEGORIAS[[#All],[COSTO REAL ANTERIOR]])) | Q37: =+O37-P37 -> #VALUE! | R37: =IF(ISBLANK(A37),"",SUMIF(CATEGORIAS[[#All],[FORMATO GENERAL]], A37, CATEGORIAS[[#All],[COSTO REAL]])) | T37: =+R37-S37 -> #VALUE! | U37: =IF(ISBLANK(A37),"",SUMIF(CATEGORIAS[[#All],[FORMATO GENERAL]], A37, CATEGORIAS[[#All],[TOTAL PRODUCCION ACTUAL]])) | W37: =+U37-V37 -> #VALUE! | X37: =IF(ISBLANK(A37),"",SUMIF(CATEGORIAS[[#All],[FORMATO GENERAL]], A37, CATEGORIAS[[#All],[PROYECCION TOTAL DE COSTO]])) | Z37: =+X37-Y37 -> #VALUE! | AB37: =IF(ISBLANK(A37),"",TRUNC(K37-R37-X37,2)) | AD37: =+AB37-AC37 -> #VALUE!
A38: 0N01 | C38: Mano de Obra | E38: =IF(ISBLANK(A38),"", SUMIF(CATEGORIAS[[#All],[FORMATO GENERAL]], A38, CATEGORIAS[[#All],[PRESUPUESTO (ORIGINAL)]])) -> 0 | G38: =+E38-F38 -> 0 | H38: =IF(ISBLANK(A38),"",K38-E38) -> 0 | J38: =+H38-I38 -> 0 | K38: =IF(ISBLANK(A38),"",SUMIF(CATEGORIAS[[#All],[FORMATO GENERAL]], A38, CATEGORIAS[[#All],[PRESUPUESTO FINAL PROYECTADO]])) -> 0 | M38: =+K38-L38 -> 0 | O38: =IF(ISBLANK(A38),"",R38-SUMIF(CATEGORIAS[[#All],[FORMATO GENERAL]], A38, CATEGORIAS[[#All],[COSTO REAL ANTERIOR]])) -> 0 | Q38: =+O38-P38 -> 0 | R38: =IF(ISBLANK(A38),"",SUMIF(CATEGORIAS[[#All],[FORMATO GENERAL]], A38, CATEGORIAS[[#All],[COSTO REAL]])) -> 0 | T38: =+R38-S38 -> 0 | U38: =IF(ISBLANK(A38),"",SUMIF(CATEGORIAS[[#All],[FORMATO GENERAL]], A38, CATEGORIAS[[#All],[TOTAL PRODUCCION ACTUAL]])) -> 0 | W38: =+U38-V38 -> 0 | X38: =IF(ISBLANK(A38),"",SUMIF(CATEGORIAS[[#All],[FORMATO GENERAL]], A38, CATEGORIAS[[#All],[PROYECCION TOTAL DE COSTO]])) -> 0 | Z38: =+X38-Y38 -> 0 | AB38: =IF(ISBLANK(A38),"",TRUNC(K38-R38-X38,2)) -> 0 | AD38: =+AB38-AC38 -> 0
A39: 0N02 | C39: Estanque Reembolsable | E39: =IF(ISBLANK(A39),"", SUMIF(CATEGORIAS[[#All],[FORMATO GENERAL]], A39, CATEGORIAS[[#All],[PRESUPUESTO (ORIGINAL)]])) -> 0 | G39: =+E39-F39 -> 0 | H39: =IF(ISBLANK(A39),"",K39-E39) -> 0 | J39: =+H39-I39 -> 0 | K39: =IF(ISBLANK(A39),"",SUMIF(CATEGORIAS[[#All],[FORMATO GENERAL]], A39, CATEGORIAS[[#All],[PRESUPUESTO FINAL PROYECTADO]])) -> 0 | M39: =+K39-L39 -> 0 | O39: =IF(ISBLANK(A39),"",R39-SUMIF(CATEGORIAS[[#All],[FORMATO GENERAL]], A39, CATEGORIAS[[#All],[COSTO REAL ANTERIOR]])) -> 0 | Q39: =+O39-P39 -> 0 | R39: =IF(ISBLANK(A39),"",SUMIF(CATEGORIAS[[#All],[FORMATO GENERAL]], A39, CATEGORIAS[[#All],[COSTO REAL]])) -> 0 | T39: =+R39-S39 -> 0 | U39: =IF(ISBLANK(A39),"",SUMIF(CATEGORIAS[[#All],[FORMATO GENERAL]], A39, CATEGORIAS[[#All],[TOTAL PRODUCCION ACTUAL]])) -> 0 | W39: =+U39-V39 -> 0 | X39: =IF(ISBLANK(A39),"",SUMIF(CATEGORIAS[[#All],[FORMATO GENERAL]], A39, CATEGORIAS[[#All],[PROYECCION TOTAL DE COSTO]])) -> 0 | Z39: =+X39-Y39 -> 0 | AB39: =IF(ISBLANK(A39),"",TRUNC(K39-R39-X39,2)) -> 0 | AD39: =+AB39-AC39 -> 0
B40: A13 | C40: Costo Proporcional HH | E40: =IF(ISBLANK(A40),"", SUMIF(CATEGORIAS[[#All],[FORMATO GENERAL]], A40, CATEGORIAS[[#All],[PRESUPUESTO (ORIGINAL)]])) | G40: =+E40-F40 -> #VALUE! | H40: =IF(ISBLANK(A40),"",K40-E40) | J40: =+H40-I40 -> #VALUE! | K40: =IF(ISBLANK(A40),"",SUMIF(CATEGORIAS[[#All],[FORMATO GENERAL]], A40, CATEGORIAS[[#All],[PRESUPUESTO FINAL PROYECTADO]])) | M40: =+K40-L40 -> #VALUE! | O40: =IF(ISBLANK(A40),"",R40-SUMIF(CATEGORIAS[[#All],[FORMATO GENERAL]], A40, CATEGORIAS[[#All],[COSTO REAL ANTERIOR]])) | Q40: =+O40-P40 -> #VALUE! | R40: =IF(ISBLANK(A40),"",SUMIF(CATEGORIAS[[#All],[FORMATO GENERAL]], A40, CATEGORIAS[[#All],[COSTO REAL]])) | T40: =+R40-S40 -> #VALUE! | U40: =IF(ISBLANK(A40),"",SUMIF(CATEGORIAS[[#All],[FORMATO GENERAL]], A40, CATEGORIAS[[#All],[TOTAL PRODUCCION ACTUAL]])) | W40: =+U40-V40 -> #VALUE! | X40: =IF(ISBLANK(A40),"",SUMIF(CATEGORIAS[[#All],[FORMATO GENERAL]], A40, CATEGORIAS[[#All],[PROYECCION TOTAL DE COSTO]])) | Z40: =+X40-Y40 -> #VALUE! | AB40: =IF(ISBLANK(A40),"",TRUNC(K40-R40-X40,2)) | AD40: =+AB40-AC40 -> #VALUE!
A41: 0P01 | C41: Movilización | E41: =IF(ISBLANK(A41),"", SUMIF(CATEGORIAS[[#All],[FORMATO GENERAL]], A41, CATEGORIAS[[#All],[PRESUPUESTO (ORIGINAL)]])) -> 91680058 | F41: 91680058 | G41: =+E41-F41 -> 0.29098517 | H41: =IF(ISBLANK(A41),"",K41-E41) -> 5566468 | I41: 5566468 | J41: =+H41-I41 -> -0.042836323 | K41: =IF(ISBLANK(A41),"",SUMIF(CATEGORIAS[[#All],[FORMATO GENERAL]], A41, CATEGORIAS[[#All],[PRESUPUESTO FINAL PROYECTADO]])) -> 97246526 | L41: 97246526 | M41: =+K41-L41 -> 0.24814884 | O41: =IF(ISBLANK(A41),"",R41-SUMIF(CATEGORIAS[[#All],[FORMATO GENERAL]], A41, CATEGORIAS[[#All],[COSTO REAL ANTERIOR]])) -> 0 | Q41: =+O41-P41 -> 0 | R41: =IF(ISBLANK(A41),"",SUMIF(CATEGORIAS[[#All],[FORMATO GENERAL]], A41, CATEGORIAS[[#All],[COSTO REAL]])) -> 14593364 | S41: 14593364 | T41: =+R41-S41 -> -0.2 | U41: =IF(ISBLANK(A41),"",SUMIF(CATEGORIAS[[#All],[FORMATO GENERAL]], A41, CATEGORIAS[[#All],[TOTAL PRODUCCION ACTUAL]])) -> 33939880 | V41: 33939880 | W41: =+U41-V41 -> 0.11119501 | X41: =IF(ISBLANK(A41),"",SUMIF(CATEGORIAS[[#All],[FORMATO GENERAL]], A41, CATEGORIAS[[#All],[PROYECCION TOTAL DE COSTO]])) -> 82653162 | Y41: 82653162 | Z41: =+X41-Y41 -> 0.44814885 | AB41: =IF(ISBLANK(A41),"",TRUNC(K41-R41-X41,2)) -> 0 | AD41: =+AB41-AC41 -> 0
...

Sheet Analisis por Categorias
E1: ERROR DE PRODUCCION - ADICIONALES | G1: 4 | H1: 5 | I1: 6 | L1: 7 | M1: 8 | N1: 9 | O1: 10 | P1: 11 | Q1: 12 | R1: 13 | S1: 14 | T1: 15 | U1: 16 | V1: 17 | W1: 18 | X1: 19 | Y1: 20 | Z1: 21 | AA1: 22 | AB1: 23 | AC1: 24 | AD1: 25 | AE1: 26
E2: ERROR DE PRODUCCION - ADICIONALES | G2: =SUBTOTAL(9,CATEGORIAS[PRESUPUESTO (ORIGINAL)]) -> 5.309817e+09 | H2: =SUBTOTAL(9,CATEGORIAS[POM]) -> 5.309817e+09 | I2: =SUBTOTAL(9,CATEGORIAS[ADICIONALES]) -> 2.0510054e+08 | L2: =SUBTOTAL(9,CATEGORIAS[PRESUPUESTO FINAL PROYECTADO]) -> 5.5149175e+09 | M2: =SUBTOTAL(9,CATEGORIAS[PRODUCCION PARTIDAS ORIGINALES ACTUAL]) -> 2.2581711e+09 | N2: =SUBTOTAL(9,CATEGORIAS[PRODUCCION ADICIONALES ACTUAL]) -> 14538275 | O2: =SUBTOTAL(9,CATEGORIAS[TOTAL PRODUCCION ACTUAL]) -> 2.2727094e+09 | P2: =SUBTOTAL(9,CATEGORIAS[PRODUCCION ANTERIOR]) -> 1.5184201e+09 | Q2: =SUBTOTAL(9,CATEGORIAS[PRODUCCION ADICIONALES ANTERIOR]) -> 14927094 | R2: =SUBTOTAL(9,CATEGORIAS[TOTAL PRODUCCION ANTERIOR]) -> 1.5333472e+09 | S2: =SUBTOTAL(9,CATEGORIAS[COSTO ACUMULADO AX]) -> 1.9279227e+09 | T2: =SUM(CATEGORIAS[CAMBIO DE CATEGORIA]) -> -0.3288 | U2: =SUBTOTAL(9,CATEGORIAS[PROVISIONES]) -> 5.3967687e+08 | V2: =SUBTOTAL(9,CATEGORIAS[COSTO REAL]) -> 2.4675996e+09 | W2: =SUBTOTAL(9,CATEGORIAS[COSTO ACUMULADO ANTERIOR]) -> 1.2145999e+09 | X2: =SUBTOTAL(9,CATEGORIAS[CAMBIO DE CATEGORIA ANTERIOR]) -> -0.30211412 | Y2: =SUBTOTAL(9,CATEGORIAS[PROVISIONES ANTERIOR]) -> 3.3224083e+08 | Z2: =SUBTOTAL(9,CATEGORIAS[COSTO REAL ANTERIOR]) -> 1.5468407e+09 | AA2: =SUBTOTAL(9,CATEGORIAS[PROYECCION DE INGRESO DEL SALDO]) -> 3.2422081e+09 | AB2: =SUBTOTAL(9,CATEGORIAS[INVENTARIO]) -> 219920096 | AC2: =SUBTOTAL(9,CATEGORIAS[PEDIDOS DE COMPRA NO RECIBIDOS]) -> 0 | AD2: =SUBTOTAL(9,CATEGORIAS[PROYECCION DE COSTO DEL SALDO]) -> 2.8297232e+09 | AE2: =SUBTOTAL(9,CATEGORIAS[PROYECCION TOTAL DE COSTO]) -> 3.0496433e+09
E3: ERROR DE COSTO - CAMBIO CATEGORIA - PROVISION | M3: PRODUCCION | S3: COSTOS | AA3: PROYECCION
E4: ERROR DE PROYECCION - INVENTARIO | M4: ACUMULADA | P4: ACUMULADA ANTERIOR | S4: ACUMULADO | W4: ACUMULADO ANTERIOR | AA4: PRODUCCION | AB4: COSTOS
G5: CARGA MANUAL | H5: CARGA MANUAL | I5: CARGA MANUAL | L5: FORMULA | M5: CARGA MANUAL | N5: CARGA MANUAL | O5: FORMULA | P5: CARGA MANUAL | Q5: CARGA MANUAL | R5: FORMULA | S5: DESDE AX | T5: CARGA MANUAL | U5: CARGA MANUAL | V5: FORMULA | W5: CARGA MANUAL | X5: CARGA MANUAL | Y5: CARGA MANUAL | Z5: FORMULA | AA5: FORMULA | AB5: DESDE AX | AC5: DESDE AX | AD5: CARGA MANUAL | AE5: FORMULA
A6: FORMATO GENERAL | B6: SUBGRUPO | C6: NOMBRE SUBGRUPO | D6: CATEGORIA2 | E6: NOMBRE CATEGORIA | F6: INCLUIR | G6: PRESUPUESTO (ORIGINAL) | H6: POM | I6: ADICIONALES | J6: REAJUSTE PAGADO | K6: REAJUSTE PROYECTADO | L6: PRESUPUESTO FINAL PROYECTADO | M6: PRODUCCION PARTIDAS ORIGINALES ACTUAL | N6: PRODUCCION ADICIONALES ACTUAL | O6: TOTAL PRODUCCION ACTUAL | P6: PRODUCCION ANTERIOR | Q6: PRODUCCION ADICIONALES ANTERIOR | R6: TOTAL PRODUCCION ANTERIOR | S6: COSTO ACUMULADO AX | T6: CAMBIO DE CATEGORIA | U6: PROVISIONES | V6: COSTO REAL | W6: COSTO ACUMULADO ANTERIOR | X6: CAMBIO DE CATEGORIA ANTERIOR | Y6: PROVISIONES ANTERIOR | Z6: COSTO REAL ANTERIOR | AA6: PROYECCION DE INGRESO DEL SALDO | AB6: INVENTARIO | AC6: PEDIDOS DE COMPRA NO RECIBIDOS | AD6: PROYECCION DE COSTO DEL SALDO | AE6: PROYECCION TOTAL DE COSTO | AF6: ITEM | AG6: Columna1
A7: =+IFERROR(VLOOKUP(CATEGORIAS[[#This Row],[CATEGORIA2]],[1]HOMOLOGACION!$A$1:$I$571,9,FALSE),0) -> 0 | B7: =+IFERROR(VLOOKUP(CATEGORIAS[[#This Row],[CATEGORIA2]],[1]HOMOLOGACION!$A$1:$C$571,3,FALSE),0) -> 0 | C7: =+IFERROR(VLOOKUP(CATEGORIAS[[#This Row],[CATEGORIA2]],[1]HOMOLOGACION!$A$1:$D$571,4,FALSE),0) -> 0 | D7: 10-0000-000G | E7: MAO / Por Distribuir (G) | F7: NO | G7: 0 | H7: 0 | L7: =CATEGORIAS[[#This Row],[ADICIONALES]]+CATEGORIAS[[#This Row],[POM]] -> 0 | M7: 0 | N7: 0 | O7: =+CATEGORIAS[[#This Row],[PRODUCCION PARTIDAS ORIGINALES ACTUAL]]+CATEGORIAS[[#This Row],[PRODUCCION ADICIONALES ACTUAL]] -> 0 | R7: =CATEGORIAS[[#This Row],[PRODUCCION ANTERIOR]]+CATEGORIAS[[#This Row],[PRODUCCION ADICIONALES ANTERIOR]] -> 0 | S7: 0 | V7: =SUM(CATEGORIAS[[#This Row],[COSTO ACUMULADO AX]:[PROVISIONES]]) -> 0 | Z7: =SUM(CATEGORIAS[[#This Row],[COSTO ACUMULADO ANTERIOR]:[PROVISIONES ANTERIOR]]) -> 0 | AA7: =CATEGORIAS[[#This Row],[PRESUPUESTO FINAL PROYECTADO]]-CATEGORIAS[[#This Row],[TOTAL PRODUCCION ACTUAL]] -> 0 | AB7: 0 | AE7: =SUM(CATEGORIAS[[#This Row],[INVENTARIO]:[PROYECCION DE COSTO DEL SALDO]]) -> 0 | AG7: =+CATEGORIAS[[#This Row],[PRESUPUESTO FINAL PROYECTADO]]-CATEGORIAS[[#This Row],[COSTO REAL]]-CATEGORIAS[[#This Row],[PROYECCION TOTAL DE COSTO]] -> 0
A8: =+IFERROR(VLOOKUP(CATEGORIAS[[#This Row],[CATEGORIA2]],[1]HOMOLOGACION!$A$1:$I$571,9,FALSE),0) -> 0A01 | B8: =+IFERROR(VLOOKUP(CATEGORIAS[[#This Row],[CATEGORIA2]],[1]HOMOLOGACION!$A$1:$C$571,3,FALSE),0) -> 0A01 | C8: =+IFERROR(VLOOKUP(CATEGORIAS[[#This Row],[CATEGORIA2]],[1]HOMOLOGACION!$A$1:$D$571,4,FALSE),0) -> Civil | D8: 11-0101-000G | E8: MAO CD - Civil / Movimiento de tierra (G) | F8: NO | G8: 0 | H8: 0 | L8: =CATEGORIAS[[#This Row],[ADICIONALES]]+CATEGORIAS[[#This Row],[POM]] -> 0 | M8: 0 | N8: 0 | O8: =CATEGORIAS[[#This Row],[PRODUCCION PARTIDAS ORIGINALES ACTUAL]]+CATEGORIAS[[#This Row],[PRODUCCION ADICIONALES ACTUAL]] -> 0 | R8: =CATEGORIAS[[#This Row],[PRODUCCION ANTERIOR]]+CATEGORIAS[[#This Row],[PRODUCCION ADICIONALES ANTERIOR]] -> 0 | S8: 0 | V8: =SUM(CATEGORIAS[[#This Row],[COSTO ACUMULADO AX]:[PROVISIONES]]) -> 0 | Z8: =SUM(CATEGORIAS[[#This Row],[COSTO ACUMULADO ANTERIOR]:[PROVISIONES ANTERIOR]]) -> 0 | AA8: =CATEGORIAS[[#This Row],[PRESUPUESTO FINAL PROYECTADO]]-CATEGORIAS[[#This Row],[TOTAL PRODUCCION ACTUAL]] -> 0 | AB8: 0 | AE8: =SUM(CATEGORIAS[[#This Row],[INVENTARIO]:[PROYECCION DE COSTO DEL SALDO]]) -> 0 | AG8: =+CATEGORIAS[[#This Row],[PRESUPUESTO FINAL PROYECTADO]]-CATEGORIAS[[#This Row],[COSTO REAL]]-CATEGORIAS[[#This Row],[PROYECCION TOTAL DE COSTO]] -> 0
A9: =+IFERROR(VLOOKUP(CATEGORIAS[[#This Row],[CATEGORIA2]],[1]HOMOLOGACION!$A$1:$I$571,9,FALSE),0) -> 0A01 | B9: =+IFERROR(VLOOKUP(CATEGORIAS[[#This Row],[CATEGORIA2]],[1]HOMOLOGACION!$A$1:$C$571,3,FALSE),0) -> 0A01 | C9: =+IFERROR(VLOOKUP(CATEGORIAS[[#This Row],[CATEGORIA2]],[1]HOMOLOGACION!$A$1:$D$571,4,FALSE),0) -> Civil | D9: 11-0102-000G | E9: MAO CD - Civil / Hormigón (G) | F9: NO | G9: 0 | H9: 0 | L9: =CATEGORIAS[[#This Row],[ADICIONALES]]+CATEGORIAS[[#This Row],[POM]] -> 0 | M9: 0 | N9: 0 | O9: =CATEGORIAS[[#This Row],[PRODUCCION PARTIDAS ORIGINALES ACTUAL]]+CATEGORIAS[[#This Row],[PRODUCCION ADICIONALES ACTUAL]] -> 0 | R9: =CATEGORIAS[[#This Row],[PRODUCCION ANTERIOR]]+CATEGORIAS[[#This Row],[PRODUCCION ADICIONALES ANTERIOR]] -> 0 | S9: 0 | V9: =SUM(CATEGORIAS[[#This Row],[COSTO ACUMULADO AX]:[PROVISIONES]]) -> 0 | Z9: =SUM(CATEGORIAS[[#This Row],[COSTO ACUMULADO ANTERIOR]:[PROVISIONES ANTERIOR]]) -> 0 | AA9: =CATEGORIAS[[#This Row],[PRESUPUESTO FINAL PROYECTADO]]-CATEGORIAS[[#This Row],[TOTAL PRODUCCION ACTUAL]] -> 0 | AB9: 0 | AE9: =SUM(CATEGORIAS[[#This Row],[INVENTARIO]:[PROYECCION DE COSTO DEL SALDO]]) -> 0 | AG9: =+CATEGORIAS[[#This Row],[PRESUPUESTO FINAL PROYECTADO]]-CATEGORIAS[[#This Row],[COSTO REAL]]-CATEGORIAS[[#This Row],[PROYECCION TOTAL DE COSTO]] -> 0
A10: =+IFERROR(VLOOKUP(CATEGORIAS[[#This Row],[CATEGORIA2]],[1]HOMOLOGACION!$A$1:$I$571,9,FALSE),0) -> 0A01 | B10: =+IFERROR(VLOOKUP(CATEGORIAS[[#This Row],[CATEGORIA2]],[1]HOMOLOGACION!$A$1:$C$571,3,FALSE),0) -> 0A01 | C10: =+IFERROR(VLOOKUP(CATEGORIAS[[#This Row],[CATEGORIA2]],[1]HOMOLOGACION!$A$1:$D$571,4,FALSE),0) -> Civil | D10: 11-0103-000G | E10: MAO CD - Civil / Moldaje (G) | F10: NO | G10: 0 | H10: 0 | L10: =CATEGORIAS[[#This Row],[ADICIONALES]]+CATEGORIAS[[#This Row],[POM]] -> 0 | M10: 0 | N10: 0 | O10: =CATEGORIAS[[#This Row],[PRODUCCION PARTIDAS ORIGINALES ACTUAL]]+CATEGORIAS[[#This Row],[PRODUCCION ADICIONALES ACTUAL]] -> 0 | R10: =CATEGORIAS[[#This Row],[PRODUCCION ANTERIOR]]+CATEGORIAS[[#This Row],[PRODUCCION ADICIONALES ANTERIOR]] -> 0 | S10: 0 | V10: =SUM(CATEGORIAS[[#This Row],[COSTO ACUMULADO AX]:[PROVISIONES]]) -> 0 | Z10: =SUM(CATEGORIAS[[#This Row],[COSTO ACUMULADO ANTERIOR]:[PROVISIONES ANTERIOR]]) -> 0 | AA10: =CATEGORIAS[[#This Row],[PRESUPUESTO FINAL PROYECTADO]]-CATEGORIAS[[#This Row],[TOTAL PRODUCCION ACTUAL]] -> 0 | AB10: 0 | AE10: =SUM(CATEGORIAS[[#This Row],[INVENTARIO]:[PROYECCION DE COSTO DEL SALDO]]) -> 0 | AG10: =+CATEGORIAS[[#This Row],[PRESUPUESTO FINAL PROYECTADO]]-CATEGORIAS[[#This Row],[COSTO REAL]]-CATEGORIAS[[#This Row],[PROYECCION TOTAL DE COSTO]] -> 0
A11: =+IFERROR(VLOOKUP(CATEGORIAS[[#This Row],[CATEGORIA2]],[1]HOMOLOGACION!$A$1:$I$571,9,FALSE),0) -> 0A01 | B11: =+IFERROR(VLOOKUP(CATEGORIAS[[#This Row],[CATEGORIA2]],[1]HOMOLOGACION!$A$1:$C$571,3,FALSE),0) -> 0A01 | C11: =+IFERROR(VLOOKUP(CATEGORIAS[[#This Row],[CATEGORIA2]],[1]HOMOLOGACION!$A$1:$D$571,4,FALSE),0) -> Civil | D11: 11-0104-000G | E11: MAO CD - Civil / Enfierradura (G) | F11: NO | G11: 0 | H11: 0 | L11: =CATEGORIAS[[#This Row],[ADICIONALES]]+CATEGORIAS[[#This Row],[POM]] -> 0 | M11: 0 | N11: 0 | O11: =CATEGORIAS[[#This Row],[PRODUCCION PARTIDAS ORIGINALES ACTUAL]]+CATEGORIAS[[#This Row],[PRODUCCION ADICIONALES ACTUAL]] -> 0 | R11: =CATEGORIAS[[#This Row],[PRODUCCION ANTERIOR]]+CATEGORIAS[[#This Row],[PRODUCCION ADICIONALES ANTERIOR]] -> 0 | S11: 0 | V11: =SUM(CATEGORIAS[[#This Row],[COSTO ACUMULADO AX]:[PROVISIONES]]) -> 0 | Z11: =SUM(CATEGORIAS[[#This Row],[COSTO ACUMULADO ANTERIOR]:[PROVISIONES ANTERIOR]]) -> 0 | AA11: =CATEGORIAS[[#This Row],[PRESUPUESTO FINAL PROYECTADO]]-CATEGORIAS[[#This Row],[TOTAL PRODUCCION ACTUAL]] -> 0 | AB11: 0 | AE11: =SUM(CATEGORIAS[[#This Row],[INVENTARIO]:[PROYECCION DE COSTO DEL SALDO]]) -> 0 | AG11: =+CATEGORIAS[[#This Row],[PRESUPUESTO FINAL PROYECTADO]]-CATEGORIAS[[#This Row],[COSTO REAL]]-CATEGORIAS[[#This Row],[PROYECCION TOTAL DE COSTO]] -> 0
A12: =+IFERROR(VLOOKUP(CATEGORIAS[[#This Row],[CATEGORIA2]],[1]HOMOLOGACION!$A$1:$I$571,9,FALSE),0) -> 0M01 | B12: =+IFERROR(VLOOKUP(CATEGORIAS[[#This Row],[CATEGORIA2]],[1]HOMOLOGACION!$A$1:$C$571,3,FALSE),0) -> 0A11 | C12: =+IFERROR(VLOOKUP(CATEGORIAS[[#This Row],[CATEGORIA2]],[1]HOMOLOGACION!$A$1:$D$571,4,FALSE),0) -> Arquitectura | D12: 11-0105-000G | E12: MAO CD - Civil / Arquitectura (G) | F12: NO | G12: 0 | H12: 0 | L12: =CATEGORIAS[[#This Row],[ADICIONALES]]+CATEGORIAS[[#This Row],[POM]] -> 0 | M12: 0 | N12: 0 | O12: =CATEGORIAS[[#This Row],[PRODUCCION PARTIDAS ORIGINALES ACTUAL]]+CATEGORIAS[[#This Row],[PRODUCCION ADICIONALES ACTUAL]] -> 0 | R12: =CATEGORIAS[[#This Row],[PRODUCCION ANTERIOR]]+CATEGORIAS[[#This Row],[PRODUCCION ADICIONALES ANTERIOR]] -> 0 | S12: 0 | V12: =SUM(CATEGORIAS[[#This Row],[COSTO ACUMULADO AX]:[PROVISIONES]]) -> 0 | Z12: =SUM(CATEGORIAS[[#This Row],[COSTO ACUMULADO ANTERIOR]:[PROVISIONES ANTERIOR]]) -> 0 | AA12: =CATEGORIAS[[#This Row],[PRESUPUESTO FINAL PROYECTADO]]-CATEGORIAS[[#This Row],[TOTAL PRODUCCION ACTUAL]] -> 0 | AB12: 0 | AE12: =SUM(CATEGORIAS[[#This Row],[INVENTARIO]:[PROYECCION DE COSTO DEL SALDO]]) -> 0 | AG12: =+CATEGORIAS[[#This Row],[PRESUPUESTO FINAL PROYECTADO]]-CATEGORIAS[[#This Row],[COSTO REAL]]-CATEGORIAS[[#This Row],[PROYECCION TOTAL DE COSTO]] -> 0
A13: =+IFERROR(VLOOKUP(CATEGORIAS[[#This Row],[CATEGORIA2]],[1]HOMOLOGACION!$A$1:$I$571,9,FALSE),0) -> 0A01 | B13: =+IFERROR(VLOOKUP(CATEGORIAS[[#This Row],[CATEGORIA2]],[1]HOMOLOGACION!$A$1:$C$571,3,FALSE),0) -> 0A01 | C13: =+IFERROR(VLOOKUP(CATEGORIAS[[#This Row],[CATEGORIA2]],[1]HOMOLOGACION!$A$1:$D$571,4,FALSE),0) -> Civil | D13: 11-0199-000G | E13: MAO CD - Civil / Otros (G) | F13: SI | G13: 1.4597251e+08 | H13: 1.4597251e+08 | I13: 14606632 | L13: =CATEGORIAS[[#This Row],[ADICIONALES]]+CATEGORIAS[[#This Row],[POM]] -> 1.6057914e+08 | M13: 1.1662961e+08 | N13: 0 | O13: =CATEGORIAS[[#This Row],[PRODUCCION PARTIDAS ORIGINALES ACTUAL]]+CATEGORIAS[[#This Row],[PRODUCCION ADICIONALES ACTUAL]] -> 1.1662961e+08 | P13: 1.0791622e+08 | Q13: 436740.47 | R13: =CATEGORIAS[[#This Row],[PRODUCCION ANTERIOR]]+CATEGORIAS[[#This Row],[PRODUCCION ADICIONALES ANTERIOR]] -> 1.0835296e+08 | S13: 99656107 | U13: 8175470.9 | V13: =SUM(CATEGORIAS[[#This Row],[COSTO ACUMULADO AX]:[PROVISIONES]]) -> 1.0783158e+08 | W13: 53713252 | Y13: 6087837.8 | Z13: =SUM(CATEGORIAS[[#This Row],[COSTO ACUMULADO ANTERIOR]:[PROVISIONES ANTERIOR]]) -> 59801090 | AA13: =CATEGORIAS[[#This Row],[PRESUPUESTO FINAL PROYECTADO]]-CATEGORIAS[[#This Row],[TOTAL PRODUCCION ACTUAL]] -> 43949535 | AB13: 0 | AD13: 52747564 | AE13: =SUM(CATEGORIAS[[#This Row],[INVENTARIO]:[PROYECCION DE COSTO DEL SALDO]]) -> 52747564 | AG13: =+CATEGORIAS[[#This Row],[PRESUPUESTO FINAL PROYECTADO]]-CATEGORIAS[[#This Row],[COSTO REAL]]-CATEGORIAS[[#This Row],[PROYECCION TOTAL DE COSTO]] -> 0
A14: =+IFERROR(VLOOKUP(CATEGORIAS[[#This Row],[CATEGORIA2]],[1]HOMOLOGACION!$A$1:$I$571,9,FALSE),0) -> 0B01 | B14: =+IFERROR(VLOOKUP(CATEGORIAS[[#This Row],[CATEGORIA2]],[1]HOMOLOGACION!$A$1:$C$571,3,FALSE),0) -> 0A02 | C14: =+IFERROR(VLOOKUP(CATEGORIAS[[#This Row],[CATEGORIA2]],[1]HOMOLOGACION!$A$1:$D$571,4,FALSE),0) -> Estructura | D14: 11-0207-000G | E14: MAO CD - Estructura / Soldadura (G) | F14: NO | G14: 0 | H14: 0 | I14: 0 | L14: =CATEGORIAS[[#This Row],[ADICIONALES]]+CATEGORIAS[[#This Row],[POM]] -> 0 | M14: 0 | N14: 0 | O14: =CATEGORIAS[[#This Row],[PRODUCCION PARTIDAS ORIGINALES ACTUAL]]+CATEGORIAS[[#This Row],[PRODUCCION ADICIONALES ACTUAL]] -> 0 | P14: 0 | Q14: 0 | R14: =CATEGORIAS[[#This Row],[PRODUCCION ANTERIOR]]+CATEGORIAS[[#This Row],[PRODUCCION ADICIONALES ANTERIOR]] -> 0 | S14: 0 | V14: =SUM(CATEGORIAS[[#This Row],[COSTO ACUMULADO AX]:[PROVISIONES]]) -> 0 | W14: 0 | Z14: =SUM(CATEGORIAS[[#This Row],[COSTO ACUMULADO ANTERIOR]:[PROVISIONES ANTERIOR]]) -> 0 | AA14: =CATEGORIAS[[#This Row],[PRESUPUESTO FINAL PROYECTADO]]-CATEGORIAS[[#This Row],[TOTAL PRODUCCION ACTUAL]] -> 0 | AB14: 0 | AE14: =SUM(CATEGORIAS[[#This Row],[INVENTARIO]:[PROYECCION DE COSTO DEL SALDO]]) -> 0 | AG14: =+CATEGORIAS[[#This Row],[PRESUPUESTO FINAL PROYECTADO]]-CATEGORIAS[[#This Row],[COSTO REAL]]-CATEGORIAS[[#This Row],[PROYECCION TOTAL DE COSTO]] -> 0
A15: =+IFERROR(VLOOKUP(CATEGORIAS[[#This Row],[CATEGORIA2]],[1]HOMOLOGACION!$A$1:$I$571,9,FALSE),0) -> 0B01 | B15: =+IFERROR(VLOOKUP(CATEGORIAS[[#This Row],[CATEGORIA2]],[1]HOMOLOGACION!$A$1:$C$571,3,FALSE),0) -> 0A02 | C15: =+IFERROR(VLOOKUP(CATEGORIAS[[#This Row],[CATEGORIA2]],[1]HOMOLOGACION!$A$1:$D$571,4,FALSE),0) -> Estructura | D15: 11-0208-000G | E15: MAO CD - Estructura / Montajes (G) | F15: SI | G15: 1.7987561e+08 | H15: 1.7987561e+08 | I15: 612034.1 | L15: =CATEGORIAS[[#This Row],[ADICIONALES]]+CATEGORIAS[[#This Row],[POM]] -> 1.8048765e+08 | M15: 69920211 | N15: 370536.65 | O15: =CATEGORIAS[[#This Row],[PRODUCCION PARTIDAS ORIGINALES ACTUAL]]+CATEGORIAS[[#This Row],[PRODUCCION ADICIONALES ACTUAL]] -> 70290747 | P15: 50928692 | Q15: 826054.81 | R15: =CATEGORIAS[[#This Row],[PRODUCCION ANTERIOR]]+CATEGORIAS[[#This Row],[PRODUCCION ADICIONALES ANTERIOR]] -> 51754747 | S15: 142125812 | T15: -6268305 | U15: 15500921 | V15: =SUM(CATEGORIAS[[#This Row],[COSTO ACUMULADO AX]:[PROVISIONES]]) -> 1.5135843e+08 | W15: 81257881 | Y15: 8426648.2 | Z15: =SUM(CATEGORIAS[[#This Row],[COSTO ACUMULADO ANTERIOR]:[PROVISIONES ANTERIOR]]) -> 89684529 | AA15: =CATEGORIAS[[#This Row],[PRESUPUESTO FINAL PROYECTADO]]-CATEGORIAS[[#This Row],[TOTAL PRODUCCION ACTUAL]] -> 1.101969e+08 | AB15: 0 | AD15: 29129221 | AE15: =SUM(CATEGORIAS[[#This Row],[INVENTARIO]:[PROYECCION DE COSTO DEL SALDO]]) -> 29129221 | AG15: =+CATEGORIAS[[#This Row],[PRESUPUESTO FINAL PROYECTADO]]-CATEGORIAS[[#This Row],[COSTO REAL]]-CATEGORIAS[[#This Row],[PROYECCION TOTAL DE COSTO]] -> 0
