Workbook

Sheet Flujo
A7: FLUJO DE CAJA OBRA CC-0398
A9: MENSUAL | B9: Acumulado Periodo | C9: 45597 | D9: 45627 | E9: 45658 | F9: 45689 | G9: 45717 | H9: 45748 | I9: 45778 | J9: 45809 | K9: 45839 | L9: 45870 | M9: 45901 | N9: 45931 | O9: 45962 | P9: 45992 | Q9: 46023 | R9: 46054 | T9: TOTALES
A11: INGRESOS
A12: Anticipo | T12: 0
A13: Avance Estado de Pago | B13: 6.0139661e+09 | C13: 1.9041602e+08 | D13: 146477473 | E13: 332815173 | F13: 2.8902092e+08 | G13: 425678947 | H13: 291006079 | I13: 645216248 | J13: 473923006 | K13: 782666456 | L13: 931793770 | M13: 403711101 | N13: 398527353 | O13: 479368495 | P13: 2.2334508e+08 | Q13: 0 | T13: 6.0139661e+09
A14: Devolución Anticipo | T14: 0
A15: Retenciones | B15: -286349364 | C15: -9520801 | D15: -7323874 | E15: -16640759 | F15: -14451046 | G15: -21283947 | H15: -14550304 | I15: -32260812 | J15: -23696150 | K15: -39133323 | L15: -33140278 | M15: -20185555 | N15: -19926368 | O15: -23968425 | P15: -10267722 | Q15: 0 | T15: -286349364
A16: Estado de Pago (Pago Factura) | B16: 5.5145394e+09 | C16: 0 | D16: 180895215 | E16: 139153599 | F16: 316174414 | G16: 2.7456987e+08 | H16: 404395000 | I16: 276455775 | J16: 612955436 | K16: 450226856 | L16: 743533133 | M16: 898653492 | N16: 383525546 | O16: 378600985 | P16: 455400070 | Q16: 195086719 | R16: 0 | T16: 5.7096261e+09
A17: Devolución de Retenciones | B17: 0 | R17: 286349364 | T17: 286349364
A18: TOTAL INGRESOS NETO | B18: 5.8008888e+09 | C18: 0 | D18: 180895215 | E18: 139153599 | F18: 316174414 | G18: 2.7456987e+08 | H18: 404395000 | I18: 276455775 | J18: 612955436 | K18: 450226856 | L18: 743533133 | M18: 898653492 | N18: 383525546 | O18: 378600985 | P18: 455400070 | Q18: 481436083 | R18: 0 | T18: 5.9959755e+09
A19: IVA (19%) | B19: 1.1021689e+09 | C19: 0 | D19: 34370091 | E19: 26439184 | F19: 60073139 | G19: 52168276 | H19: 76835050 | I19: 52526597 | J19: 116461533 | K19: 85543103 | L19: 141271295 | M19: 170744163 | N19: 72869854 | O19: 71934187 | P19: 86526013 | Q19: 91472856 | R19: 0 | T19: 1139235341
A20: TOTAL INGRESOS | B20: 6.9030576e+09 | C20: 0 | D20: 215265306 | E20: 165592783 | F20: 376247553 | G20: 3.2673815e+08 | H20: 481230050 | I20: 328982372 | J20: 729416969 | K20: 535769959 | L20: 884804428 | M20: 1069397655 | N20: 456395400 | O20: 450535172 | P20: 541926083 | Q20: 572908939 | R20: 0 | T20: 7.1352108e+09
A22: COSTOS
A23: Mano de Obra | B23: 2.9378843e+09 | C23: 0 | D23: 2.706179e+08 | E23: 1.4741885e+08 | F23: 1.8828324e+08 | G23: 1.7979938e+08 | H23: 1.9616873e+08 | I23: 2.1858637e+08 | J23: 2.6391264e+08 | K23: 4.0626612e+08 | L23: 2.8564136e+08 | M23: 2.4066249e+08 | N23: 2.1269754e+08 | O23: 1.6152056e+08 | P23: 1.6963947e+08 | Q23: 0 | R23: 0 | T23: 2.9412146e+09
A24: Materiales | B24: 890841215 | C24: 0 | D24: 24862435 | E24: 1.4978851e+08 | F24: 60835352 | G24: 1.5621281e+08 | H24: 61861243 | I24: 33502848 | J24: 66893524 | K24: 1.3709684e+08 | L24: 81272168 | M24: 21347835 | N24: 39346132 | O24: 18248411 | P24: 18321506 | Q24: 0 | R24: 0 | T24: 8.6958961e+08
A25: Equipos | B25: 8.5084247e+08 | C25: 0 | D25: 45252147 | E25: 60732318 | F25: 59332536 | G25: 73771903 | H25: 78019623 | I25: 87118982 | J25: 96716433 | K25: 87936762 | L25: 81639261 | M25: 79049155 | N25: 37882310 | O25: 37655385 | P25: 33299188 | Q25: 0 | R25: 0 | T25: 8.58406e+08
A26: SubContratos | B26: 1.8795792e+08 | C26: 0 | D26: 46999638 | E26: 623218 | F26: 17653632 | G26: 6160082.9 | H26: 12789488 | I26: 5067928.4 | J26: 12429278 | K26: 9134612.1 | L26: 25359260 | M26: -2524857.8 | N26: 9384750 | O26: 27959337 | P26: 16372352 | Q26: 0 | R26: 0 | T26: 1.8740872e+08
A27: Otros Gastos | B27: 376299148 | C27: 0 | D27: 55710751 | E27: 34698582 | F27: 48396539 | G27: 8987376.2 | H27: 40368622 | I27: 30718045 | J27: 15502896 | K27: 25152219 | L27: 17680014 | M27: 24555684 | N27: 21604970 | O27: 23182550 | P27: 27057271 | Q27: 0 | R27: 0 | T27: 3.7361552e+08
A28: TOTAL COSTOS NETOS | B28: 5.243825e+09 | C28: 0 | D28: 4.4344287e+08 | E28: 3.9326147e+08 | F28: 3.745013e+08 | G28: 4.2493155e+08 | H28: 3.8920771e+08 | I28: 3.7499417e+08 | J28: 4.5545478e+08 | K28: 6.6558656e+08 | L28: 4.9159206e+08 | M28: 3.6309031e+08 | N28: 3.209157e+08 | O28: 2.6856624e+08 | P28: 2.6468978e+08 | Q28: 0 | R28: 0 | T28: 5.2302345e+09
A29: IVA (19%) | B29: 9.9632675e+08 | C29: 0 | D29: 84254146 | E29: 74719680 | F29: 71155246 | G29: 80736994 | H29: 73949464 | I29: 71248893 | J29: 86536407 | K29: 1.2646145e+08 | L29: 93402491 | M29: 68987158 | N29: 60973983 | O29: 51027586 | P29: 50291059 | Q29: 0 | R29: 0 | T29: 9.9374455e+08
A30: TOTAL COSTOS | B30: 6.2401518e+09 | C30: 0 | D30: 5.2769702e+08 | E30: 4.6798115e+08 | F30: 4.4565654e+08 | G30: 5.0566854e+08 | H30: 4.6315717e+08 | I30: 4.4624307e+08 | J30: 5.4199118e+08 | K30: 7.92048e+08 | L30: 5.8499455e+08 | M30: 4.3207747e+08 | N30: 3.8188969e+08 | O30: 3.1959383e+08 | P30: 3.1498084e+08 | Q30: 0 | R30: 0 | T30: 6.2239791e+09
A32: FLUJO CAJA | B32: 6.6290585e+08 | C32: 0 | D32: -3.1243171e+08 | E32: -3.0238837e+08 | F32: -69408989 | G32: -1.7893039e+08 | H32: 18072879 | I32: -1.1726069e+08 | J32: 1.8742579e+08 | K32: -2.5627804e+08 | L32: 2.9980988e+08 | M32: 6.3732019e+08 | N32: 74505714 | O32: 1.3094134e+08 | P32: 2.2694524e+08 | Q32: 572908939 | R32: 0 | T32: 9.1123177e+08
B33: 5.5706374e+08 | C33: 0 | D33: -2.6254766e+08 | E33: -2.5410787e+08 | F33: -58326882 | G33: -1.5036167e+08 | H33: 15187293 | I33: -98538398 | J33: 1.5750066e+08 | K33: -2.153597e+08 | L33: 2.5194107e+08 | M33: 5.3556318e+08 | N33: 62609844 | O33: 1.1003474e+08 | P33: 1.9071029e+08 | Q33: 481436083 | R33: 0 | T33: 7.6574098e+08
D34: -1312738.3 | E34: -1270539.4 | F34: -291634.41 | G34: -751808.37 | H34: 75936.467 | I34: -492691.99 | J34: 787503.3 | K34: -1076798.5 | L34: 1259705.4 | M34: 2677815.9 | N34: 313049.22 | O34: 550173.71 | P34: 953551.43 | Q34: 2407180.4 | R34: 0

Sheet Costo
C1: COSTO
H3: ACUMULADO | N3: TOTAL | O3: =+SUM(O5:Y5) -> 4.726637e+09
B4: COD | C4: PARTIDA / CATEGORIA | E4: PRESUPUESTO | F4: POM | H4: COSTO | I4: PROVISION | J4: TOTAL COSTO ACUMULADO | K4: TOTAL COSTO PERIODO | N4: noviembre | O4: diciembre | P4: enero | Q4: febrero | R4: Marzo | S4: Abril | T4: Mayo | U4: Junio | V4: Julio | W4: Agosto | X4: Septiembre | Y4: Octubre | Z4: Noviembre | AA4: Diciembre | AB4: Enero
C5: TOTALES | E5: =SUM(E6:E16) -> 4.75e+09 | F5: =SUM(F6:F16) -> 5.7770578e+09 | H5: =+SUM(H6:H16) -> 5.5972885e+09 | I5: =+SUM(I6:I16) -> 26536512 | J5: =+SUM(J6:J16) -> 5.623825e+09 | K5: =+SUM(K6:K16) -> 41640613 | M5: TOTAL | O5: =+SUM(O6:O10) -> 4.4344287e+08 | P5: =+SUM(P6:P10) -> 3.9326147e+08 | Q5: =+SUM(Q6:Q10) -> 3.745013e+08 | R5: =+SUM(R6:R10) -> 4.2493155e+08 | S5: =+SUM(S6:S10) -> 3.8920771e+08 | T5: =+SUM(T6:T10) -> 3.7499417e+08 | U5: =+SUM(U6:U10) -> 4.5545478e+08 | V5: =+SUM(V6:V10) -> 6.73969e+08 | ... AB5: =+SUM(AB6:AB10) -> 41640613
B6: 0A00 | C6: A - MANO DE OBRA DIRECTA | E6: 9.8950398e+08 | F6: 1.1914504e+09 | H6: 1021487689 | I6: 0 | J6: 1021487689 | K6: 0 | M6: =+SUM(O6:AB6) -> 2.9378843e+09 | O6: 2.706179e+08 | P6: 1.4741885e+08 | Q6: 1.8828324e+08 | R6: 179799377 | S6: 1.9616873e+08 | T6: 2.1858637e+08 | U6: 2.6391264e+08 | V6: 4.0626612e+08 | W6: 2.8564136e+08 | X6: 2.4066249e+08 | Y6: 2.1269754e+08 | Z6: 1.6152056e+08 | AA6: 1.2045129e+08 | AB6: 45857793
B7: 0B00 | C7: B - MATERIALES | E7: 6.5413681e+08 | F7: 6.2563393e+08 | H7: 889767275 | I7: 1073940 | J7: 890841215 | K7: 24407773 | M7: =+SUM(O7:AB7) -> 8.9086956e+08 | O7: 24862435 | P7: 1.4978851e+08 | Q7: 60835352 | R7: 1.5621281e+08 | S7: 61861243 | T7: 33502848 | U7: 66893524 | V7: 1.3709684e+08 | W7: 81272168 | X7: 21347835 | Y7: 39346132 | Z7: 18248411 | AA7: 15193690 | AB7: 24407773
B8: 0C00 | C8: C - COSTO PROPORCIONAL HH | E8: 4.3866146e+08 | F8: 4.6882103e+08 | H8: 6.2471013e+08 | I8: 2670636 | J8: 6.2738077e+08 | K8: 12462129 | M8: =+SUM(O8:AB8) -> 8.5084247e+08 | O8: 45252147 | P8: 60732318 | Q8: 59332536 | R8: 73771903 | S8: 78019623 | T8: 87118982 | U8: 96716433 | V8: 87936762 | W8: 81639261 | X8: 79049155 | Y8: 37882310 | Z8: 37655385 | AA8: 27614408 | AB8: -1878756
B9: 0D00 | C9: D - EQUIPOS Y COMBUSTIBLES | E9: 8.2520614e+08 | F9: 9.7711839e+08 | H9: 7.1878179e+08 | I9: 653386 | J9: 7.1943517e+08 | K9: -4692261 | M9: =+SUM(O9:AB9) -> 1.879492e+08 | O9: 46999638 | P9: 623218 | Q9: 17653632 | R9: 6160082.9 | S9: 12789488 | T9: 5067928.4 | U9: 12429278 | V9: 9134612.1 | W9: 25359260 | X9: -2524857.8 | Y9: 9384750 | Z9: 27959337 | AA9: 13577292 | AB9: 3335540
B10: 0X00 | C10: E - SUBCONTRATOS | E10: 1.1022147e+08 | F10: 2.0940075e+08 | H10: 180846551 | I10: 7111366.3 | J10: 1.8795792e+08 | K10: 3335540 | M10: =+SUM(O10:AB10) -> 3.7629915e+08 | O10: 55710751 | P10: 34698582 | Q10: 48396539 | R10: 8987376 | S10: 40368622 | T10: 30718045 | U10: 15502896 | V10: 33534660 | W10: 23572205 | X10: 32739320 | Y10: 28805225 | Z10: 30908563 | AA10: 22438100 | AB10: -30081737
B11: 1F00 | C11: F - MANO DE OBRA INDIRECTA | E11: 8.493466e+08 | F11: 1.2773712e+09 | H11: 1.2890158e+09 | I11: 0 | J11: 1.2890158e+09 | K11: 33395664 | M11: =+SUM(M6:M10) -> 5.2438446e+09
B12: 1G00 | C12: G - EQUIPOS INDIRECTOS | E12: 1.1279563e+08 | F12: 1.5747306e+08 | H12: 1.2334266e+08 | I12: 8064635 | J12: 1.3140729e+08 | K12: 2813505
B13: 1H00 | C13: H - INSTALACIÓN DE FAENAS | E13: 1.3575453e+08 | F13: 1.869204e+08 | H13: 103224911 | I13: 1649016 | J13: 104873927 | K13: -35662648
B14: 1I00 | C14: I - GASTOS GENERALES | E14: 1.9454474e+08 | F14: 2.4304008e+08 | H14: 170627337 | I14: 3443701 | J14: 174071038 | K14: 6384688
B15: 1J00 | C15: J - GASTOS FINANCIEROS - SEGUROS Y BOLETAS | E15: 59828638 | F15: 59828638 | H15: 95484351 | I15: 1869832 | J15: 97354183 | K15: -803777
B16: 1K00 | C16: K - OFICINA CENTRAL - IMPREVISTOS - UTILIDADES | E16: 3.8e+08 | F16: 3.8e+08 | H16: 3.8e+08 | I16: 0 | J16: 3.8e+08 | K16: 0
F19: Mano de Obra | H19: =+H6+H8+H11 -> 2.9352136e+09 | I19: Mano de Obra | J19: =+J6+J8+J11 -> 2.9378843e+09 | K19: =+K6+K8+K11 -> 45857793
F20: Materiales | H20: =+H7 -> 889767275 | I20: Materiales | J20: =+J7 -> 890841215 | K20: =+K7 -> 24407773 | L20: Reclasificación Fact Hormigón Santiago
F21: Equipos | H21: =+H9+H12 -> 8.4212445e+08 | I21: Equipos | J21: =+J9+J12 -> 8.5084247e+08 | K21: =+K9+K12 -> -1878756
F22: Subcontratos | H22: =+H10 -> 180846551 | I22: Subcontratos | J22: =+J10 -> 1.8795792e+08 | K22: =+K10 -> 3335540
F23: Otros Gastos | H23: =+H13+H14+H15 -> 369336599 | I23: Otros Gastos | J23: =+J13+J14+J15 -> 376299148 | K23: =+K13+K14+K15 -> -30081737
H24: =SUM(H19:H23) -> 5.2172885e+09 | J24: =SUM(J19:J23) -> 5.243825e+09
M25: Perdida o Ganancia | N25: =+J29-N29 -> 3.8575626e+08
C26: PROYECCION
L27: Costo Acumulado | M27: Costo Proyect. Periodo | N27: Proyec. Costo Acum.
H28: PRODUCCION | L28: COSTOS | P28: PROYECCION
C29: TOTALES | E29: =SUM(E30:E40) -> 4.75e+09 | F29: =SUM(F30:F40) -> 6.0139661e+09 | H29: =SUM(H30:H40) -> 6.0139661e+09 | I29: =SUM(I30:I40) -> 0.005105339 | J29: =SUM(J30:J40) -> 6.0139661e+09 | K29: 0 | L29: =SUM(L30:L40) -> 5.623825e+09 | M29: =SUM(M30:M40) -> 4384841 | N29: =SUM(N30:N40) -> 5.6282099e+09 | O29: 0 | P29: =SUM(P31:P40) -> 5.1726261e+09 | Q29: =SUM(Q31:Q40) -> 5.1726261e+09 | R29: =SUM(R31:R40) -> 0
C30: A - MANO DE OBRA DIRECTA | E30: 9.8950398e+08 | F30: 1.2398846e+09 | H30: 1.2398846e+09 | I30: =+F30-H30 -> 0 | J30: 1.2398846e+09 | K30: 0 | L30: 1021487689 | M30: =+N30-L30 -> 0 | N30: 1021487689 | O30: 0 | P30: 1.3587361e+09 | Q30: 1.3587361e+09 | R30: 0
C31: B - MATERIALES | E31: 6.5413681e+08 | F31: 6.7918319e+08 | H31: 6.7918319e+08 | I31: =+F31-H31 -> 0 | J31: 6.7918319e+08 | K31: 0 | L31: 890841215 | M31: =+N31-L31 -> 0 | N31: 890841215 | O31: 0 | P31: 4.8090604e+08 | Q31: 4.8090604e+08 | R31: 0
C32: C - COSTO PROPORCIONAL HH | E32: 4.3866146e+08 | F32: 4.9517782e+08 | H32: 4.9517782e+08 | I32: =+F32-H32 -> 0 | J32: 4.9517782e+08 | K32: 0 | L32: 6.2738077e+08 | M32: =+N32-L32 -> 0 | N32: 6.2738077e+08 | O32: 0 | P32: 2.1464034e+08 | Q32: 2.1464034e+08 | R32: 0
C33: D - EQUIPOS Y COMBUSTIBLES | E33: 8.2520614e+08 | F33: 1.005747e+09 | H33: 1.005747e+09 | I33: =+F33-H33 -> 0 | J33: 1.005747e+09 | K33: 0 | L33: 7.1943517e+08 | M33: =+N33-L33 -> 0 | N33: 7.1943517e+08 | O33: 0 | P33: 1.1347377e+09 | Q33: 1.1347377e+09 | R33: 0
C34: E - SUBCONTRATOS | E34: 1.1022147e+08 | F34: 2.3868082e+08 | H34: 2.3868082e+08 | I34: =+F34-H34 -> 0 | J34: 2.3868082e+08 | K34: 0 | L34: 1.8795792e+08 | M34: =+N34-L34 -> 0 | N34: 1.8795792e+08 | O34: 0 | P34: 2.9233488e+08 | Q34: 2.9233488e+08 | R34: 0
C35: F - MANO DE OBRA INDIRECTA | E35: 8.493466e+08 | F35: 1.3073177e+09 | H35: 1.3073177e+09 | I35: =+F35-H35 -> 0 | J35: 1.3073177e+09 | K35: 0 | L35: 1.2890158e+09 | M35: =+N35-L35 -> 1902303.5 | N35: 1.2909181e+09 | O35: 0 | P35: 1.8532068e+09 | Q35: 1.8532068e+09 | R35: 0
C36: G - EQUIPOS INDIRECTOS | E36: 1.1279563e+08 | F36: 1.6145005e+08 | H36: 1.6145005e+08 | I36: =+F36-H36 -> 0 | J36: 1.6145005e+08 | K36: 0 | L36: 1.3140729e+08 | M36: =+N36-L36 -> 482537.5 | N36: 1.3188983e+08 | O36: 0 | P36: 78853656 | Q36: 78853656 | R36: 0
C37: H - INSTALACIÓN DE FAENAS | E37: 1.3575453e+08 | F37: 1.9683827e+08 | H37: 1.9683827e+08 | I37: =+F37-H37 -> 0 | J37: 1.9683827e+08 | K37: 0 | L37: 104873927 | M37: =+N37-L37 -> 0 | N37: 104873927 | O37: 0 | P37: 2.5253843e+08 | Q37: 2.5253843e+08 | R37: 0
C38: I - GASTOS GENERALES | E38: 1.9454474e+08 | F38: 2.4774862e+08 | H38: 2.4774862e+08 | I38: =+F38-H38 -> 0 | J38: 2.4774862e+08 | K38: 0 | L38: 174071038 | M38: =+N38-L38 -> 2000000 | N38: 176071038 | O38: 0 | P38: 2.6502103e+08 | Q38: 2.6502103e+08 | R38: 0
C39: J - GASTOS FINANCIEROS - SEGUROS Y BOLETAS | E39: 59828638 | F39: 61938097 | H39: 61938097 | I39: =+F39-H39 -> 0.005105339 | J39: 61938097 | K39: 0 | L39: 97354183 | M39: =+N39-L39 -> 0 | N39: 97354183 | O39: 0 | P39: 78147228 | Q39: 78147228 | R39: 0
C40: K - OFICINA CENTRAL - IMPREVISTOS - UTILIDADES | E40: 3.8e+08 | F40: 3.8e+08 | H40: 3.8e+08 | I40: =+F40-H40 -> 0 | J40: 3.8e+08 | K40: 0 | L40: 3.8e+08 | M40: =+N40-L40 -> 0 | N40: 3.8e+08 | O40: 0 | P40: 5.2224e+08 | Q40: 5.2224e+08 | R40: 0
E41: =SUM(E30:E40) -> 4.75e+09 | F41: =SUM(F30:F40) -> 6.0139661e+09 | H41: =SUM(H30:H40) -> 6.0139661e+09 | I41: =SUM(I30:I40) -> 0.005105339 | J41: =SUM(J30:J40) -> 6.0139661e+09 | L41: =SUM(L30:L40) -> 5.623825e+09 | M41: =SUM(M30:M40) -> 4384841 | N41: =SUM(N30:N40) -> 5.6282099e+09 | P41: =SUM(P30:P40) -> 6.5313622e+09 | Q41: =SUM(Q30:Q40) -> 6.5313622e+09 | R41: =SUM(R30:R40) -> 0
L42: Proyectado | M42: Pendiente | N42: ACUM. PERIODO | P42: =SUM(P30:P39) -> 6.0091222e+09
H43: =+H30+H32+H35 -> 3.0423801e+09 | I43: =+I30+I32+I35 -> 0 | J43: Mano de Obra | L43: =+N30+N32+N35 -> 2.9397866e+09 | M43: =+M30+M32+M35 -> 1902303.5 | N43: =+L30+L32+L35 -> 2.9378843e+09 | O43: =+N43+M43 -> 2.9397866e+09
...

Sheet Flujo (reajuste)
E2: 4750000000
A7: FLUJO DE CAJA OBRA CC-0398
AX8: ENERO
A9: MENSUAL | B9: Acumulado Periodo | C9: 45597 | D9: 45627 | E9: 45658 | F9: 45689 | G9: 45717 | H9: 45748 | I9: 45778 | J9: 45809 | K9: 45839 | L9: 45870 | M9: 45901 | N9: 45931 | O9: 45962 | P9: 45992 | Q9: 46023 | R9: 46054 | S9: 46082 | U9: TOTALES | AX9: TOTALES
A11: INGRESOS
A12: Anticipo | U12: =SUM(B12:B12) -> 0 | V12: Ingreso total | W12: =+U12+U14 -> 0 | Z12: Costo total | AX12: 0
A13: Avance Estado de Pago | B13: =SUM(C13:G13) -> 1.4545376e+09 | C13: 1.9041602e+08 | D13: 146477473 | E13: 332815173 | F13: 2.8902092e+08 | G13: 4.9580802e+08 | H13: =+Costo!$F$41*'Flujo (reajuste)'!H36 -> 8.6499836e+08 | I13: =+Costo!$F$41*'Flujo (reajuste)'!I36 -> 8.0351649e+08 | J13: =+Costo!$F$41*'Flujo (reajuste)'!J36 -> 6.8179419e+08 | K13: =+Costo!$F$41*'Flujo (reajuste)'!K36 -> 6.916061e+08 | L13: =+Costo!$F$41*'Flujo (reajuste)'!L36 -> 4.8111729e+08 | M13: =+Costo!$F$41*'Flujo (reajuste)'!M36 -> 2.4055864e+08 | N13: =+Costo!$F$41*'Flujo (reajuste)'!N36 -> 1.8116275e+08 | O13: =+Costo!$F$41*'Flujo (reajuste)'!O36 -> 1.5034915e+08 | ... Q13: =+Costo!$F$41*'Flujo (reajuste)'!Q36 -> 1.0223742e+08 | U13: =SUM(C13:S13) -> 5.7841853e+09 | V13: 5.193519e+09 | X13: =+X16-U13 -> 2.2978085e+08 | Z13: 5.1793168e+09 | AX13: 4750000000
A14: Devolución Anticipo | U14: =SUM(D14:P14) -> 0 | AX14: 0
A15: Retenciones | B15: =SUM(C15:G15) -> -72726881 | C15: =-ROUND(C13*5%,0) -> -9520801 | D15: =-ROUND(D13*5%,0) -> -7323874 | E15: =-ROUND(E13*5%,0) -> -16640759 | F15: =-ROUND(F13*5%,0) -> -14451046 | G15: =-ROUND(G13*5%,0) -> -24790401 | H15: =-ROUND(H13*5%,0) -> -43249918 | I15: =-ROUND(I13*5%,0) -> -40175825 | J15: =-ROUND(J13*5%,0) -> -34089710 | ... Q15: =-ROUND(Q13*5%,0) -> -5111871 | U15: =SUM(C15:S15) -> -289209265 | W15: Total Facturado | X15: POM | Y15: Saldo x Facturar | AX15: -237500001
A16: Estado de Pago (Pago Factura) | B16: =SUM(C16:G16) -> 9.107931e+08 | C16: 0 | D16: 180895215 | E16: 139153599 | F16: 316174414 | G16: 2.7456987e+08 | H16: 471017620 | I16: 709642535 | J16: 659202958 | K16: 559342284 | L16: 567391951 | M16: 394707444 | N16: 197353722 | O16: 148625479 | P16: 123346076 | Q16: 108544547 | R16: 83875332 | U16: =SUM(D16:R16) -> 4.933843e+09 | W16: =U18 -> 5.2230523e+09 | X16: =+Costo!F41 -> 6.0139661e+09 | Y16: =+X16-W16 -> 7.9091381e+08 | AX16: 4.1969861e+09
A17: Devolución de Retenciones | B17: 0 | S17: =+SUM(C15:S15)*-1 -> 289209265 | U17: =SUM(D17:R17) -> 0 | AX17: 237500001
A18: TOTAL INGRESOS NETO | B18: =+B16-B14-B15 -> 9.8351998e+08 | C18: =+C16+D17 -> 0 | D18: =+D16+E17 -> 180895215 | E18: =+E16+F17 -> 139153599 | F18: =+F16+G17 -> 316174414 | G18: =+G16+H17 -> 2.7456987e+08 | H18: =+H16+I17 -> 471017620 | I18: =+I16+J17 -> 709642535 | J18: =+J16+K17 -> 659202958 | K18: =+K16+Q17 -> 559342284 | L18: =+L16 -> 567391951 | M18: =+M16 -> 394707444 | N18: =+N16 -> 197353722 | O18: =+O16 -> 148625479 | P18: =+P16 -> 123346076 | Q18: =+Q16 -> 108544547 | R18: =+R16 -> 83875332 | S18: =+S17 -> 289209265 | U18: =SUM(D18:S18) -> 5.2230523e+09 | AX18: 4.4344861e+09
A19: IVA (19%) | B19: =B18*0.19 -> 1.868688e+08 | C19: =ROUND(C18*0.19,0) -> 0 | D19: =ROUND(D18*0.19,0) -> 34370091 | E19: =ROUND(E18*0.19,0) -> 26439184 | F19: =ROUND(F18*0.19,0) -> 60073139 | G19: =ROUND(G18*0.19,0) -> 52168276 | H19: =ROUND(H18*0.19,0) -> 89493348 | I19: =ROUND(I18*0.19,0) -> 134832082 | J19: =ROUND(J18*0.19,0) -> 125248562 | ... S19: =ROUND(S18*0.19,0) -> 54949760 | U19: =SUM(D19:S19) -> 992379940 | AX19: 842552354
A20: TOTAL INGRESOS | B20: =B18+B19 -> 1.1703888e+09 | C20: =C18+C19 -> 0 | D20: =D18+D19 -> 215265306 | E20: =E18+E19 -> 165592783 | F20: =F18+F19 -> 376247553 | G20: =G18+G19 -> 3.2673815e+08 | H20: =H18+H19 -> 560510968 | I20: =I18+I19 -> 844474617 | ... S20: =S18+S19 -> 344159025 | U20: =+U18+U19 -> 6.2154323e+09 | AX20: =+AX19+AX18 -> 5.2770384e+09
A22: COSTOS | AB22: Proyectado | AD22: Antes del cambio | AF22: Dif | AG22: Resta mensual
A23: Mano de Obra | B23: =+Costo!J19 -> 2.9378843e+09 | C23: 0 | D23: 2.706179e+08 | E23: 1.4741885e+08 | F23: 1.8828324e+08 | G23: 1.7979938e+08 | H23: 3.2728254e+08 | I23: 3.4489121e+08 | J23: 3.5225399e+08 | K23: 3.0022416e+08 | L23: 2.0537633e+08 | M23: 1.5435655e+08 | N23: 83470118 | O23: 83470118 | P23: 42834715 | Q23: 28747776 | R23: =+R$39*Costo!$L43 -> 0 | S23: =+S$39*Costo!$L43 -> 0 | U23: =SUM(D23:S23) -> 2.7090269e+09 | Z23: Mano de Obra | AB23: 1.9229075e+09 | AD23: 2.0363657e+09 | AF23: =+AB23-AD23 -> -1.1345822e+08 | AG23: 11345822 | AX23: 2.2855422e+09
A24: Materiales | B24: =+Costo!J20 -> 890841215 | C24: 0 | D24: =4862435+20000000 -> 24862435 | E24: =129788505.104+20000000 -> 1.4978851e+08 | F24: =40835351.9702+20000000 -> 60835352 | G24: 1.5621281e+08 | H24: 47580923 | I24: 51561294 | J24: 45225621 | K24: 31464484 | L24: 25024509 | M24: 13491691 | N24: 2468094.6 | O24: 2468094.6 | P24: 1282623.2 | Q24: 98326.49 | R24: =+R$39*Costo!$L44 -> 0 | S24: =+S$39*Costo!$L44 -> 0 | U24: =SUM(D24:S24) -> 6.1236476e+08 | Z24: Materiales | AB24: 2.2066566e+08 | AD24: 4.6031238e+08 | AF24: =+AB24-AD24 -> -2.3964672e+08 | AG24: 23964672 | AX24: 6.710275e+08
A25: Equipos | B25: =+Costo!J21 -> 8.5084247e+08 | C25: 0 | D25: 45252147 | E25: 60732318 | F25: 59332536 | G25: 73771903 | H25: 1.091347e+08 | I25: 1.1490645e+08 | J25: 1.1731981e+08 | K25: 1.0026554e+08 | L25: 69176431 | M25: 52453232 | N25: 29218165 | O25: 29218165 | P25: 15898743 | Q25: 11281343 | R25: =+R$39*Costo!$L45 -> 0 | S25: =+S$39*Costo!$L45 -> 0 | U25: =SUM(D25:S25) -> 8.8796147e+08 | Z25: Equipos | AB25: 6.4887256e+08 | AD25: 6.6747743e+08 | AF25: =+AB25-AD25 -> -18604867 | AG25: 1860486.7 | AX25: 8.7512352e+08
A26: SubContratos | B26: =+Costo!J22 -> 1.8795792e+08 | C26: 0 | D26: 46999638 | E26: 623218 | F26: 17653632 | G26: 6160082.9 | H26: 28500187 | I26: 30046502 | J26: 30693068 | K26: 26124040 | L26: 17794927 | M26: 13314597 | N26: 7089666.6 | O26: 7089666.6 | P26: 3521246.6 | Q26: 2284194.4 | R26: =+R$39*Costo!$L46 -> 0 | S26: =+S$39*Costo!$L46 -> 0 | U26: =SUM(D26:S26) -> 2.3789467e+08 | Z26: Subcontratos | AB26: 166458095 | AD26: 1.7882456e+08 | AF26: =+AB26-AD26 -> -12366467 | AG26: 1236646.7 | AX26: 1.3800183e+08
A27: Otros Gastos | B27: =+Costo!J23 -> 376299148 | C27: 0 | D27: =50710751+5000000 -> 55710751 | E27: =29698582+5000000 -> 34698582 | F27: =38396539.4414033+10000000 -> 48396539 | G27: 8987376.2 | H27: 37971301 | I27: 40259749 | J27: 40216627 | K27: 34454755 | L27: 22128196 | M27: 15497593 | N27: 6285090.7 | O27: 6285090.7 | P27: 1004055.6 | Q27: 173296.78 | R27: =+R$39*Costo!$L47 -> 0 | S27: =+S$39*Costo!$L47 -> 0 | U27: =SUM(D27:S27) -> 3.52069e+08 | Z27: Otros Gastos | AB27: 2.0427575e+08 | AD27: 2.64649e+08 | AF27: =+AB27-AD27 -> -60373245 | AG27: 6037324.5 | AX27: 4.003049e+08
A28: TOTAL COSTOS NETOS | B28: =SUM(B23:B27) -> 5.243825e+09 | C28: =SUM(C23:C27) -> 0 | D28: =SUM(D23:D27) -> 4.4344287e+08 | E28: =SUM(E23:E27) -> 3.9326147e+08 | F28: =SUM(F23:F27) -> 3.745013e+08 | G28: =SUM(G23:G27) -> 4.2493155e+08 | H28: =SUM(H23:H27) -> 5.5046964e+08 | I28: =SUM(I23:I27) -> 5.816652e+08 | ... S28: =SUM(S23:S27) -> 0 | U28: =SUM(D28:S28) -> 4.7993168e+09 | V28: =+Z13-U28 -> 3.8e+08 | AX28: 4370000000
A29: IVA (19%) | B29: {=SUM(B23:B27*0.19)} -> 9.9632675e+08 | C29: {=SUM(C23:C27*0.19)} -> 0 | D29: {=SUM(D23:D27*0.19)} -> 84254146 | E29: {=SUM(E23:E27*0.19)} -> 74719680 | F29: {=SUM(F23:F27*0.19)} -> 71155246 | G29: {=SUM(G23:G27*0.19)} -> 80736994 | H29: {=SUM(H23:H27*0.19)} -> 1.0458923e+08 | I29: {=SUM(I23:I27*0.19)} -> 1.1051639e+08 | ... S29: {=SUM(S23:S27*0.19)} -> 0 | U29: =SUM(D29:S29) -> 9.1187018e+08 | AB29: 14202237 | AX29: 8.303e+08
A30: TOTAL COSTOS | B30: =B28+B29 -> 6.2401518e+09 | C30: =C28+C29 -> 0 | D30: =D28+D29 -> 5.2769702e+08 | E30: =E28+E29 -> 4.6798115e+08 | F30: =F28+F29 -> 4.4565654e+08 | G30: =G28+G29 -> 5.0566854e+08 | H30: =H28+H29 -> 6.5505888e+08 | I30: =I28+I29 -> 6.9218159e+08 | ... S30: =S28+S29 -> 0 | U30: =SUM(D30:S30) -> 5.7111869e+09 | AX30: 5.2003e+09
A32: FLUJO CAJA | B32: =B20-B30 -> -5.069763e+09 | C32: =C20-C30 -> 0 | D32: =D20-D30 -> -3.1243171e+08 | E32: =E20-E30 -> -3.0238837e+08 | F32: =F20-F30 -> -69408989 | G32: =G20-G30 -> -1.7893039e+08 | H32: =H20-H30 -> -94547908 | I32: =I20-I30 -> 1.5229303e+08 | ... S32: =S20-S30 -> 344159025 | U32: =SUM(D32:S32) -> 5.0424531e+08 | AB32: =+U32-V28 -> 1.2424531e+08 | AX32: 76738422
B33: =+B18-B28 -> -4.260305e+09 | C33: =+C18-C28 -> 0 | D33: =+D18-D28 -> -2.6254766e+08 | E33: =+E18-E28 -> -2.5410787e+08 | F33: =+F18-F28 -> -58326882 | G33: =+G18-G28 -> -1.5036167e+08 | H33: =+H18-H28 -> -79452023 | I33: =+I18-I28 -> 1.2797733e+08 | ... S33: =+S18-S28 -> 289209265 | U33: =SUM(D33:S33) -> 4.2373555e+08 | V33: Resultado Informe de costos | AX33: 64486068
AB34: =+U33*0.19 -> 80509755
B36: %AVANCE Producción | D36: =D13/Costo!F41 -> 0.024356219 | E36: =+E13/4750000000 -> 0.070066352 | F36: =+F13/4750000000 -> 0.060846509 | G36: 0.083 | H36: 0.1438316 | I36: 0.13360842 | J36: 0.11336848 | K36: 0.115 | L36: 0.08 | M36: 0.04 | N36: 0.030123674 | O36: 0.025 | P36: 0.022 | Q36: 0.017 | AB36: =+U20-U30 -> 5.0424531e+08
AB38: =+U18-U28 -> 4.2373555e+08
B39: %AVANCE Costo | D39: 0.028203897 | E39: 0.070066352 | F39: 0.07 | G39: 0.08 | H39: 0.125 | I39: 0.1315 | J39: 0.13421787 | K39: 0.11501177 | L39: 0.08 | M39: 0.061166751 | N39: 0.035 | O39: 0.035 | P39: 0.02 | Q39: 0.0148
H44: =+H23-$AG$23 -> 3.1593671e+08 | I44: =+I23-$AG$23 -> 3.3354539e+08 | J44: =+J23-$AG$23 -> 3.4090817e+08 | K44: =+K23-$AG$23 -> 2.8887834e+08 | L44: =+L23-$AG$23 -> 1.9403051e+08 | M44: =+M23-$AG$23 -> 1.4301073e+08 | N44: =+N23-$AG$23 -> 72124296 | O44: =+O23-$AG$23 -> 72124296 | ... Q44: =+Q23-$AG$23 -> 17401954 | R44: =+SUM(H44:Q44) -> 1.8094493e+09
H45: =+H24-$AG$24 -> 23616251 | I45: =+I24-$AG$24 -> 27596622 | J45: =+J24-$AG$24 -> 21260949 | K45: =+K24-$AG$24 -> 7499812 | L45: =+L24-$AG$24 -> 1059836.8 | M45: =+M24-$AG$24 -> -10472981 | N45: =+N24-$AG$24 -> -21496577 | O45: =+O24-$AG$24 -> -21496577 | ... Q45: =+Q24-$AG$24 -> -23866345 | R45: =+SUM(H45:Q45) -> -18981059
H46: =+H25-$AG$25 -> 1.0727421e+08 | I46: =+I25-$AG$25 -> 1.1304596e+08 | J46: =+J25-$AG$25 -> 1.1545932e+08 | K46: =+K25-$AG$25 -> 98405048 | L46: =+L25-$AG$25 -> 67315944 | M46: =+M25-$AG$25 -> 50592745 | N46: =+N25-$AG$25 -> 27357678 | O46: =+O25-$AG$25 -> 27357678 | ... Q46: =+Q25-$AG$25 -> 9420856.4 | R46: =+SUM(H46:Q46) -> 6.302677e+08
H47: =+H26-$AG$26 -> 27263540 | I47: =+I26-$AG$26 -> 28809855 | J47: =+J26-$AG$26 -> 29456422 | K47: =+K26-$AG$26 -> 24887394 | L47: =+L26-$AG$26 -> 16558280 | M47: =+M26-$AG$26 -> 12077951 | N47: =+N26-$AG$26 -> 5853019.9 | O47: =+O26-$AG$26 -> 5853019.9 | ... Q47: =+Q26-$AG$26 -> 1047547.7 | R47: =+SUM(H47:Q47) -> 1.5409163e+08
H48: =+H27-$AG$27 -> 31933976 | I48: =+I27-$AG$27 -> 34222425 | J48: =+J27-$AG$27 -> 34179302 | K48: =+K27-$AG$27 -> 28417431 | L48: =+L27-$AG$27 -> 16090871 | M48: =+M27-$AG$27 -> 9460268.3 | N48: =+N27-$AG$27 -> 247766.18 | O48: =+O27-$AG$27 -> 247766.18 | ... Q48: =+Q27-$AG$27 -> -5864027.7 | R48: =+SUM(H48:Q48) -> 1.4390251e+08
H51: 3.2728254e+08 | I51: 3.4489121e+08 | J51: 3.5225399e+08 | K51: 3.0022416e+08 | L51: 2.0537633e+08 | M51: 1.5435655e+08 | N51: 83470118 | O51: 83470118 | P51: 42834715 | Q51: 28747776 | R51: =+SUM(H51:Q51) -> 1.9229075e+09
H52: =52580922.8946731-5000000 -> 47580923 | I52: =56561293.8223072-5000000 -> 51561294 | J52: =58225620.538641-13000000 -> 45225621 | K52: =46464483.9719175-15000000 -> 31464484 | L52: 25024509 | M52: 13491691 | N52: =+-2531905.38564015+5000000 -> 2468094.6 | O52: =+-2531905.38564015+5000000 -> 2468094.6 | P52: =-11717376.7651138+13000000 -> 1282623.2 | Q52: =+-14901673.509998+15000000 -> 98326.49 | R52: =+SUM(H52:Q52) -> 2.2066566e+08
H53: 1.091347e+08 | I53: 1.1490645e+08 | J53: 1.1731981e+08 | K53: 1.0026554e+08 | L53: 69176431 | M53: 52453232 | N53: 29218165 | O53: 29218165 | P53: 15898743 | Q53: 11281343 | R53: =+SUM(H53:Q53) -> 6.4887256e+08
H54: 28500187 | I54: 30046502 | J54: 30693068 | K54: 26124040 | L54: 17794927 | M54: 13314597 | N54: 7089666.6 | O54: 7089666.6 | P54: 3521246.6 | Q54: 2284194.4 | R54: =+SUM(H54:Q54) -> 166458095
H55: 37971301 | I55: 40259749 | J55: =41216626.6348358-1000000 -> 40216627 | K55: 34454755 | L55: 22128196 | M55: 15497593 | N55: 6285090.7 | O55: 6285090.7 | P55: 1004055.6 | Q55: =+-826703.218294677+1000000 -> 173296.78 | R55: =+SUM(H55:Q55) -> 2.0427575e+08

Sheet Costo (2)
C1: COSTO
H3: ACUMULADO
B4: COD | C4: PARTIDA / CATEGORIA | E4: PRESUPUESTO | F4: POM | H4: COSTO | I4: PROVISION | J4: TOTAL COSTO ACUMULADO | K4: TOTAL COSTO PERIODO | M4: noviembre | N4: diciembre | O4: enero | P4: febrero
C5: TOTALES | E5: =SUM(E6:E16) -> 4.75e+09 | F5: =SUM(F6:F16) -> 4.75e+09 | H5: =+SUM(H6:H16) -> 1.2126257e+09 | I5: =+SUM(I6:I16) -> 62184567 | J5: =+SUM(J6:J16) -> 1.2748103e+09 | K5: =+SUM(K6:K16) -> 3.7543153e+08 | N5: =+SUM(N6:N10) -> 4.1844287e+08 | O5: =+SUM(O6:O10) -> 3.6826147e+08 | P5: =+SUM(P6:P10) -> 3.445013e+08
B6: 0A00 | C6: A - MANO DE OBRA DIRECTA | E6: 9.8950398e+08 | F6: 9.8950398e+08 | H6: 1.4782464e+08 | I6: 22819434 | J6: 1.7064408e+08 | K6: 32726608 | N6: 2.706179e+08 | O6: 1.4741885e+08 | P6: 1.8828324e+08
B7: 0B00 | C7: B - MATERIALES | E7: 6.5413681e+08 | F7: 6.5413681e+08 | H7: 247212310 | I7: -71726018 | J7: 1.7548629e+08 | K7: 40835352 | N7: 4862435 | O7: 1.2978851e+08 | P7: 40835352
B8: 0C00 | C8: C - COSTO PROPORCIONAL HH | E8: 4.3866146e+08 | F8: 4.3866146e+08 | H8: 1.0938225e+08 | I8: 22863048 | J8: 1.322453e+08 | K8: 75165205 | N8: 45252147 | O8: 60732318 | P8: 59332536
B9: 0D00 | C9: D - EQUIPOS Y COMBUSTIBLES | E9: 8.2520614e+08 | F9: 8.2520614e+08 | H9: 1.0910315e+08 | I9: 28126286 | J9: 1.3722943e+08 | K9: 52262104 | N9: 46999638 | O9: 623218 | P9: 17653632
B10: 0X00 | C10: E - SUBCONTRATOS | E10: 1.1022147e+08 | F10: 1.1022147e+08 | H10: 56821348 | I10: 8455140 | J10: 65276488 | K10: 17653632 | N10: 50710751 | O10: 29698582 | P10: 38396539
B11: 1F00 | C11: F - MANO DE OBRA INDIRECTA | E11: 8.493466e+08 | F11: 8.493466e+08 | H11: 2.9429467e+08 | I11: 9135947.8 | J11: 3.0343062e+08 | K11: 80391423
B12: 1G00 | C12: G - EQUIPOS INDIRECTOS | E12: 1.1279563e+08 | F12: 1.1279563e+08 | H12: 12075609 | I12: 16011957 | J12: 28087566 | K12: 7070432
B13: 1H00 | C13: H - INSTALACIÓN DE FAENAS | E13: 1.3575453e+08 | F13: 1.3575453e+08 | H13: 37841171 | I13: 12159039 | J13: 50000210 | K13: 12659074 | N13: 2.706179e+08 | O13: =+N13-P13 -> 1.3652708e+08 | P13: 1.3409083e+08
B14: 1I00 | C14: I - GASTOS GENERALES | E14: 1.9454474e+08 | F14: 1.9454474e+08 | H14: 43392152 | I14: 12177403 | J14: 55569555 | K14: 14993671 | P14: 4862435
B15: 1J00 | C15: J - GASTOS FINANCIEROS - SEGUROS Y BOLETAS | E15: 59828638 | F15: 59828638 | H15: 11073777 | I15: 2162330 | J15: 13236107 | K15: 10743794 | P15: 45252147
B16: 1K00 | C16: K - OFICINA CENTRAL - IMPREVISTOS - UTILIDADES | E16: 3.8e+08 | F16: 3.8e+08 | H16: 1.4360465e+08 | I16: 0 | J16: 1.4360465e+08 | K16: 30930233 | L16: =+J16-H16 -> 0 | P16: 46999638
P17: 50710751
F19: Mano de Obra | H19: =+H6+H8+H11 -> 5.5150156e+08 | I19: Mano de Obra | J19: =+J6+J8+J11 -> 6.0631999e+08 | K19: =+K6+K8+K11 -> 1.8828324e+08
F20: Materiales | H20: =+H7 -> 247212310 | I20: Materiales | J20: =+J7 -> 1.7548629e+08 | K20: =+K7 -> 40835352
F21: Equipos | H21: =+H9+H12 -> 1.2117876e+08 | I21: Equipos | J21: =+J9+J12 -> 1.65317e+08 | K21: =+K9+K12 -> 59332536
F22: Subcontratos | H22: =+H10 -> 56821348 | I22: Subcontratos | J22: =+J10 -> 65276488 | K22: =+K10 -> 17653632
F23: Otros Gastos | H23: =+H13+H14+H15 -> 92307100 | I23: Otros Gastos | J23: =+J13+J14+J15 -> 1.1880587e+08 | K23: =+K13+K14+K15 -> 38396539
H24: =SUM(H19:H23) -> 1.0690211e+09 | J24: =SUM(J19:J23) -> 1.1312056e+09
C26: PROYECCION
H28: PRODUCCION | L28: COSTOS | P28: PROYECCION
C29: TOTALES | E29: =SUM(E30:E40) -> 4.75e+09 | F29: =SUM(F30:F40) -> 4.75e+09 | H29: =SUM(H30:H40) -> 8.8246022e+08 | I29: =SUM(I30:I40) -> 3.8675398e+09 | J29: =SUM(J30:J40) -> 4.75e+09 | K29: 0 | L29: =SUM(L30:L40) -> 8.9937876e+08 | M29: =SUM(M30:M40) -> 3.8506212e+09 | N29: =SUM(N30:N40) -> 4.75e+09 | O29: 0 | P29: =SUM(P31:P40) -> 5.1726261e+09 | Q29: =SUM(Q31:Q40) -> 5.1726261e+09 | R29: =SUM(R31:R40) -> 0
C30: A - MANO DE OBRA DIRECTA | E30: 9.8950398e+08 | F30: 9.8950398e+08 | H30: 69431092 | I30: =+F30-H30 -> 9.2007289e+08 | J30: =+F30 -> 9.8950398e+08 | K30: 0 | L30: 1.3791747e+08 | M30: =+N30-L30 -> 8.5158651e+08 | N30: =+F30 -> 9.8950398e+08 | O30: 0 | P30: 1.3587361e+09 | Q30: 1.3587361e+09 | R30: 0
C31: B - MATERIALES | E31: 6.5413681e+08 | F31: 6.5413681e+08 | H31: 96894575 | I31: =+F31-H31 -> 5.5724223e+08 | J31: =+F31 -> 6.5413681e+08 | K31: 0 | L31: 1.3465094e+08 | M31: =+N31-L31 -> 5.1948587e+08 | N31: =+F31 -> 6.5413681e+08 | O31: 0 | P31: 4.8090604e+08 | Q31: 4.8090604e+08 | R31: 0
C32: C - COSTO PROPORCIONAL HH | E32: 4.3866146e+08 | F32: 4.3866146e+08 | H32: 39440181 | I32: =+F32-H32 -> 3.9922128e+08 | J32: =+F32 -> 4.3866146e+08 | K32: 0 | L32: 57080091 | M32: =+N32-L32 -> 3.8158137e+08 | N32: =+F32 -> 4.3866146e+08 | O32: 0 | P32: 2.1464034e+08 | Q32: 2.1464034e+08 | R32: 0
C33: D - EQUIPOS Y COMBUSTIBLES | E33: 8.2520614e+08 | F33: 8.2520614e+08 | H33: 1.4107514e+08 | I33: =+F33-H33 -> 6.84131e+08 | J33: =+F33 -> 8.2520614e+08 | K33: 0 | L33: 84967330 | M33: =+N33-L33 -> 7.4023881e+08 | N33: =+F33 -> 8.2520614e+08 | O33: 0 | P33: 1.1347377e+09 | Q33: 1.1347377e+09 | R33: 0
C34: E - SUBCONTRATOS | E34: 1.1022147e+08 | F34: 1.1022147e+08 | H34: 26021130 | I34: =+F34-H34 -> 84200343 | J34: =+F34 -> 1.1022147e+08 | K34: 0 | L34: 47622856 | M34: =+N34-L34 -> 62598617 | N34: =+F34 -> 1.1022147e+08 | O34: 0 | P34: 2.9233488e+08 | Q34: 2.9233488e+08 | R34: 0
C35: F - MANO DE OBRA INDIRECTA | E35: 8.493466e+08 | F35: 8.493466e+08 | H35: 2.5184114e+08 | I35: =+F35-H35 -> 5.9750546e+08 | J35: =+F35 -> 8.493466e+08 | K35: 0 | L35: 2.2303919e+08 | M35: =+N35-L35 -> 6.263074e+08 | N35: =+F35 -> 8.493466e+08 | O35: 0 | P35: 1.8532068e+09 | Q35: 1.8532068e+09 | R35: 0
C36: G - EQUIPOS INDIRECTOS | E36: 1.1279563e+08 | F36: 1.1279563e+08 | H36: 33445215 | I36: =+F36-H36 -> 79350413 | J36: =+F36 -> 1.1279563e+08 | K36: 0 | L36: 21017134 | M36: =+N36-L36 -> 91778494 | N36: =+F36 -> 1.1279563e+08 | O36: 0 | P36: 78853656 | Q36: 78853656 | R36: 0
C37: H - INSTALACIÓN DE FAENAS | E37: 1.3575453e+08 | F37: 1.3575453e+08 | H37: 40252797 | I37: =+F37-H37 -> 95501735 | J37: =+F37 -> 1.3575453e+08 | K37: 0 | L37: 37341136 | M37: =+N37-L37 -> 98413397 | N37: =+F37 -> 1.3575453e+08 | O37: 0 | P37: 2.5253843e+08 | Q37: 2.5253843e+08 | R37: 0
C38: I - GASTOS GENERALES | E38: 1.9454474e+08 | F38: 1.9454474e+08 | H38: 53644639 | I38: =+F38-H38 -> 1.409001e+08 | J38: =+F38 -> 1.9454474e+08 | K38: 0 | L38: 40575884 | M38: =+N38-L38 -> 1.5396886e+08 | N38: =+F38 -> 1.9454474e+08 | O38: 0 | P38: 2.6502103e+08 | Q38: 2.6502103e+08 | R38: 0
C39: J - GASTOS FINANCIEROS - SEGUROS Y BOLETAS | E39: 59828638 | F39: 59828638 | H39: 17739887 | I39: =+F39-H39 -> 42088751 | J39: =+F39 -> 59828638 | K39: 0 | L39: 2492313 | M39: =+N39-L39 -> 57336325 | N39: =+F39 -> 59828638 | O39: 0 | P39: 78147228 | Q39: 78147228 | R39: 0
C40: K - OFICINA CENTRAL - IMPREVISTOS - UTILIDADES | E40: 3.8e+08 | F40: 3.8e+08 | H40: 1.1267442e+08 | I40: =+F40-H40 -> 2.6732558e+08 | J40: =+F40 -> 3.8e+08 | K40: 0 | L40: 1.1267442e+08 | M40: =+N40-L40 -> 2.6732558e+08 | N40: =+F40 -> 3.8e+08 | O40: 0 | P40: 5.2224e+08 | Q40: 5.2224e+08 | R40: 0
E41: =SUM(E30:E40) -> 4.75e+09 | F41: =SUM(F30:F40) -> 4.75e+09 | H41: =SUM(H30:H40) -> 8.8246022e+08 | I41: =SUM(I30:I40) -> 3.8675398e+09 | J41: =SUM(J30:J40) -> 4.75e+09 | L41: =SUM(L30:L40) -> 8.9937876e+08 | M41: =SUM(M30:M40) -> 3.8506212e+09 | N41: =SUM(N30:N40) -> 4.75e+09 | P41: =SUM(P30:P40) -> 6.5313622e+09 | Q41: =SUM(Q30:Q40) -> 6.5313622e+09 | R41: =SUM(R30:R40) -> 0
M42: =+M41-M40 -> 3.5832957e+09
H43: =+H30+H32+H35 -> 3.6071241e+08 | I43: =+I30+I32+I35 -> 1.9167996e+09 | J43: Mano de Obra | L43: =+N30+N32+N35 -> 2.277512e+09 | P43: =SUM(P30:P39) -> 6.0091222e+09
H44: =+H31 -> 96894575 | I44: =+I31 -> 5.5724223e+08 | J44: Materiales | L44: =+N31 -> 6.5413681e+08
...

Sheet Facturacion
B2: PERIODO | C2: PRESENTADO | D2: DESCUENTO ANTICIPO | E2: APROBADO | F2: OBSERVACIONES2
B3: ANTICIPO N°1
B4: EDP N°1 | F4: Facturado
B5: EDP N°2 | F5: Facturado
B6: EDP N°3 | F6: Facturado
B7: EDP N°4 | F7: Facturado
B8: EDP N°5 | F8: Facturado | J8: =+EDP_15916[[#This Row],[PRESENTADO]]+C9 -> 0
E9: =+EDP_15916[[#This Row],[PRESENTADO]]-EDP_15916[[#This Row],[DESCUENTO ANTICIPO]] -> 0 | F9: Facturado
E10: =+EDP_15916[[#This Row],[PRESENTADO]]-EDP_15916[[#This Row],[DESCUENTO ANTICIPO]] -> 0 | J10: =+EDP_15916[[#This Row],[PRESENTADO]]+C11 -> 0
E11: =+EDP_15916[[#This Row],[PRESENTADO]]-EDP_15916[[#This Row],[DESCUENTO ANTICIPO]] -> 0 | F11: Facturado
E12: =+EDP_15916[[#This Row],[PRESENTADO]]-EDP_15916[[#This Row],[DESCUENTO ANTICIPO]] -> 0
E13: =+EDP_15916[[#This Row],[PRESENTADO]]-EDP_15916[[#This Row],[DESCUENTO ANTICIPO]] -> 0
E14: =+EDP_15916[[#This Row],[PRESENTADO]]-EDP_15916[[#This Row],[DESCUENTO ANTICIPO]] -> 0
E15: =+EDP_15916[[#This Row],[PRESENTADO]]-EDP_15916[[#This Row],[DESCUENTO ANTICIPO]] -> 0
E16: =+EDP_15916[[#This Row],[PRESENTADO]]-EDP_15916[[#This Row],[DESCUENTO ANTICIPO]] -> 0
E17: =+EDP_15916[[#This Row],[PRESENTADO]]-EDP_15916[[#This Row],[DESCUENTO ANTICIPO]] -> 0
E18: =+EDP_15916[[#This Row],[PRESENTADO]]-EDP_15916[[#This Row],[DESCUENTO ANTICIPO]] -> 0
E19: =+EDP_15916[[#This Row],[PRESENTADO]]-EDP_15916[[#This Row],[DESCUENTO ANTICIPO]] -> 0
E20: =+EDP_15916[[#This Row],[PRESENTADO]]-EDP_15916[[#This Row],[DESCUENTO ANTICIPO]] -> 0
C21: =SUBTOTAL(109,C3:C20) -> 0 | D21: =SUBTOTAL(109,D3:D20) -> 0 | E21: =SUM(E3:E20) -> 0
F46: 2
